Workbook
Name piinfo: #REF!

Sheet ReadMe
B1: For submitter (i.e, PI or project leader):
A2: 1: | B2: Download this file and RENAME: | C2: "Ordering_eDNA_Archive_sampling_(YYMMDD_Initials_ProjectID).xlsx"
C3: eg. Ordering_eDNA_Archive_sampling_(230715_LVI_NileValley).xlsx
A4: 2: | B4: Fill out the [Submit here] tab column B,C,D (and optionally E).
A5: 3: | B5: Mail the renamed and completed ordering form (this file) to Jesper Stenderup; eDNA_orders@sund.ku.dk.
A6: 4: | B6: Make sure the core is clearly labelled and easily available for the lab assistants.

Sheet Submit here
A1: No | B1: Submitter (initials) | C1: Submission date (yyyy-mm-dd) | D1: Bulk or Core segment ID (eg. ISL23_019_02A or CGG3_xxxxxx) | E1: Calibration tape depth (cm) | F1: Notes from submitter (optional)
A2: 1 | B2: NKL | C2: 45226 | D2: Tåruplund_2 | E2: Continuous
A3: 2 | B3: =B2 -> NKL | C3: =C2 -> 45226
A4: 3 | B4: =B3 -> NKL | C4: =C3 -> 45226
A5: 4 | B5: =B4 -> NKL | C5: =C4 -> 45226
A6: 5 | B6: =B5 -> NKL | C6: =C5 -> 45226
A7: 6 | B7: =B6 -> NKL | C7: =C6 -> 45226
A8: 7 | B8: =B7 -> NKL | C8: =C7 -> 45226
A9: 8 | B9: =B8 -> NKL | C9: =C8 -> 45226
A10: 9 | B10: =B9 -> NKL | C10: =C9 -> 45226
A11: 10 | B11: =B10 -> NKL | C11: =C10 -> 45226
A12: 11 | B12: =B11 -> NKL | C12: =C11 -> 45226
A13: 12 | B13: =B12 -> NKL | C13: =C12 -> 45226
A14: 13 | B14: =B13 -> NKL | C14: =C13 -> 45226
... A673: 672 | B673: =B672 -> NKL | C673: =C672 -> 45226

Sheet Output4SubSamplingSubmiss.
A1: ='For lab assistants'!O1 -> Core segment ID (fx ISL23_019_02A) | B1: ='For lab assistants'!A1 -> Archive rack position | C1: ='For lab assistants'!B1 -> Archive RACK name (eg. ARack0052) | D1: ='For lab assistants'!C1 -> Archive RACK barcode | E1: ='For lab assistants'!D1 -> Archive TUBE barcode | F1: ='For lab assistants'!Q1 -> Notes from submitter (optional)
A2: =IF('For lab assistants'!O2>0,'For lab assistants'!O2,"") -> Tåruplund_2 | B2: =IF('For lab assistants'!C2>0,'For lab assistants'!A2,"") -> A01 | C2: =IF('For lab assistants'!B2>0,'For lab assistants'!B2,"") -> ARack0471 | D2: =IF('For lab assistants'!#REF!>0,'For lab assistants'!#REF!,"") -> #REF! | E2: =IF('For lab assistants'!C2>0,'For lab assistants'!C2,"") -> LVL600038050 | F2: =IF('For lab assistants'!Q2>0,'For lab assistants'!Q2,"")
A3: =IF('For lab assistants'!O3>0,'For lab assistants'!O3,"") -> Tåruplund_2 | B3: =IF('For lab assistants'!D3>0,'For lab assistants'!A3,"") -> B01 | C3: =IF('For lab assistants'!B3>0,'For lab assistants'!B3,"") -> ARack0471 | D3: =IF('For lab assistants'!C3>0,'For lab assistants'!C3,"") -> LVL600038050 | E3: =IF('For lab assistants'!D3>0,'For lab assistants'!D3,"") -> LV3005888696 | F3: =IF('For lab assistants'!Q3>0,'For lab assistants'!Q3,"")
A4: =IF('For lab assistants'!O4>0,'For lab assistants'!O4,"") -> Tåruplund_2 | B4: =IF('For lab assistants'!D4>0,'For lab assistants'!A4,"") -> C01 | C4: =IF('For lab assistants'!B4>0,'For lab assistants'!B4,"") -> ARack0471 | D4: =IF('For lab assistants'!C4>0,'For lab assistants'!C4,"") -> LVL600038050 | E4: =IF('For lab assistants'!D4>0,'For lab assistants'!D4,"") -> LV3005888690 | F4: =IF('For lab assistants'!Q4>0,'For lab assistants'!Q4,"")
A5: =IF('For lab assistants'!O5>0,'For lab assistants'!O5,"") -> Tåruplund_2 | B5: =IF('For lab assistants'!D5>0,'For lab assistants'!A5,"") -> D01 | C5: =IF('For lab assistants'!B5>0,'For lab assistants'!B5,"") -> ARack0471 | D5: =IF('For lab assistants'!C5>0,'For lab assistants'!C5,"") -> LVL600038050 | E5: =IF('For lab assistants'!D5>0,'For lab assistants'!D5,"") -> LV3005888684 | F5: =IF('For lab assistants'!Q5>0,'For lab assistants'!Q5,"")
A6: =IF('For lab assistants'!O6>0,'For lab assistants'!O6,"") -> Tåruplund_2 | B6: =IF('For lab assistants'!D6>0,'For lab assistants'!A6,"") -> A02 | C6: =IF('For lab assistants'!B6>0,'For lab assistants'!B6,"") -> ARack0471 | D6: =IF('For lab assistants'!C6>0,'For lab assistants'!C6,"") -> LVL600038050 | E6: =IF('For lab assistants'!D6>0,'For lab assistants'!D6,"") -> LV3005888701 | F6: =IF('For lab assistants'!Q6>0,'For lab assistants'!Q6,"")
A7: =IF('For lab assistants'!O7>0,'For lab assistants'!O7,"") -> Tåruplund_2 | B7: =IF('For lab assistants'!D7>0,'For lab assistants'!A7,"") -> B02 | C7: =IF('For lab assistants'!B7>0,'For lab assistants'!B7,"") -> ARack0471 | D7: =IF('For lab assistants'!C7>0,'For lab assistants'!C7,"") -> LVL600038050 | E7: =IF('For lab assistants'!D7>0,'For lab assistants'!D7,"") -> LV3005888695 | F7: =IF('For lab assistants'!Q7>0,'For lab assistants'!Q7,"")
A8: =IF('For lab assistants'!O8>0,'For lab assistants'!O8,"") -> Tåruplund_2 | B8: =IF('For lab assistants'!D8>0,'For lab assistants'!A8,"") -> C02 | C8: =IF('For lab assistants'!B8>0,'For lab assistants'!B8,"") -> ARack0471 | D8: =IF('For lab assistants'!C8>0,'For lab assistants'!C8,"") -> LVL600038050 | E8: =IF('For lab assistants'!D8>0,'For lab assistants'!D8,"") -> LV3005888689 | F8: =IF('For lab assistants'!Q8>0,'For lab assistants'!Q8,"")
A9: =IF('For lab assistants'!O9>0,'For lab assistants'!O9,"") -> Tåruplund_2 | B9: =IF('For lab assistants'!D9>0,'For lab assistants'!A9,"") -> D02 | C9: =IF('For lab assistants'!B9>0,'For lab assistants'!B9,"") -> ARack0471 | D9: =IF('For lab assistants'!C9>0,'For lab assistants'!C9,"") -> LVL600038050 | E9: =IF('For lab assistants'!D9>0,'For lab assistants'!D9,"") -> LV3005888683 | F9: =IF('For lab assistants'!Q9>0,'For lab assistants'!Q9,"")
A10: =IF('For lab assistants'!O10>0,'For lab assistants'!O10,"") -> Tåruplund_2 | B10: =IF('For lab assistants'!D10>0,'For lab assistants'!A10,"") -> A03 | C10: =IF('For lab assistants'!B10>0,'For lab assistants'!B10,"") -> ARack0471 | D10: =IF('For lab assistants'!C10>0,'For lab assistants'!C10,"") -> LVL600038050 | E10: =IF('For lab assistants'!D10>0,'For lab assistants'!D10,"") -> LV3005888700 | F10: =IF('For lab assistants'!Q10>0,'For lab assistants'!Q10,"")
A11: =IF('For lab assistants'!O11>0,'For lab assistants'!O11,"") -> Tåruplund_2 | B11: =IF('For lab assistants'!D11>0,'For lab assistants'!A11,"") -> B03 | C11: =IF('For lab assistants'!B11>0,'For lab assistants'!B11,"") -> ARack0471 | D11: =IF('For lab assistants'!C11>0,'For lab assistants'!C11,"") -> LVL600038050 | E11: =IF('For lab assistants'!D11>0,'For lab assistants'!D11,"") -> LV3005888694 | F11: =IF('For lab assistants'!Q11>0,'For lab assistants'!Q11,"")
A12: =IF('For lab assistants'!O12>0,'For lab assistants'!O12,"") -> Tåruplund_2 | B12: =IF('For lab assistants'!D12>0,'For lab assistants'!A12,"") -> C03 | C12: =IF('For lab assistants'!B12>0,'For lab assistants'!B12,"") -> ARack0471 | D12: =IF('For lab assistants'!C12>0,'For lab assistants'!C12,"") -> LVL600038050 | E12: =IF('For lab assistants'!D12>0,'For lab assistants'!D12,"") -> LV3005888688 | F12: =IF('For lab assistants'!Q12>0,'For lab assistants'!Q12,"")
A13: =IF('For lab assistants'!O13>0,'For lab assistants'!O13,"") -> Tåruplund_2 | B13: =IF('For lab assistants'!D13>0,'For lab assistants'!A13,"") -> D03 | C13: =IF('For lab assistants'!B13>0,'For lab assistants'!B13,"") -> ARack0471 | D13: =IF('For lab assistants'!C13>0,'For lab assistants'!C13,"") -> LVL600038050 | E13: =IF('For lab assistants'!D13>0,'For lab assistants'!D13,"") -> LV3005888682 | F13: =IF('For lab assistants'!Q13>0,'For lab assistants'!Q13,"")
A14: =IF('For lab assistants'!O14>0,'For lab assistants'!O14,"") -> Tåruplund_2 | B14: =IF('For lab assistants'!D14>0,'For lab assistants'!A14,"") -> A04 | C14: =IF('For lab assistants'!B14>0,'For lab assistants'!B14,"") -> ARack0471 | D14: =IF('For lab assistants'!C14>0,'For lab assistants'!C14,"") -> LVL600038050 | E14: =IF('For lab assistants'!D14>0,'For lab assistants'!D14,"") -> LV3005888699 | F14: =IF('For lab assistants'!Q14>0,'For lab assistants'!Q14,"")
... A672: =IF('For lab assistants'!O672>0,'For lab assistants'!O672,"") | B672: =IF('For lab assistants'!D672>0,'For lab assistants'!A672,"") | C672: =IF('For lab assistants'!B672>0,'For lab assistants'!B672,"") | D672: =IF('For lab assistants'!C672>0,'For lab assistants'!C672,"") | E672: =IF('For lab assistants'!D672>0,'For lab assistants'!D672,"") | F672: =IF('For lab assistants'!Q672>0,'For lab assistants'!Q672,"")

Sheet For lab assistants
A1: Archive rack position | B1: Archive RACK name (eg. ARack0052) | C1: Archive RACK barcode | D1: Archive TUBE barcode | E1: Depth sampled (tape, cm) | F1: Organic content (High /Low) | G1: Surface exposed? (ie Back wall hit?) (Yes / No) | H1: Remarks from sampling (optional) | I1: Sampled by 1 (initials) | J1: Sampled by 2 (initials) | K1: Sampled date (yyyy-mm-dd) | L1: No | M1: Submitter (initials) | N1: Submission date (yyyy-mm-dd) | O1: Core segment ID (fx ISL23_019_02A) | P1: Ordered depth (Calibration tape, cm) | Q1: Notes from submitter (optional)
A2: A01 | B2: ARack0471 | C2: LVL600038050 | D2: LV3005888702 | E2: 0,5 | F2: High | G2: yes | I2: MH | K2: 45240 | L2: 1 | M2: =IF('Submit here'!B2>0,'Submit here'!B2,"") -> NKL | N2: =IF('Submit here'!C2>0,'Submit here'!C2,"") -> 45226 | O2: =IF('Submit here'!D2>0,'Submit here'!D2,"") -> Tåruplund_2 | P2: =IF('Submit here'!E2>0,'Submit here'!E2,"") -> Continuous | Q2: =IF('Submit here'!F2>0,'Submit here'!F2,"")
A3: B01 | B3: =B2 -> ARack0471 | C3: LVL600038050 | D3: LV3005888696 | E3: 1,5 | F3: High | G3: yes | I3: =I2 -> MH | J3: =J2 -> 0 | K3: =K2 -> 45240 | L3: 2 | M3: =IF('Submit here'!B3>0,'Submit here'!B3,"") -> NKL | N3: =IF('Submit here'!C3>0,'Submit here'!C3,"") -> 45226 | O3: Tåruplund_2 | P3: =IF('Submit here'!E3>0,'Submit here'!E3,"") | Q3: =IF('Submit here'!F3>0,'Submit here'!F3,"")
A4: C01 | B4: =B3 -> ARack0471 | C4: =C3 -> LVL600038050 | D4: LV3005888690 | E4: 3 | F4: High | G4: yes | I4: =I3 -> MH | J4: =J3 -> 0 | K4: =K3 -> 45240 | L4: 3 | M4: =IF('Submit here'!B4>0,'Submit here'!B4,"") -> NKL | N4: =IF('Submit here'!C4>0,'Submit here'!C4,"") -> 45226 | O4: Tåruplund_2 | P4: =IF('Submit here'!E4>0,'Submit here'!E4,"") | Q4: =IF('Submit here'!F4>0,'Submit here'!F4,"")
A5: D01 | B5: =B4 -> ARack0471 | C5: =C4 -> LVL600038050 | D5: LV3005888684 | E5: 5 | F5: High | G5: yes | I5: =I4 -> MH | J5: =J4 -> 0 | K5: =K4 -> 45240 | L5: 4 | M5: =IF('Submit here'!B5>0,'Submit here'!B5,"") -> NKL | N5: =IF('Submit here'!C5>0,'Submit here'!C5,"") -> 45226 | O5: Tåruplund_2 | P5: =IF('Submit here'!E5>0,'Submit here'!E5,"") | Q5: =IF('Submit here'!F5>0,'Submit here'!F5,"")
A6: A02 | B6: =B5 -> ARack0471 | C6: =C5 -> LVL600038050 | D6: LV3005888701 | E6: 6,5 | F6: High | G6: no | I6: =I5 -> MH | J6: =J5 -> 0 | K6: =K5 -> 45240 | L6: 5 | M6: =IF('Submit here'!B6>0,'Submit here'!B6,"") -> NKL | N6: =IF('Submit here'!C6>0,'Submit here'!C6,"") -> 45226 | O6: Tåruplund_2 | P6: =IF('Submit here'!E6>0,'Submit here'!E6,"") | Q6: =IF('Submit here'!F6>0,'Submit here'!F6,"")
A7: B02 | B7: =B6 -> ARack0471 | C7: =C6 -> LVL600038050 | D7: LV3005888695 | E7: 8 | F7: High | G7: no | I7: =I6 -> MH | J7: =J6 -> 0 | K7: =K6 -> 45240 | L7: 6 | M7: =IF('Submit here'!B7>0,'Submit here'!B7,"") -> NKL | N7: =IF('Submit here'!C7>0,'Submit here'!C7,"") -> 45226 | O7: Tåruplund_2 | P7: =IF('Submit here'!E7>0,'Submit here'!E7,"") | Q7: =IF('Submit here'!F7>0,'Submit here'!F7,"")
A8: C02 | B8: =B7 -> ARack0471 | C8: =C7 -> LVL600038050 | D8: LV3005888689 | E8: 9,5 | F8: High | G8: no | I8: =I7 -> MH | J8: =J7 -> 0 | K8: =K7 -> 45240 | L8: 7 | M8: =IF('Submit here'!B8>0,'Submit here'!B8,"") -> NKL | N8: =IF('Submit here'!C8>0,'Submit here'!C8,"") -> 45226 | O8: Tåruplund_2 | P8: =IF('Submit here'!E8>0,'Submit here'!E8,"") | Q8: =IF('Submit here'!F8>0,'Submit here'!F8,"")
A9: D02 | B9: =B8 -> ARack0471 | C9: =C8 -> LVL600038050 | D9: LV3005888683 | E9: 11 | F9: High | G9: no | I9: =I8 -> MH | J9: =J8 -> 0 | K9: =K8 -> 45240 | L9: 8 | M9: =IF('Submit here'!B9>0,'Submit here'!B9,"") -> NKL | N9: =IF('Submit here'!C9>0,'Submit here'!C9,"") -> 45226 | O9: Tåruplund_2 | P9: =IF('Submit here'!E9>0,'Submit here'!E9,"") | Q9: =IF('Submit here'!F9>0,'Submit here'!F9,"")
A10: A03 | B10: =B9 -> ARack0471 | C10: =C9 -> LVL600038050 | D10: LV3005888700 | E10: 13 | F10: High | G10: no | I10: =I9 -> MH | J10: =J9 -> 0 | K10: =K9 -> 45240 | L10: 9 | M10: =IF('Submit here'!B10>0,'Submit here'!B10,"") -> NKL | N10: =IF('Submit here'!C10>0,'Submit here'!C10,"") -> 45226 | O10: Tåruplund_2 | P10: =IF('Submit here'!E10>0,'Submit here'!E10,"") | Q10: =IF('Submit here'!F10>0,'Submit here'!F10,"")
A11: B03 | B11: =B10 -> ARack0471 | C11: =C10 -> LVL600038050 | D11: LV3005888694 | E11: 14,5 | F11: High | G11: yes | I11: =I10 -> MH | J11: =J10 -> 0 | K11: =K10 -> 45240 | L11: 10 | M11: =IF('Submit here'!B11>0,'Submit here'!B11,"") -> NKL | N11: =IF('Submit here'!C11>0,'Submit here'!C11,"") -> 45226 | O11: Tåruplund_2 | P11: =IF('Submit here'!E11>0,'Submit here'!E11,"") | Q11: =IF('Submit here'!F11>0,'Submit here'!F11,"")
A12: C03 | B12: =B11 -> ARack0471 | C12: =C11 -> LVL600038050 | D12: LV3005888688 | E12: 16 | F12: High | G12: yes | I12: =I11 -> MH | J12: =J11 -> 0 | K12: =K11 -> 45240 | L12: 11 | M12: =IF('Submit here'!B12>0,'Submit here'!B12,"") -> NKL | N12: =IF('Submit here'!C12>0,'Submit here'!C12,"") -> 45226 | O12: Tåruplund_2 | P12: =IF('Submit here'!E12>0,'Submit here'!E12,"") | Q12: =IF('Submit here'!F12>0,'Submit here'!F12,"")
A13: D03 | B13: =B12 -> ARack0471 | C13: =C12 -> LVL600038050 | D13: LV3005888682 | E13: 17,5 | F13: High | G13: yes | I13: =I12 -> MH | J13: =J12 -> 0 | K13: =K12 -> 45240 | L13: 12 | M13: =IF('Submit here'!B13>0,'Submit here'!B13,"") -> NKL | N13: =IF('Submit here'!C13>0,'Submit here'!C13,"") -> 45226 | O13: Tåruplund_2 | P13: =IF('Submit here'!E13>0,'Submit here'!E13,"") | Q13: =IF('Submit here'!F13>0,'Submit here'!F13,"")
A14: A04 | B14: =B13 -> ARack0471 | C14: =C13 -> LVL600038050 | D14: LV3005888699 | E14: 19 | F14: High | G14: yes | I14: =I13 -> MH | J14: =J13 -> 0 | K14: =K13 -> 45240 | L14: 13 | M14: =IF('Submit here'!B14>0,'Submit here'!B14,"") -> NKL | N14: =IF('Submit here'!C14>0,'Submit here'!C14,"") -> 45226 | O14: Tåruplund_2 | P14: =IF('Submit here'!E14>0,'Submit here'!E14,"") | Q14: =IF('Submit here'!F14>0,'Submit here'!F14,"")
A15: B04 | B15: =B14 -> ARack0471 | C15: =C14 -> LVL600038050 | D15: LV3005888693 | E15: 20,5 | F15: High | G15: yes | I15: =I14 -> MH | J15: =J14 -> 0 | K15: =K14 -> 45240 | L15: 14 | M15: =IF('Submit here'!B15>0,'Submit here'!B15,"") -> NKL | N15: =IF('Submit here'!C15>0,'Submit here'!C15,"") -> 45226 | O15: Tåruplund_2 | P15: =IF('Submit here'!E15>0,'Submit here'!E15,"") | Q15: =IF('Submit here'!F15>0,'Submit here'!F15,"")
A16: C04 | B16: =B15 -> ARack0471 | C16: =C15 -> LVL600038050 | D16: LV3005888687 | E16: 22 | F16: High | G16: no | I16: =I15 -> MH | J16: =J15 -> 0 | K16: =K15 -> 45240 | L16: 15 | M16: =IF('Submit here'!B16>0,'Submit here'!B16,"") -> NKL | N16: =IF('Submit here'!C16>0,'Submit here'!C16,"") -> 45226 | O16: Tåruplund_2 | P16: =IF('Submit here'!E16>0,'Submit here'!E16,"") | Q16: =IF('Submit here'!F16>0,'Submit here'!F16,"")
A17: D04 | B17: =B16 -> ARack0471 | C17: =C16 -> LVL600038050 | D17: LV3005888681 | E17: 24 | F17: High | G17: no | I17: =I16 -> MH | J17: =J16 -> 0 | K17: =K16 -> 45240 | L17: 16 | M17: =IF('Submit here'!B17>0,'Submit here'!B17,"") -> NKL | N17: =IF('Submit here'!C17>0,'Submit here'!C17,"") -> 45226 | O17: Tåruplund_2 | P17: =IF('Submit here'!E17>0,'Submit here'!E17,"") | Q17: =IF('Submit here'!F17>0,'Submit here'!F17,"")
A18: A05 | B18: =B17 -> ARack0471 | C18: =C17 -> LVL600038050 | D18: LV3005888698 | E18: 25,5 | F18: High | G18: no | I18: =I17 -> MH | J18: =J17 -> 0 | K18: =K17 -> 45240 | L18: 17 | M18: =IF('Submit here'!B18>0,'Submit here'!B18,"") -> NKL | N18: =IF('Submit here'!C18>0,'Submit here'!C18,"") -> 45226 | O18: Tåruplund_2 | P18: =IF('Submit here'!E18>0,'Submit here'!E18,"") | Q18: =IF('Submit here'!F18>0,'Submit here'!F18,"")
A19: B05 | B19: =B18 -> ARack0471 | C19: =C18 -> LVL600038050 | D19: LV3005888692 | E19: 27 | F19: High | G19: no | I19: =I18 -> MH | J19: =J18 -> 0 | K19: =K18 -> 45240 | L19: 18 | M19: =IF('Submit here'!B19>0,'Submit here'!B19,"") -> NKL | N19: =IF('Submit here'!C19>0,'Submit here'!C19,"") -> 45226 | O19: Tåruplund_2 | P19: =IF('Submit here'!E19>0,'Submit here'!E19,"") | Q19: =IF('Submit here'!F19>0,'Submit here'!F19,"")
A20: C05 | B20: =B19 -> ARack0471 | C20: =C19 -> LVL600038050 | D20: LV3005888686 | E20: 29 | F20: High | G20: no | I20: =I19 -> MH | J20: =J19 -> 0 | K20: =K19 -> 45240 | L20: 19 | M20: =IF('Submit here'!B20>0,'Submit here'!B20,"") -> NKL | N20: =IF('Submit here'!C20>0,'Submit here'!C20,"") -> 45226 | O20: Tåruplund_2 | P20: =IF('Submit here'!E20>0,'Submit here'!E20,"") | Q20: =IF('Submit here'!F20>0,'Submit here'!F20,"")
A21: D05 | B21: =B20 -> ARack0471 | C21: =C20 -> LVL600038050 | D21: LV3005888680 | E21: 30,5 | F21: High | G21: no | I21: =I20 -> MH | J21: =J20 -> 0 | K21: =K20 -> 45240 | L21: 20 | M21: =IF('Submit here'!B21>0,'Submit here'!B21,"") -> NKL | N21: =IF('Submit here'!C21>0,'Submit here'!C21,"") -> 45226 | O21: Tåruplund_2 | P21: =IF('Submit here'!E21>0,'Submit here'!E21,"") | Q21: =IF('Submit here'!F21>0,'Submit here'!F21,"")
A22: A06 | B22: =B21 -> ARack0471 | C22: =C21 -> LVL600038050 | D22: LV3005888697 | E22: 32 | F22: High | G22: no | I22: =I21 -> MH | J22: =J21 -> 0 | K22: =K21 -> 45240 | L22: 21 | M22: =IF('Submit here'!B22>0,'Submit here'!B22,"") -> NKL | N22: =IF('Submit here'!C22>0,'Submit here'!C22,"") -> 45226 | O22: Tåruplund_2 | P22: =IF('Submit here'!E22>0,'Submit here'!E22,"") | Q22: =IF('Submit here'!F22>0,'Submit here'!F22,"")
A23: B06 | B23: =B22 -> ARack0471 | C23: =C22 -> LVL600038050 | D23: LV3005888691 | E23: 33,5 | F23: High | G23: no | I23: =I22 -> MH | J23: =J22 -> 0 | K23: =K22 -> 45240 | L23: 22 | M23: =IF('Submit here'!B23>0,'Submit here'!B23,"") -> NKL | N23: =IF('Submit here'!C23>0,'Submit here'!C23,"") -> 45226 | O23: Tåruplund_2 | P23: =IF('Submit here'!E23>0,'Submit here'!E23,"") | Q23: =IF('Submit here'!F23>0,'Submit here'!F23,"")
A24: C06 | B24: =B23 -> ARack0471 | C24: =C23 -> LVL600038050 | D24: LV3005888685 | E24: 35 | F24: Low | G24: no | I24: =I23 -> MH | J24: =J23 -> 0 | K24: =K23 -> 45240 | L24: 23 | M24: =IF('Submit here'!B24>0,'Submit here'!B24,"") -> NKL | N24: =IF('Submit here'!C24>0,'Submit here'!C24,"") -> 45226 | O24: Tåruplund_2 | P24: =IF('Submit here'!E24>0,'Submit here'!E24,"") | Q24: =IF('Submit here'!F24>0,'Submit here'!F24,"")
A25: D06 | B25: =B24 -> ARack0471 | C25: =C24 -> LVL600038050 | D25: LV3005888679 | E25: 37 | F25: Low | G25: no | I25: =I24 -> MH | J25: =J24 -> 0 | K25: =K24 -> 45240 | L25: 24 | M25: =IF('Submit here'!B25>0,'Submit here'!B25,"") -> NKL | N25: =IF('Submit here'!C25>0,'Submit here'!C25,"") -> 45226 | O25: Tåruplund_2 | P25: =IF('Submit here'!E25>0,'Submit here'!E25,"") | Q25: =IF('Submit here'!F25>0,'Submit here'!F25,"")
A26: A01 | B26: ARack0472 | C26: LVL600038049 | D26: LV3005888654 | E26: 38,5 | F26: Low | G26: no | I26: =I25 -> MH | J26: =J25 -> 0 | K26: =K25 -> 45240 | L26: 25 | M26: =IF('Submit here'!B26>0,'Submit here'!B26,"") -> NKL | N26: =IF('Submit here'!C26>0,'Submit here'!C26,"") -> 45226 | O26: Tåruplund_2 | P26: =IF('Submit here'!E26>0,'Submit here'!E26,"") | Q26: =IF('Submit here'!F26>0,'Submit here'!F26,"")
A27: B01 | B27: =B26 -> ARack0472 | C27: =C26 -> LVL600038049 | D27: LV3005888660 | E27: 40 | F27: Low | G27: no | I27: =I26 -> MH | J27: =J26 -> 0 | K27: =K26 -> 45240 | L27: 26 | M27: =IF('Submit here'!B27>0,'Submit here'!B27,"") -> NKL | N27: =IF('Submit here'!C27>0,'Submit here'!C27,"") -> 45226 | O27: Tåruplund_2 | P27: =IF('Submit here'!E27>0,'Submit here'!E27,"") | Q27: =IF('Submit here'!F27>0,'Submit here'!F27,"")
A28: C01 | B28: =B27 -> ARack0472 | C28: =C27 -> LVL600038049 | D28: LV3005888666 | E28: 41,5 | F28: Low | G28: no | I28: =I27 -> MH | J28: =J27 -> 0 | K28: =K27 -> 45240 | L28: 27 | M28: =IF('Submit here'!B28>0,'Submit here'!B28,"") -> NKL | N28: =IF('Submit here'!C28>0,'Submit here'!C28,"") -> 45226 | O28: Tåruplund_2 | P28: =IF('Submit here'!E28>0,'Submit here'!E28,"") | Q28: =IF('Submit here'!F28>0,'Submit here'!F28,"")
A29: D01 | B29: =B28 -> ARack0472 | C29: =C28 -> LVL600038049 | D29: LV3005888672 | E29: 43 | F29: Low | G29: no | I29: =I28 -> MH | J29: =J28 -> 0 | K29: =K28 -> 45240 | L29: 28 | M29: =IF('Submit here'!B29>0,'Submit here'!B29,"") -> NKL | N29: =IF('Submit here'!C29>0,'Submit here'!C29,"") -> 45226 | O29: Tåruplund_2 | P29: =IF('Submit here'!E29>0,'Submit here'!E29,"") | Q29: =IF('Submit here'!F29>0,'Submit here'!F29,"")
A30: A02 | B30: =B29 -> ARack0472 | C30: =C29 -> LVL600038049 | D30: LV3005888655 | E30: 44,5 | F30: Low | G30: no | I30: =I29 -> MH | J30: =J29 -> 0 | K30: =K29 -> 45240 | L30: 29 | M30: =IF('Submit here'!B30>0,'Submit here'!B30,"") -> NKL | N30: =IF('Submit here'!C30>0,'Submit here'!C30,"") -> 45226 | O30: Tåruplund_2 | P30: =IF('Submit here'!E30>0,'Submit here'!E30,"") | Q30: =IF('Submit here'!F30>0,'Submit here'!F30,"")
A31: B02 | B31: =B30 -> ARack0472 | C31: =C30 -> LVL600038049 | D31: LV3005888661 | E31: 46,5 | F31: Low | G31: no | I31: =I30 -> MH | J31: =J30 -> 0 | K31: =K30 -> 45240 | L31: 30 | M31: =IF('Submit here'!B31>0,'Submit here'!B31,"") -> NKL | N31: =IF('Submit here'!C31>0,'Submit here'!C31,"") -> 45226 | O31: Tåruplund_2 | P31: =IF('Submit here'!E31>0,'Submit here'!E31,"") | Q31: =IF('Submit here'!F31>0,'Submit here'!F31,"")
A32: C02 | B32: =B31 -> ARack0472 | C32: =C31 -> LVL600038049 | D32: LV3005888667 | E32: 48 | F32: Low | G32: no | I32: =I31 -> MH | J32: =J31 -> 0 | K32: =K31 -> 45240 | L32: 31 | M32: =IF('Submit here'!B32>0,'Submit here'!B32,"") -> NKL | N32: =IF('Submit here'!C32>0,'Submit here'!C32,"") -> 45226 | O32: Tåruplund_2 | P32: =IF('Submit here'!E32>0,'Submit here'!E32,"") | Q32: =IF('Submit here'!F32>0,'Submit here'!F32,"")
A33: D02 | B33: =B32 -> ARack0472 | C33: =C32 -> LVL600038049 | D33: LV3005888673 | E33: 49,5 | F33: Low | G33: no | I33: =I32 -> MH | J33: =J32 -> 0 | K33: =K32 -> 45240 | L33: 32 | M33: =IF('Submit here'!B33>0,'Submit here'!B33,"") -> NKL | N33: =IF('Submit here'!C33>0,'Submit here'!C33,"") -> 45226 | O33: Tåruplund_2 | P33: =IF('Submit here'!E33>0,'Submit here'!E33,"") | Q33: =IF('Submit here'!F33>0,'Submit here'!F33,"")
A34: A03 | B34: =B33 -> ARack0472 | C34: =C33 -> LVL600038049 | D34: LV3005888656 | E34: 51 | F34: Low | G34: no | I34: =I33 -> MH | J34: =J33 -> 0 | K34: =K33 -> 45240 | L34: 33 | M34: =IF('Submit here'!B34>0,'Submit here'!B34,"") -> NKL | N34: =IF('Submit here'!C34>0,'Submit here'!C34,"") -> 45226 | O34: Tåruplund_2 | P34: =IF('Submit here'!E34>0,'Submit here'!E34,"") | Q34: =IF('Submit here'!F34>0,'Submit here'!F34,"")
A35: B03 | B35: =B34 -> ARack0472 | C35: =C34 -> LVL600038049 | D35: LV3005888662 | E35: 53 | F35: Low | G35: no | I35: =I34 -> MH | J35: =J34 -> 0 | K35: =K34 -> 45240 | L35: 34 | M35: =IF('Submit here'!B35>0,'Submit here'!B35,"") -> NKL | N35: =IF('Submit here'!C35>0,'Submit here'!C35,"") -> 45226 | O35: Tåruplund_2 | P35: =IF('Submit here'!E35>0,'Submit here'!E35,"") | Q35: =IF('Submit here'!F35>0,'Submit here'!F35,"")
A36: C03 | B36: =B35 -> ARack0472 | C36: =C35 -> LVL600038049 | D36: LV3005888668 | E36: 54,5 | F36: Low | G36: no | I36: =I35 -> MH | J36: =J35 -> 0 | K36: =K35 -> 45240 | L36: 35 | M36: =IF('Submit here'!B36>0,'Submit here'!B36,"") -> NKL | N36: =IF('Submit here'!C36>0,'Submit here'!C36,"") -> 45226 | O36: Tåruplund_2 | P36: =IF('Submit here'!E36>0,'Submit here'!E36,"") | Q36: =IF('Submit here'!F36>0,'Submit here'!F36,"")
A37: D03 | B37: =B36 -> ARack0472 | C37: =C36 -> LVL600038049 | D37: LV3005888674 | E37: 56,5 | F37: Low | G37: no | I37: =I36 -> MH | J37: =J36 -> 0 | K37: =K36 -> 45240 | L37: 36 | M37: =IF('Submit here'!B37>0,'Submit here'!B37,"") -> NKL | N37: =IF('Submit here'!C37>0,'Submit here'!C37,"") -> 45226 | O37: Tåruplund_2 | P37: =IF('Submit here'!E37>0,'Submit here'!E37,"") | Q37: =IF('Submit here'!F37>0,'Submit here'!F37,"")
A38: A04 | B38: =B37 -> ARack0472 | C38: =C37 -> LVL600038049 | D38: LV3005888657 | E38: 58 | F38: Low | G38: no | I38: =I37 -> MH | J38: =J37 -> 0 | K38: =K37 -> 45240 | L38: 37 | M38: =IF('Submit here'!B38>0,'Submit here'!B38,"") -> NKL | N38: =IF('Submit here'!C38>0,'Submit here'!C38,"") -> 45226 | O38: Tåruplund_2 | P38: =IF('Submit here'!E38>0,'Submit here'!E38,"") | Q38: =IF('Submit here'!F38>0,'Submit here'!F38,"")
A39: B04 | B39: =B38 -> ARack0472 | C39: =C38 -> LVL600038049 | D39: LV3005888663 | E39: 60 | F39: Low | G39: no | I39: =I38 -> MH | J39: =J38 -> 0 | K39: =K38 -> 45240 | L39: 38 | M39: =IF('Submit here'!B39>0,'Submit here'!B39,"") -> NKL | N39: =IF('Submit here'!C39>0,'Submit here'!C39,"") -> 45226 | O39: Tåruplund_2 | P39: =IF('Submit here'!E39>0,'Submit here'!E39,"") | Q39: =IF('Submit here'!F39>0,'Submit here'!F39,"")
A40: C04 | B40: =B39 -> ARack0472 | C40: =C39 -> LVL600038049 | D40: LV3005888669 | E40: 61,5 | F40: Low | G40: no | I40: =I39 -> MH | J40: =J39 -> 0 | K40: =K39 -> 45240 | L40: 39 | M40: =IF('Submit here'!B40>0,'Submit here'!B40,"") -> NKL | N40: =IF('Submit here'!C40>0,'Submit here'!C40,"") -> 45226 | O40: Tåruplund_2 | P40: =IF('Submit here'!E40>0,'Submit here'!E40,"") | Q40: =IF('Submit here'!F40>0,'Submit here'!F40,"")
...

Sheet OutputForDB
A1: ArchiveSampleID | B1: PositionInRack | C1: RackName | D1: RackID | E1: BulkSampleID | F1: DepthSampledCalTape | G1: DepthOrderedCalTape | H1: OrganicContent | I1: SurfaceExposed | J1: RemarksArchiveSampling | K1: SampledBy1 | L1: SampledBy2 | M1: SamplingDate | N1: Submitter | O1: SubmissionDate | P1: NotesSubmitter
A2: =IF('For lab assistants'!C2>0,'For lab assistants'!C2,"") -> LVL600038050 | B2: =IF('For lab assistants'!C2>0,'For lab assistants'!A2,"") -> A01 | C2: =IF('For lab assistants'!B2>0,'For lab assistants'!B2,"") -> ARack0471 | D2: =IF('For lab assistants'!#REF!>0,'For lab assistants'!#REF!,"") -> #REF! | E2: =IF('For lab assistants'!O2>0,'For lab assistants'!O2,"") -> Tåruplund_2 | F2: =IF('For lab assistants'!E2>0,'For lab assistants'!E2,"") -> 0,5 | G2: =IF('For lab assistants'!P2>0,'For lab assistants'!P2,"") -> Continuous | H2: =IF('For lab assistants'!F2>0,'For lab assistants'!F2,"low") -> High | I2: =IF('For lab assistants'!G2>0,'For lab assistants'!G2,"no") -> yes | J2: =IF('For lab assistants'!H2>0,'For lab assistants'!H2,"") | K2: =IF('For lab assistants'!I2>0,'For lab assistants'!I2,"") -> MH | L2: =IF('For lab assistants'!J2>0,'For lab assistants'!J2,"") | M2: =IF('For lab assistants'!K2>0,'For lab assistants'!K2,"") -> 45240 | N2: =IF('For lab assistants'!C2>0,'For lab assistants'!M2,"") -> NKL | O2: =IF('For lab assistants'!C2>0,'For lab assistants'!N2,"") -> 45226 | P2: =IF(Output4SubSamplingSubmiss.!F2>0,Output4SubSamplingSubmiss.!F2,"")
A3: =IF('For lab assistants'!D3>0,'For lab assistants'!D3,"") -> LV3005888696 | B3: =IF('For lab assistants'!D3>0,'For lab assistants'!A3,"") -> B01 | C3: =IF('For lab assistants'!B3>0,'For lab assistants'!B3,"") -> ARack0471 | D3: =IF('For lab assistants'!C3>0,'For lab assistants'!C3,"") -> LVL600038050 | E3: =IF('For lab assistants'!O3>0,'For lab assistants'!O3,"") -> Tåruplund_2 | F3: =IF('For lab assistants'!E3>0,'For lab assistants'!E3,"") -> 1,5 | G3: =IF('For lab assistants'!P3>0,'For lab assistants'!P3,"") | H3: =IF('For lab assistants'!F3>0,'For lab assistants'!F3,"low") -> High | I3: =IF('For lab assistants'!G3>0,'For lab assistants'!G3,"no") -> yes | J3: =IF('For lab assistants'!H3>0,'For lab assistants'!H3,"") | K3: =IF('For lab assistants'!I3>0,'For lab assistants'!I3,"") -> MH | L3: =IF('For lab assistants'!J3>0,'For lab assistants'!J3,"") | M3: =IF('For lab assistants'!K3>0,'For lab assistants'!K3,"") -> 45240 | N3: =IF('For lab assistants'!D3>0,'For lab assistants'!M3,"") -> NKL | O3: =IF('For lab assistants'!D3>0,'For lab assistants'!N3,"") -> 45226 | P3: =IF(Output4SubSamplingSubmiss.!F3>0,Output4SubSamplingSubmiss.!F3,"")
A4: =IF('For lab assistants'!D4>0,'For lab assistants'!D4,"") -> LV3005888690 | B4: =IF('For lab assistants'!D4>0,'For lab assistants'!A4,"") -> C01 | C4: =IF('For lab assistants'!B4>0,'For lab assistants'!B4,"") -> ARack0471 | D4: =IF('For lab assistants'!C4>0,'For lab assistants'!C4,"") -> LVL600038050 | E4: =IF('For lab assistants'!O4>0,'For lab assistants'!O4,"") -> Tåruplund_2 | F4: =IF('For lab assistants'!E4>0,'For lab assistants'!E4,"") -> 3 | G4: =IF('For lab assistants'!P4>0,'For lab assistants'!P4,"") | H4: =IF('For lab assistants'!F4>0,'For lab assistants'!F4,"low") -> High | I4: =IF('For lab assistants'!G4>0,'For lab assistants'!G4,"no") -> yes | J4: =IF('For lab assistants'!H4>0,'For lab assistants'!H4,"") | K4: =IF('For lab assistants'!I4>0,'For lab assistants'!I4,"") -> MH | L4: =IF('For lab assistants'!J4>0,'For lab assistants'!J4,"") | M4: =IF('For lab assistants'!K4>0,'For lab assistants'!K4,"") -> 45240 | N4: =IF('For lab assistants'!D4>0,'For lab assistants'!M4,"") -> NKL | O4: =IF('For lab assistants'!D4>0,'For lab assistants'!N4,"") -> 45226 | P4: =IF(Output4SubSamplingSubmiss.!F4>0,Output4SubSamplingSubmiss.!F4,"")
A5: =IF('For lab assistants'!D5>0,'For lab assistants'!D5,"") -> LV3005888684 | B5: =IF('For lab assistants'!D5>0,'For lab assistants'!A5,"") -> D01 | C5: =IF('For lab assistants'!B5>0,'For lab assistants'!B5,"") -> ARack0471 | D5: =IF('For lab assistants'!C5>0,'For lab assistants'!C5,"") -> LVL600038050 | E5: =IF('For lab assistants'!O5>0,'For lab assistants'!O5,"") -> Tåruplund_2 | F5: =IF('For lab assistants'!E5>0,'For lab assistants'!E5,"") -> 5 | G5: =IF('For lab assistants'!P5>0,'For lab assistants'!P5,"") | H5: =IF('For lab assistants'!F5>0,'For lab assistants'!F5,"low") -> High | I5: =IF('For lab assistants'!G5>0,'For lab assistants'!G5,"no") -> yes | J5: =IF('For lab assistants'!H5>0,'For lab assistants'!H5,"") | K5: =IF('For lab assistants'!I5>0,'For lab assistants'!I5,"") -> MH | L5: =IF('For lab assistants'!J5>0,'For lab assistants'!J5,"") | M5: =IF('For lab assistants'!K5>0,'For lab assistants'!K5,"") -> 45240 | N5: =IF('For lab assistants'!D5>0,'For lab assistants'!M5,"") -> NKL | O5: =IF('For lab assistants'!D5>0,'For lab assistants'!N5,"") -> 45226 | P5: =IF(Output4SubSamplingSubmiss.!F5>0,Output4SubSamplingSubmiss.!F5,"")
A6: =IF('For lab assistants'!D6>0,'For lab assistants'!D6,"") -> LV3005888701 | B6: =IF('For lab assistants'!D6>0,'For lab assistants'!A6,"") -> A02 | C6: =IF('For lab assistants'!B6>0,'For lab assistants'!B6,"") -> ARack0471 | D6: =IF('For lab assistants'!C6>0,'For lab assistants'!C6,"") -> LVL600038050 | E6: =IF('For lab assistants'!O6>0,'For lab assistants'!O6,"") -> Tåruplund_2 | F6: =IF('For lab assistants'!E6>0,'For lab assistants'!E6,"") -> 6,5 | G6: =IF('For lab assistants'!P6>0,'For lab assistants'!P6,"") | H6: =IF('For lab assistants'!F6>0,'For lab assistants'!F6,"low") -> High | I6: =IF('For lab assistants'!G6>0,'For lab assistants'!G6,"no") -> no | J6: =IF('For lab assistants'!H6>0,'For lab assistants'!H6,"") | K6: =IF('For lab assistants'!I6>0,'For lab assistants'!I6,"") -> MH | L6: =IF('For lab assistants'!J6>0,'For lab assistants'!J6,"") | M6: =IF('For lab assistants'!K6>0,'For lab assistants'!K6,"") -> 45240 | N6: =IF('For lab assistants'!D6>0,'For lab assistants'!M6,"") -> NKL | O6: =IF('For lab assistants'!D6>0,'For lab assistants'!N6,"") -> 45226 | P6: =IF(Output4SubSamplingSubmiss.!F6>0,Output4SubSamplingSubmiss.!F6,"")
A7: =IF('For lab assistants'!D7>0,'For lab assistants'!D7,"") -> LV3005888695 | B7: =IF('For lab assistants'!D7>0,'For lab assistants'!A7,"") -> B02 | C7: =IF('For lab assistants'!B7>0,'For lab assistants'!B7,"") -> ARack0471 | D7: =IF('For lab assistants'!C7>0,'For lab assistants'!C7,"") -> LVL600038050 | E7: =IF('For lab assistants'!O7>0,'For lab assistants'!O7,"") -> Tåruplund_2 | F7: =IF('For lab assistants'!E7>0,'For lab assistants'!E7,"") -> 8 | G7: =IF('For lab assistants'!P7>0,'For lab assistants'!P7,"") | H7: =IF('For lab assistants'!F7>0,'For lab assistants'!F7,"low") -> High | I7: =IF('For lab assistants'!G7>0,'For lab assistants'!G7,"no") -> no | J7: =IF('For lab assistants'!H7>0,'For lab assistants'!H7,"") | K7: =IF('For lab assistants'!I7>0,'For lab assistants'!I7,"") -> MH | L7: =IF('For lab assistants'!J7>0,'For lab assistants'!J7,"") | M7: =IF('For lab assistants'!K7>0,'For lab assistants'!K7,"") -> 45240 | N7: =IF('For lab assistants'!D7>0,'For lab assistants'!M7,"") -> NKL | O7: =IF('For lab assistants'!D7>0,'For lab assistants'!N7,"") -> 45226 | P7: =IF(Output4SubSamplingSubmiss.!F7>0,Output4SubSamplingSubmiss.!F7,"")
A8: =IF('For lab assistants'!D8>0,'For lab assistants'!D8,"") -> LV3005888689 | B8: =IF('For lab assistants'!D8>0,'For lab assistants'!A8,"") -> C02 | C8: =IF('For lab assistants'!B8>0,'For lab assistants'!B8,"") -> ARack0471 | D8: =IF('For lab assistants'!C8>0,'For lab assistants'!C8,"") -> LVL600038050 | E8: =IF('For lab assistants'!O8>0,'For lab assistants'!O8,"") -> Tåruplund_2 | F8: =IF('For lab assistants'!E8>0,'For lab assistants'!E8,"") -> 9,5 | G8: =IF('For lab assistants'!P8>0,'For lab assistants'!P8,"") | H8: =IF('For lab assistants'!F8>0,'For lab assistants'!F8,"low") -> High | I8: =IF('For lab assistants'!G8>0,'For lab assistants'!G8,"no") -> no | J8: =IF('For lab assistants'!H8>0,'For lab assistants'!H8,"") | K8: =IF('For lab assistants'!I8>0,'For lab assistants'!I8,"") -> MH | L8: =IF('For lab assistants'!J8>0,'For lab assistants'!J8,"") | M8: =IF('For lab assistants'!K8>0,'For lab assistants'!K8,"") -> 45240 | N8: =IF('For lab assistants'!D8>0,'For lab assistants'!M8,"") -> NKL | O8: =IF('For lab assistants'!D8>0,'For lab assistants'!N8,"") -> 45226 | P8: =IF(Output4SubSamplingSubmiss.!F8>0,Output4SubSamplingSubmiss.!F8,"")
A9: =IF('For lab assistants'!D9>0,'For lab assistants'!D9,"") -> LV3005888683 | B9: =IF('For lab assistants'!D9>0,'For lab assistants'!A9,"") -> D02 | C9: =IF('For lab assistants'!B9>0,'For lab assistants'!B9,"") -> ARack0471 | D9: =IF('For lab assistants'!C9>0,'For lab assistants'!C9,"") -> LVL600038050 | E9: =IF('For lab assistants'!O9>0,'For lab assistants'!O9,"") -> Tåruplund_2 | F9: =IF('For lab assistants'!E9>0,'For lab assistants'!E9,"") -> 11 | G9: =IF('For lab assistants'!P9>0,'For lab assistants'!P9,"") | H9: =IF('For lab assistants'!F9>0,'For lab assistants'!F9,"low") -> High | I9: =IF('For lab assistants'!G9>0,'For lab assistants'!G9,"no") -> no | J9: =IF('For lab assistants'!H9>0,'For lab assistants'!H9,"") | K9: =IF('For lab assistants'!I9>0,'For lab assistants'!I9,"") -> MH | L9: =IF('For lab assistants'!J9>0,'For lab assistants'!J9,"") | M9: =IF('For lab assistants'!K9>0,'For lab assistants'!K9,"") -> 45240 | N9: =IF('For lab assistants'!D9>0,'For lab assistants'!M9,"") -> NKL | O9: =IF('For lab assistants'!D9>0,'For lab assistants'!N9,"") -> 45226 | P9: =IF(Output4SubSamplingSubmiss.!F9>0,Output4SubSamplingSubmiss.!F9,"")
A10: =IF('For lab assistants'!D10>0,'For lab assistants'!D10,"") -> LV3005888700 | B10: =IF('For lab assistants'!D10>0,'For lab assistants'!A10,"") -> A03 | C10: =IF('For lab assistants'!B10>0,'For lab assistants'!B10,"") -> ARack0471 | D10: =IF('For lab assistants'!C10>0,'For lab assistants'!C10,"") -> LVL600038050 | E10: =IF('For lab assistants'!O10>0,'For lab assistants'!O10,"") -> Tåruplund_2 | F10: =IF('For lab assistants'!E10>0,'For lab assistants'!E10,"") -> 13 | G10: =IF('For lab assistants'!P10>0,'For lab assistants'!P10,"") | H10: =IF('For lab assistants'!F10>0,'For lab assistants'!F10,"low") -> High | I10: =IF('For lab assistants'!G10>0,'For lab assistants'!G10,"no") -> no | J10: =IF('For lab assistants'!H10>0,'For lab assistants'!H10,"") | K10: =IF('For lab assistants'!I10>0,'For lab assistants'!I10,"") -> MH | L10: =IF('For lab assistants'!J10>0,'For lab assistants'!J10,"") | M10: =IF('For lab assistants'!K10>0,'For lab assistants'!K10,"") -> 45240 | N10: =IF('For lab assistants'!D10>0,'For lab assistants'!M10,"") -> NKL | O10: =IF('For lab assistants'!D10>0,'For lab assistants'!N10,"") -> 45226 | P10: =IF(Output4SubSamplingSubmiss.!F10>0,Output4SubSamplingSubmiss.!F10,"")
A11: =IF('For lab assistants'!D11>0,'For lab assistants'!D11,"") -> LV3005888694 | B11: =IF('For lab assistants'!D11>0,'For lab assistants'!A11,"") -> B03 | C11: =IF('For lab assistants'!B11>0,'For lab assistants'!B11,"") -> ARack0471 | D11: =IF('For lab assistants'!C11>0,'For lab assistants'!C11,"") -> LVL600038050 | E11: =IF('For lab assistants'!O11>0,'For lab assistants'!O11,"") -> Tåruplund_2 | F11: =IF('For lab assistants'!E11>0,'For lab assistants'!E11,"") -> 14,5 | G11: =IF('For lab assistants'!P11>0,'For lab assistants'!P11,"") | H11: =IF('For lab assistants'!F11>0,'For lab assistants'!F11,"low") -> High | I11: =IF('For lab assistants'!G11>0,'For lab assistants'!G11,"no") -> yes | J11: =IF('For lab assistants'!H11>0,'For lab assistants'!H11,"") | K11: =IF('For lab assistants'!I11>0,'For lab assistants'!I11,"") -> MH | L11: =IF('For lab assistants'!J11>0,'For lab assistants'!J11,"") | M11: =IF('For lab assistants'!K11>0,'For lab assistants'!K11,"") -> 45240 | N11: =IF('For lab assistants'!D11>0,'For lab assistants'!M11,"") -> NKL | O11: =IF('For lab assistants'!D11>0,'For lab assistants'!N11,"") -> 45226 | P11: =IF(Output4SubSamplingSubmiss.!F11>0,Output4SubSamplingSubmiss.!F11,"")
A12: =IF('For lab assistants'!D12>0,'For lab assistants'!D12,"") -> LV3005888688 | B12: =IF('For lab assistants'!D12>0,'For lab assistants'!A12,"") -> C03 | C12: =IF('For lab assistants'!B12>0,'For lab assistants'!B12,"") -> ARack0471 | D12: =IF('For lab assistants'!C12>0,'For lab assistants'!C12,"") -> LVL600038050 | E12: =IF('For lab assistants'!O12>0,'For lab assistants'!O12,"") -> Tåruplund_2 | F12: =IF('For lab assistants'!E12>0,'For lab assistants'!E12,"") -> 16 | G12: =IF('For lab assistants'!P12>0,'For lab assistants'!P12,"") | H12: =IF('For lab assistants'!F12>0,'For lab assistants'!F12,"low") -> High | I12: =IF('For lab assistants'!G12>0,'For lab assistants'!G12,"no") -> yes | J12: =IF('For lab assistants'!H12>0,'For lab assistants'!H12,"") | K12: =IF('For lab assistants'!I12>0,'For lab assistants'!I12,"") -> MH | L12: =IF('For lab assistants'!J12>0,'For lab assistants'!J12,"") | M12: =IF('For lab assistants'!K12>0,'For lab assistants'!K12,"") -> 45240 | N12: =IF('For lab assistants'!D12>0,'For lab assistants'!M12,"") -> NKL | O12: =IF('For lab assistants'!D12>0,'For lab assistants'!N12,"") -> 45226 | P12: =IF(Output4SubSamplingSubmiss.!F12>0,Output4SubSamplingSubmiss.!F12,"")
A13: =IF('For lab assistants'!D13>0,'For lab assistants'!D13,"") -> LV3005888682 | B13: =IF('For lab assistants'!D13>0,'For lab assistants'!A13,"") -> D03 | C13: =IF('For lab assistants'!B13>0,'For lab assistants'!B13,"") -> ARack0471 | D13: =IF('For lab assistants'!C13>0,'For lab assistants'!C13,"") -> LVL600038050 | E13: =IF('For lab assistants'!O13>0,'For lab assistants'!O13,"") -> Tåruplund_2 | F13: =IF('For lab assistants'!E13>0,'For lab assistants'!E13,"") -> 17,5 | G13: =IF('For lab assistants'!P13>0,'For lab assistants'!P13,"") | H13: =IF('For lab assistants'!F13>0,'For lab assistants'!F13,"low") -> High | I13: =IF('For lab assistants'!G13>0,'For lab assistants'!G13,"no") -> yes | J13: =IF('For lab assistants'!H13>0,'For lab assistants'!H13,"") | K13: =IF('For lab assistants'!I13>0,'For lab assistants'!I13,"") -> MH | L13: =IF('For lab assistants'!J13>0,'For lab assistants'!J13,"") | M13: =IF('For lab assistants'!K13>0,'For lab assistants'!K13,"") -> 45240 | N13: =IF('For lab assistants'!D13>0,'For lab assistants'!M13,"") -> NKL | O13: =IF('For lab assistants'!D13>0,'For lab assistants'!N13,"") -> 45226 | P13: =IF(Output4SubSamplingSubmiss.!F13>0,Output4SubSamplingSubmiss.!F13,"")
A14: =IF('For lab assistants'!D14>0,'For lab assistants'!D14,"") -> LV3005888699 | B14: =IF('For lab assistants'!D14>0,'For lab assistants'!A14,"") -> A04 | C14: =IF('For lab assistants'!B14>0,'For lab assistants'!B14,"") -> ARack0471 | D14: =IF('For lab assistants'!C14>0,'For lab assistants'!C14,"") -> LVL600038050 | E14: =IF('For lab assistants'!O14>0,'For lab assistants'!O14,"") -> Tåruplund_2 | F14: =IF('For lab assistants'!E14>0,'For lab assistants'!E14,"") -> 19 | G14: =IF('For lab assistants'!P14>0,'For lab assistants'!P14,"") | H14: =IF('For lab assistants'!F14>0,'For lab assistants'!F14,"low") -> High | I14: =IF('For lab assistants'!G14>0,'For lab assistants'!G14,"no") -> yes | J14: =IF('For lab assistants'!H14>0,'For lab assistants'!H14,"") | K14: =IF('For lab assistants'!I14>0,'For lab assistants'!I14,"") -> MH | L14: =IF('For lab assistants'!J14>0,'For lab assistants'!J14,"") | M14: =IF('For lab assistants'!K14>0,'For lab assistants'!K14,"") -> 45240 | N14: =IF('For lab assistants'!D14>0,'For lab assistants'!M14,"") -> NKL | O14: =IF('For lab assistants'!D14>0,'For lab assistants'!N14,"") -> 45226 | P14: =IF(Output4SubSamplingSubmiss.!F14>0,Output4SubSamplingSubmiss.!F14,"")
... A673: =IF('For lab assistants'!D673>0,'For lab assistants'!D673,"") | B673: =IF('For lab assistants'!D673>0,'For lab assistants'!A673,"") | C673: =IF('For lab assistants'!B673>0,'For lab assistants'!B673,"") | D673: =IF('For lab assistants'!C673>0,'For lab assistants'!C673,"") | E673: =IF('For lab assistants'!O673>0,'For lab assistants'!O673,"") | F673: =IF('For lab assistants'!E673>0,'For lab assistants'!E673,"") | G673: =IF('For lab assistants'!P673>0,'For lab assistants'!P673,"") | H673: =IF('For lab assistants'!F673>0,'For lab assistants'!F673,"low") -> low | I673: =IF('For lab assistants'!G673>0,'For lab assistants'!G673,"no") -> no | J673: =IF('For lab assistants'!H673>0,'For lab assistants'!H673,"") | K673: =IF('For lab assistants'!I673>0,'For lab assistants'!I673,"") -> MH | L673: =IF('For lab assistants'!J673>0,'For lab assistants'!J673,"") | M673: =IF('For lab assistants'!K673>0,'For lab assistants'!K673,"") -> 45240 | N673: =IF('For lab assistants'!D673>0,'For lab assistants'!M673,"") | O673: =IF('For lab assistants'!D673>0,'For lab assistants'!N673,"") | P673: =IF(Output4SubSamplingSubmiss.!F673>0,Output4SubSamplingSubmiss.!F673,"")

Sheet BackroundCalculations
B3: high
B4: low
