Workbook
Name piinfo: #REF!

Sheet ReadMe
B1: For submitter (i.e, PI or project leader):
A2: 1: | B2: Download this file and RENAME: | C2: "Ordering_eDNA_Archive_sampling_(YYMMDD_Initials_ProjectID).xlsx"
C3: eg. Ordering_eDNA_Archive_sampling_(230715_LVI_NileValley).xlsx
A4: 2: | B4: Fill out the [Submit here] tab column B,C,D (and optionally E).
A5: 3: | B5: Mail the renamed and completed ordering form (this file) to Jesper Stenderup; eDNA_orders@sund.ku.dk.
A6: 4: | B6: Make sure the core is clearly labelled and easily available for the lab assistants.

Sheet Submit here
A1: No | B1: Submitter (initials) | C1: Submission date (yyyy-mm-dd) | D1: Bulk or Core segment ID (eg. ISL23_019_02A or CGG3_xxxxxx) | E1: Calibration tape depth (cm) | F1: Notes from submitter (optional)
A2: 1 | B2: NKL | C2: 45226 | D2: CAM2205A | E2: Continuous
A3: 2 | B3: =B2 -> NKL | C3: =C2 -> 45226 | D3: CAM2205A
A4: 3 | B4: =B3 -> NKL | C4: =C3 -> 45226 | D4: CAM2205A
A5: 4 | B5: =B4 -> NKL | C5: =C4 -> 45226 | D5: CAM2205A
A6: 5 | B6: =B5 -> NKL | C6: =C5 -> 45226 | D6: CAM2205A
A7: 6 | B7: =B6 -> NKL | C7: =C6 -> 45226 | D7: CAM2205A
A8: 7 | B8: =B7 -> NKL | C8: =C7 -> 45226 | D8: CAM2205A
A9: 8 | B9: =B8 -> NKL | C9: =C8 -> 45226 | D9: CAM2205A
A10: 9 | B10: =B9 -> NKL | C10: =C9 -> 45226 | D10: CAM2205A
A11: 10 | B11: =B10 -> NKL | C11: =C10 -> 45226 | D11: CAM2205A
A12: 11 | B12: =B11 -> NKL | C12: =C11 -> 45226 | D12: CAM2205A
A13: 12 | B13: =B12 -> NKL | C13: =C12 -> 45226 | D13: CAM2205A
A14: 13 | B14: =B13 -> NKL | C14: =C13 -> 45226 | D14: CAM2205A
... A83: 82 | B83: =B82 -> NKL | C83: =C82 -> 45226 | D83: CAM2205A
A84: 83 | B84: =B83 -> NKL | C84: =C83 -> 45226
A85: 84 | B85: =B84 -> NKL | C85: =C84 -> 45226
A86: 85 | B86: =B85 -> NKL | C86: =C85 -> 45226
A87: 86 | B87: =B86 -> NKL | C87: =C86 -> 45226
A88: 87 | B88: =B87 -> NKL | C88: =C87 -> 45226
A89: 88 | B89: =B88 -> NKL | C89: =C88 -> 45226
A90: 89 | B90: =B89 -> NKL | C90: =C89 -> 45226
A91: 90 | B91: =B90 -> NKL | C91: =C90 -> 45226
A92: 91 | B92: =B91 -> NKL | C92: =C91 -> 45226
A93: 92 | B93: =B92 -> NKL | C93: =C92 -> 45226
A94: 93 | B94: =B93 -> NKL | C94: =C93 -> 45226
A95: 94 | B95: =B94 -> NKL | C95: =C94 -> 45226
... A673: 672 | B673: =B672 -> NKL | C673: =C672 -> 45226

Sheet Output4SubSamplingSubmiss.
A1: ='For lab assistants'!O1 -> Core segment ID (fx ISL23_019_02A) | B1: ='For lab assistants'!A1 -> Archive rack position | C1: ='For lab assistants'!B1 -> Archive RACK name (eg. ARack0052) | D1: ='For lab assistants'!C1 -> Archive RACK barcode | E1: ='For lab assistants'!D1 -> Archive TUBE barcode | F1: ='For lab assistants'!Q1 -> Notes from submitter (optional)
A2: =IF('For lab assistants'!#REF!>0,'For lab assistants'!#REF!,"") -> #REF! | B2: =IF('For lab assistants'!#REF!>0,'For lab assistants'!#REF!,"") -> #REF! | C2: =IF('For lab assistants'!#REF!>0,'For lab assistants'!#REF!,"") -> #REF! | D2: =IF('For lab assistants'!#REF!>0,'For lab assistants'!#REF!,"") -> #REF! | E2: =IF('For lab assistants'!#REF!>0,'For lab assistants'!#REF!,"") -> #REF! | F2: =IF('For lab assistants'!#REF!>0,'For lab assistants'!#REF!,"") -> #REF!
A3: =IF('For lab assistants'!#REF!>0,'For lab assistants'!#REF!,"") -> #REF! | B3: =IF('For lab assistants'!#REF!>0,'For lab assistants'!#REF!,"") -> #REF! | C3: =IF('For lab assistants'!#REF!>0,'For lab assistants'!#REF!,"") -> #REF! | D3: =IF('For lab assistants'!#REF!>0,'For lab assistants'!#REF!,"") -> #REF! | E3: =IF('For lab assistants'!#REF!>0,'For lab assistants'!#REF!,"") -> #REF! | F3: =IF('For lab assistants'!#REF!>0,'For lab assistants'!#REF!,"") -> #REF!
A4: =IF('For lab assistants'!#REF!>0,'For lab assistants'!#REF!,"") -> #REF! | B4: =IF('For lab assistants'!#REF!>0,'For lab assistants'!#REF!,"") -> #REF! | C4: =IF('For lab assistants'!#REF!>0,'For lab assistants'!#REF!,"") -> #REF! | D4: =IF('For lab assistants'!#REF!>0,'For lab assistants'!#REF!,"") -> #REF! | E4: =IF('For lab assistants'!#REF!>0,'For lab assistants'!#REF!,"") -> #REF! | F4: =IF('For lab assistants'!#REF!>0,'For lab assistants'!#REF!,"") -> #REF!
A5: =IF('For lab assistants'!#REF!>0,'For lab assistants'!#REF!,"") -> #REF! | B5: =IF('For lab assistants'!#REF!>0,'For lab assistants'!#REF!,"") -> #REF! | C5: =IF('For lab assistants'!#REF!>0,'For lab assistants'!#REF!,"") -> #REF! | D5: =IF('For lab assistants'!#REF!>0,'For lab assistants'!#REF!,"") -> #REF! | E5: =IF('For lab assistants'!#REF!>0,'For lab assistants'!#REF!,"") -> #REF! | F5: =IF('For lab assistants'!#REF!>0,'For lab assistants'!#REF!,"") -> #REF!
A6: =IF('For lab assistants'!#REF!>0,'For lab assistants'!#REF!,"") -> #REF! | B6: =IF('For lab assistants'!#REF!>0,'For lab assistants'!#REF!,"") -> #REF! | C6: =IF('For lab assistants'!#REF!>0,'For lab assistants'!#REF!,"") -> #REF! | D6: =IF('For lab assistants'!#REF!>0,'For lab assistants'!#REF!,"") -> #REF! | E6: =IF('For lab assistants'!#REF!>0,'For lab assistants'!#REF!,"") -> #REF! | F6: =IF('For lab assistants'!#REF!>0,'For lab assistants'!#REF!,"") -> #REF!
A7: =IF('For lab assistants'!#REF!>0,'For lab assistants'!#REF!,"") -> #REF! | B7: =IF('For lab assistants'!#REF!>0,'For lab assistants'!#REF!,"") -> #REF! | C7: =IF('For lab assistants'!#REF!>0,'For lab assistants'!#REF!,"") -> #REF! | D7: =IF('For lab assistants'!#REF!>0,'For lab assistants'!#REF!,"") -> #REF! | E7: =IF('For lab assistants'!#REF!>0,'For lab assistants'!#REF!,"") -> #REF! | F7: =IF('For lab assistants'!#REF!>0,'For lab assistants'!#REF!,"") -> #REF!
A8: =IF('For lab assistants'!#REF!>0,'For lab assistants'!#REF!,"") -> #REF! | B8: =IF('For lab assistants'!#REF!>0,'For lab assistants'!#REF!,"") -> #REF! | C8: =IF('For lab assistants'!#REF!>0,'For lab assistants'!#REF!,"") -> #REF! | D8: =IF('For lab assistants'!#REF!>0,'For lab assistants'!#REF!,"") -> #REF! | E8: =IF('For lab assistants'!#REF!>0,'For lab assistants'!#REF!,"") -> #REF! | F8: =IF('For lab assistants'!#REF!>0,'For lab assistants'!#REF!,"") -> #REF!
A9: =IF('For lab assistants'!#REF!>0,'For lab assistants'!#REF!,"") -> #REF! | B9: =IF('For lab assistants'!#REF!>0,'For lab assistants'!#REF!,"") -> #REF! | C9: =IF('For lab assistants'!#REF!>0,'For lab assistants'!#REF!,"") -> #REF! | D9: =IF('For lab assistants'!#REF!>0,'For lab assistants'!#REF!,"") -> #REF! | E9: =IF('For lab assistants'!#REF!>0,'For lab assistants'!#REF!,"") -> #REF! | F9: =IF('For lab assistants'!#REF!>0,'For lab assistants'!#REF!,"") -> #REF!
A10: =IF('For lab assistants'!#REF!>0,'For lab assistants'!#REF!,"") -> #REF! | B10: =IF('For lab assistants'!#REF!>0,'For lab assistants'!#REF!,"") -> #REF! | C10: =IF('For lab assistants'!#REF!>0,'For lab assistants'!#REF!,"") -> #REF! | D10: =IF('For lab assistants'!#REF!>0,'For lab assistants'!#REF!,"") -> #REF! | E10: =IF('For lab assistants'!#REF!>0,'For lab assistants'!#REF!,"") -> #REF! | F10: =IF('For lab assistants'!#REF!>0,'For lab assistants'!#REF!,"") -> #REF!
A11: =IF('For lab assistants'!#REF!>0,'For lab assistants'!#REF!,"") -> #REF! | B11: =IF('For lab assistants'!#REF!>0,'For lab assistants'!#REF!,"") -> #REF! | C11: =IF('For lab assistants'!#REF!>0,'For lab assistants'!#REF!,"") -> #REF! | D11: =IF('For lab assistants'!#REF!>0,'For lab assistants'!#REF!,"") -> #REF! | E11: =IF('For lab assistants'!#REF!>0,'For lab assistants'!#REF!,"") -> #REF! | F11: =IF('For lab assistants'!#REF!>0,'For lab assistants'!#REF!,"") -> #REF!
A12: =IF('For lab assistants'!#REF!>0,'For lab assistants'!#REF!,"") -> #REF! | B12: =IF('For lab assistants'!#REF!>0,'For lab assistants'!#REF!,"") -> #REF! | C12: =IF('For lab assistants'!#REF!>0,'For lab assistants'!#REF!,"") -> #REF! | D12: =IF('For lab assistants'!#REF!>0,'For lab assistants'!#REF!,"") -> #REF! | E12: =IF('For lab assistants'!#REF!>0,'For lab assistants'!#REF!,"") -> #REF! | F12: =IF('For lab assistants'!#REF!>0,'For lab assistants'!#REF!,"") -> #REF!
A13: =IF('For lab assistants'!#REF!>0,'For lab assistants'!#REF!,"") -> #REF! | B13: =IF('For lab assistants'!#REF!>0,'For lab assistants'!#REF!,"") -> #REF! | C13: =IF('For lab assistants'!#REF!>0,'For lab assistants'!#REF!,"") -> #REF! | D13: =IF('For lab assistants'!#REF!>0,'For lab assistants'!#REF!,"") -> #REF! | E13: =IF('For lab assistants'!#REF!>0,'For lab assistants'!#REF!,"") -> #REF! | F13: =IF('For lab assistants'!#REF!>0,'For lab assistants'!#REF!,"") -> #REF!
... A19: =IF('For lab assistants'!#REF!>0,'For lab assistants'!#REF!,"") -> #REF! | B19: =IF('For lab assistants'!#REF!>0,'For lab assistants'!#REF!,"") -> #REF! | C19: =IF('For lab assistants'!#REF!>0,'For lab assistants'!#REF!,"") -> #REF! | D19: =IF('For lab assistants'!#REF!>0,'For lab assistants'!#REF!,"") -> #REF! | E19: =IF('For lab assistants'!#REF!>0,'For lab assistants'!#REF!,"") -> #REF! | F19: =IF('For lab assistants'!#REF!>0,'For lab assistants'!#REF!,"") -> #REF!
A20: =IF('For lab assistants'!O2>0,'For lab assistants'!O2,"") -> CAM2205A | B20: =IF('For lab assistants'!D2>0,'For lab assistants'!A2,"") -> C05 | C20: =IF('For lab assistants'!B2>0,'For lab assistants'!B2,"") -> ARack0457 | D20: =IF('For lab assistants'!C2>0,'For lab assistants'!C2,"") -> LVL600038007 | E20: =IF('For lab assistants'!D2>0,'For lab assistants'!D2,"") -> LV3005887701 | F20: =IF('For lab assistants'!Q2>0,'For lab assistants'!Q2,"")
A21: =IF('For lab assistants'!O3>0,'For lab assistants'!O3,"") -> CAM2205A | B21: =IF('For lab assistants'!D3>0,'For lab assistants'!A3,"") -> D05 | C21: =IF('For lab assistants'!B3>0,'For lab assistants'!B3,"") -> ARack0457 | D21: =IF('For lab assistants'!C3>0,'For lab assistants'!C3,"") -> LVL600038007 | E21: =IF('For lab assistants'!D3>0,'For lab assistants'!D3,"") -> LV3005887607 | F21: =IF('For lab assistants'!Q3>0,'For lab assistants'!Q3,"")
A22: =IF('For lab assistants'!O4>0,'For lab assistants'!O4,"") -> CAM2205A | B22: =IF('For lab assistants'!D4>0,'For lab assistants'!A4,"") -> A06 | C22: =IF('For lab assistants'!B4>0,'For lab assistants'!B4,"") -> ARack0457 | D22: =IF('For lab assistants'!C4>0,'For lab assistants'!C4,"") -> LVL600038007 | E22: =IF('For lab assistants'!D4>0,'For lab assistants'!D4,"") -> LV3005887608 | F22: =IF('For lab assistants'!Q4>0,'For lab assistants'!Q4,"")
A23: =IF('For lab assistants'!O5>0,'For lab assistants'!O5,"") -> CAM2205A | B23: =IF('For lab assistants'!D5>0,'For lab assistants'!A5,"") -> B06 | C23: =IF('For lab assistants'!B5>0,'For lab assistants'!B5,"") -> ARack0457 | D23: =IF('For lab assistants'!C5>0,'For lab assistants'!C5,"") -> LVL600038007 | E23: =IF('For lab assistants'!D5>0,'For lab assistants'!D5,"") -> LV3005887602 | F23: =IF('For lab assistants'!Q5>0,'For lab assistants'!Q5,"")
A24: =IF('For lab assistants'!O6>0,'For lab assistants'!O6,"") -> CAM2205A | B24: =IF('For lab assistants'!D6>0,'For lab assistants'!A6,"") -> C06 | C24: =IF('For lab assistants'!B6>0,'For lab assistants'!B6,"") -> ARack0457 | D24: =IF('For lab assistants'!C6>0,'For lab assistants'!C6,"") -> LVL600038007 | E24: =IF('For lab assistants'!D6>0,'For lab assistants'!D6,"") -> LV3005887615 | F24: =IF('For lab assistants'!Q6>0,'For lab assistants'!Q6,"")
A25: =IF('For lab assistants'!O7>0,'For lab assistants'!O7,"") -> CAM2205A | B25: =IF('For lab assistants'!D7>0,'For lab assistants'!A7,"") -> D06 | C25: =IF('For lab assistants'!B7>0,'For lab assistants'!B7,"") -> ARack0457 | D25: =IF('For lab assistants'!C7>0,'For lab assistants'!C7,"") -> LVL600038007 | E25: =IF('For lab assistants'!D7>0,'For lab assistants'!D7,"") -> LV3005887614 | F25: =IF('For lab assistants'!Q7>0,'For lab assistants'!Q7,"")
A26: =IF('For lab assistants'!O8>0,'For lab assistants'!O8,"") -> CAM2205A | B26: =IF('For lab assistants'!D8>0,'For lab assistants'!A8,"") -> A01 | C26: =IF('For lab assistants'!B8>0,'For lab assistants'!B8,"") -> ARack0459 | D26: =IF('For lab assistants'!C8>0,'For lab assistants'!C8,"") -> LVL600038005 | E26: =IF('For lab assistants'!D8>0,'For lab assistants'!D8,"") -> LV3005887544 | F26: =IF('For lab assistants'!Q8>0,'For lab assistants'!Q8,"")
A27: =IF('For lab assistants'!O9>0,'For lab assistants'!O9,"") -> CAM2205A | B27: =IF('For lab assistants'!D9>0,'For lab assistants'!A9,"") -> B01 | C27: =IF('For lab assistants'!B9>0,'For lab assistants'!B9,"") -> ARack0459 | D27: =IF('For lab assistants'!C9>0,'For lab assistants'!C9,"") -> LVL600038005 | E27: =IF('For lab assistants'!D9>0,'For lab assistants'!D9,"") -> LV3005887550 | F27: =IF('For lab assistants'!Q9>0,'For lab assistants'!Q9,"")
A28: =IF('For lab assistants'!O10>0,'For lab assistants'!O10,"") -> CAM2205A | B28: =IF('For lab assistants'!D10>0,'For lab assistants'!A10,"") -> C01 | C28: =IF('For lab assistants'!B10>0,'For lab assistants'!B10,"") -> ARack0459 | D28: =IF('For lab assistants'!C10>0,'For lab assistants'!C10,"") -> LVL600038005 | E28: =IF('For lab assistants'!D10>0,'For lab assistants'!D10,"") -> LV3005887556 | F28: =IF('For lab assistants'!Q10>0,'For lab assistants'!Q10,"")
A29: =IF('For lab assistants'!O11>0,'For lab assistants'!O11,"") -> CAM2205A | B29: =IF('For lab assistants'!D11>0,'For lab assistants'!A11,"") -> D01 | C29: =IF('For lab assistants'!B11>0,'For lab assistants'!B11,"") -> ARack0459 | D29: =IF('For lab assistants'!C11>0,'For lab assistants'!C11,"") -> LVL600038005 | E29: =IF('For lab assistants'!D11>0,'For lab assistants'!D11,"") -> LV3005887563 | F29: =IF('For lab assistants'!Q11>0,'For lab assistants'!Q11,"")
A30: =IF('For lab assistants'!O12>0,'For lab assistants'!O12,"") -> CAM2205A | B30: =IF('For lab assistants'!D12>0,'For lab assistants'!A12,"") -> A02 | C30: =IF('For lab assistants'!B12>0,'For lab assistants'!B12,"") -> ARack0459 | D30: =IF('For lab assistants'!C12>0,'For lab assistants'!C12,"") -> LVL600038005 | E30: =IF('For lab assistants'!D12>0,'For lab assistants'!D12,"") -> LV3005887543 | F30: =IF('For lab assistants'!Q12>0,'For lab assistants'!Q12,"")
A31: =IF('For lab assistants'!O13>0,'For lab assistants'!O13,"") -> CAM2205A | B31: =IF('For lab assistants'!D13>0,'For lab assistants'!A13,"") -> B02 | C31: =IF('For lab assistants'!B13>0,'For lab assistants'!B13,"") -> ARack0459 | D31: =IF('For lab assistants'!C13>0,'For lab assistants'!C13,"") -> LVL600038005 | E31: =IF('For lab assistants'!D13>0,'For lab assistants'!D13,"") -> LV3005887549 | F31: =IF('For lab assistants'!Q13>0,'For lab assistants'!Q13,"")
... A73: =IF('For lab assistants'!O55>0,'For lab assistants'!O55,"") -> CAM2205A | B73: =IF('For lab assistants'!D55>0,'For lab assistants'!A55,"") -> D06 | C73: =IF('For lab assistants'!B55>0,'For lab assistants'!B55,"") -> ARack0460 | D73: =IF('For lab assistants'!C55>0,'For lab assistants'!C55,"") -> LVL600038004 | E73: =IF('For lab assistants'!D55>0,'For lab assistants'!D55,"") -> LV3005887508 | F73: =IF('For lab assistants'!Q55>0,'For lab assistants'!Q55,"")
A74: =IF('For lab assistants'!O56>0,'For lab assistants'!O56,"") -> CAM2205A | B74: =IF('For lab assistants'!E60>0,'For lab assistants'!A56,"") -> A01 | C74: =IF('For lab assistants'!B56>0,'For lab assistants'!B56,"") -> ARack0461 | D74: =IF('For lab assistants'!C56>0,'For lab assistants'!C56,"") -> LVL600038029 | E74: =IF('For lab assistants'!E60>0,'For lab assistants'!E60,"") -> 88 | F74: =IF('For lab assistants'!Q56>0,'For lab assistants'!Q56,"")
A75: =IF('For lab assistants'!O57>0,'For lab assistants'!O57,"") -> CAM2205A | B75: =IF('For lab assistants'!E61>0,'For lab assistants'!A57,"") -> B01 | C75: =IF('For lab assistants'!B57>0,'For lab assistants'!B57,"") -> ARack0461 | D75: =IF('For lab assistants'!C57>0,'For lab assistants'!C57,"") -> LVL600038029 | E75: =IF('For lab assistants'!E61>0,'For lab assistants'!E61,"") -> 90 | F75: =IF('For lab assistants'!Q57>0,'For lab assistants'!Q57,"")
A76: =IF('For lab assistants'!O58>0,'For lab assistants'!O58,"") -> CAM2205A | B76: =IF('For lab assistants'!E62>0,'For lab assistants'!A58,"") -> C01 | C76: =IF('For lab assistants'!B58>0,'For lab assistants'!B58,"") -> ARack0461 | D76: =IF('For lab assistants'!C58>0,'For lab assistants'!C58,"") -> LVL600038029 | E76: =IF('For lab assistants'!E62>0,'For lab assistants'!E62,"") -> 91 | F76: =IF('For lab assistants'!Q58>0,'For lab assistants'!Q58,"")
A77: =IF('For lab assistants'!O59>0,'For lab assistants'!O59,"") -> CAM2205A | B77: =IF('For lab assistants'!D59>0,'For lab assistants'!A59,"") -> D01 | C77: =IF('For lab assistants'!B59>0,'For lab assistants'!B59,"") -> ARack0461 | D77: =IF('For lab assistants'!C59>0,'For lab assistants'!C59,"") -> LVL600038029 | E77: =IF('For lab assistants'!D59>0,'For lab assistants'!D59,"") -> LV3005888167 | F77: =IF('For lab assistants'!Q59>0,'For lab assistants'!Q59,"")
A78: =IF('For lab assistants'!O60>0,'For lab assistants'!O60,"") -> CAM2205A | B78: =IF('For lab assistants'!D60>0,'For lab assistants'!A60,"") -> A02 | C78: =IF('For lab assistants'!B60>0,'For lab assistants'!B60,"") -> ARack0461 | D78: =IF('For lab assistants'!C60>0,'For lab assistants'!C60,"") -> LVL600038029 | E78: =IF('For lab assistants'!D60>0,'For lab assistants'!D60,"") -> LV3005888166 | F78: =IF('For lab assistants'!Q60>0,'For lab assistants'!Q60,"")
A79: =IF('For lab assistants'!O61>0,'For lab assistants'!O61,"") -> CAM2205A | B79: =IF('For lab assistants'!D61>0,'For lab assistants'!A61,"") -> B02 | C79: =IF('For lab assistants'!B61>0,'For lab assistants'!B61,"") -> ARack0461 | D79: =IF('For lab assistants'!C61>0,'For lab assistants'!C61,"") -> LVL600038029 | E79: =IF('For lab assistants'!D61>0,'For lab assistants'!D61,"") -> LV3005888148 | F79: =IF('For lab assistants'!Q61>0,'For lab assistants'!Q61,"")
A80: =IF('For lab assistants'!O62>0,'For lab assistants'!O62,"") -> CAM2205A | B80: =IF('For lab assistants'!D62>0,'For lab assistants'!A62,"") -> C02 | C80: =IF('For lab assistants'!B62>0,'For lab assistants'!B62,"") -> ARack0461 | D80: =IF('For lab assistants'!C62>0,'For lab assistants'!C62,"") -> LVL600038029 | E80: =IF('For lab assistants'!D62>0,'For lab assistants'!D62,"") -> LV3005888165 | F80: =IF('For lab assistants'!Q62>0,'For lab assistants'!Q62,"")
A81: =IF('For lab assistants'!#REF!>0,'For lab assistants'!#REF!,"") -> #REF! | B81: =IF('For lab assistants'!D63>0,'For lab assistants'!A63,"") | C81: =IF('For lab assistants'!B63>0,'For lab assistants'!B63,"") | D81: =IF('For lab assistants'!C63>0,'For lab assistants'!C63,"") | E81: =IF('For lab assistants'!D63>0,'For lab assistants'!D63,"") | F81: =IF('For lab assistants'!Q63>0,'For lab assistants'!Q63,"")
A82: =IF('For lab assistants'!O63>0,'For lab assistants'!O63,"") -> CAM2205A | B82: =IF('For lab assistants'!D64>0,'For lab assistants'!A64,"") | C82: =IF('For lab assistants'!B64>0,'For lab assistants'!B64,"") | D82: =IF('For lab assistants'!C64>0,'For lab assistants'!C64,"") | E82: =IF('For lab assistants'!D64>0,'For lab assistants'!D64,"") | F82: =IF('For lab assistants'!Q64>0,'For lab assistants'!Q64,"")
A83: =IF('For lab assistants'!O64>0,'For lab assistants'!O64,"") | B83: =IF('For lab assistants'!D65>0,'For lab assistants'!A65,"") | C83: =IF('For lab assistants'!B65>0,'For lab assistants'!B65,"") | D83: =IF('For lab assistants'!C65>0,'For lab assistants'!C65,"") | E83: =IF('For lab assistants'!D65>0,'For lab assistants'!D65,"") | F83: =IF('For lab assistants'!Q65>0,'For lab assistants'!Q65,"")
A84: =IF('For lab assistants'!O65>0,'For lab assistants'!O65,"") | B84: =IF('For lab assistants'!D66>0,'For lab assistants'!A66,"") | C84: =IF('For lab assistants'!B66>0,'For lab assistants'!B66,"") | D84: =IF('For lab assistants'!C66>0,'For lab assistants'!C66,"") | E84: =IF('For lab assistants'!D66>0,'For lab assistants'!D66,"") | F84: =IF('For lab assistants'!Q66>0,'For lab assistants'!Q66,"")
A85: =IF('For lab assistants'!O66>0,'For lab assistants'!O66,"") | B85: =IF('For lab assistants'!D67>0,'For lab assistants'!A67,"") | C85: =IF('For lab assistants'!B67>0,'For lab assistants'!B67,"") | D85: =IF('For lab assistants'!C67>0,'For lab assistants'!C67,"") | E85: =IF('For lab assistants'!D67>0,'For lab assistants'!D67,"") | F85: =IF('For lab assistants'!Q67>0,'For lab assistants'!Q67,"")
A86: =IF('For lab assistants'!O67>0,'For lab assistants'!O67,"") | B86: =IF('For lab assistants'!D68>0,'For lab assistants'!A68,"") | C86: =IF('For lab assistants'!B68>0,'For lab assistants'!B68,"") | D86: =IF('For lab assistants'!C68>0,'For lab assistants'!C68,"") | E86: =IF('For lab assistants'!D68>0,'For lab assistants'!D68,"") | F86: =IF('For lab assistants'!Q68>0,'For lab assistants'!Q68,"")
...

Sheet For lab assistants
A1: Archive rack position | B1: Archive RACK name (eg. ARack0052) | C1: Archive RACK barcode | D1: Archive TUBE barcode | E1: Depth sampled (tape, cm) | F1: Organic content (High /Low) | G1: Surface exposed? (ie Back wall hit?) (Yes / No) | H1: Remarks from sampling (optional) | I1: Sampled by 1 (initials) | J1: Sampled by 2 (initials) | K1: Sampled date (yyyy-mm-dd) | L1: No | M1: Submitter (initials) | N1: Submission date (yyyy-mm-dd) | O1: Core segment ID (fx ISL23_019_02A) | P1: Ordered depth (Calibration tape, cm) | Q1: Notes from submitter (optional)
A2: C05 | B2: ARack0457 | C2: LVL600038007 | D2: LV3005887701 | E2: 0.5 | F2: high | I2: FM | J2: - | K2: 45229 | L2: 1 | M2: =IF('Submit here'!B20>0,'Submit here'!B20,"") -> NKL | N2: =IF('Submit here'!C20>0,'Submit here'!C20,"") -> 45226 | O2: =IF('Submit here'!D20>0,'Submit here'!D20,"") -> CAM2205A | P2: =IF('Submit here'!E20>0,'Submit here'!E20,"") | Q2: =IF('Submit here'!F20>0,'Submit here'!F20,"")
A3: D05 | B3: =B2 -> ARack0457 | C3: =C2 -> LVL600038007 | D3: LV3005887607 | E3: 1.5 | F3: high | I3: =I2 -> FM | J3: =J2 -> - | K3: =K2 -> 45229 | L3: 2 | M3: =IF('Submit here'!B21>0,'Submit here'!B21,"") -> NKL | N3: =IF('Submit here'!C21>0,'Submit here'!C21,"") -> 45226 | O3: =IF('Submit here'!D21>0,'Submit here'!D21,"") -> CAM2205A | P3: =IF('Submit here'!E21>0,'Submit here'!E21,"") | Q3: =IF('Submit here'!F21>0,'Submit here'!F21,"")
A4: A06 | B4: =B3 -> ARack0457 | C4: =C3 -> LVL600038007 | D4: LV3005887608 | E4: 3 | F4: high | I4: =I3 -> FM | J4: =J3 -> - | K4: =K3 -> 45229 | L4: 3 | M4: =IF('Submit here'!B22>0,'Submit here'!B22,"") -> NKL | N4: =IF('Submit here'!C22>0,'Submit here'!C22,"") -> 45226 | O4: =IF('Submit here'!D22>0,'Submit here'!D22,"") -> CAM2205A | P4: =IF('Submit here'!E22>0,'Submit here'!E22,"") | Q4: =IF('Submit here'!F22>0,'Submit here'!F22,"")
A5: B06 | B5: =B4 -> ARack0457 | C5: =C4 -> LVL600038007 | D5: LV3005887602 | E5: 4.5 | F5: high | I5: =I4 -> FM | J5: =J4 -> - | K5: =K4 -> 45229 | L5: 4 | M5: =IF('Submit here'!B23>0,'Submit here'!B23,"") -> NKL | N5: =IF('Submit here'!C23>0,'Submit here'!C23,"") -> 45226 | O5: =IF('Submit here'!D23>0,'Submit here'!D23,"") -> CAM2205A | P5: =IF('Submit here'!E23>0,'Submit here'!E23,"") | Q5: =IF('Submit here'!F23>0,'Submit here'!F23,"")
A6: C06 | B6: =B5 -> ARack0457 | C6: =C5 -> LVL600038007 | D6: LV3005887615 | E6: 6 | F6: high | I6: =I5 -> FM | J6: =J5 -> - | K6: =K5 -> 45229 | L6: 5 | M6: =IF('Submit here'!B24>0,'Submit here'!B24,"") -> NKL | N6: =IF('Submit here'!C24>0,'Submit here'!C24,"") -> 45226 | O6: =IF('Submit here'!D24>0,'Submit here'!D24,"") -> CAM2205A | P6: =IF('Submit here'!E24>0,'Submit here'!E24,"") | Q6: =IF('Submit here'!F24>0,'Submit here'!F24,"")
A7: D06 | B7: =B6 -> ARack0457 | C7: =C6 -> LVL600038007 | D7: LV3005887614 | E7: 7.5 | F7: high | I7: =I6 -> FM | J7: =J6 -> - | K7: =K6 -> 45229 | L7: 6 | M7: =IF('Submit here'!B25>0,'Submit here'!B25,"") -> NKL | N7: =IF('Submit here'!C25>0,'Submit here'!C25,"") -> 45226 | O7: =IF('Submit here'!D25>0,'Submit here'!D25,"") -> CAM2205A | P7: =IF('Submit here'!E25>0,'Submit here'!E25,"") | Q7: =IF('Submit here'!F25>0,'Submit here'!F25,"")
A8: A01 | B8: ARack0459 | C8: LVL600038005 | D8: LV3005887544 | E8: 9 | F8: high | I8: =I7 -> FM | J8: =J7 -> - | K8: =K7 -> 45229 | L8: 7 | M8: =IF('Submit here'!B26>0,'Submit here'!B26,"") -> NKL | N8: =IF('Submit here'!C26>0,'Submit here'!C26,"") -> 45226 | O8: =IF('Submit here'!D26>0,'Submit here'!D26,"") -> CAM2205A | P8: =IF('Submit here'!E26>0,'Submit here'!E26,"") | Q8: =IF('Submit here'!F26>0,'Submit here'!F26,"")
A9: B01 | B9: =B8 -> ARack0459 | C9: =C8 -> LVL600038005 | D9: LV3005887550 | E9: 10.5 | F9: high | I9: =I8 -> FM | J9: =J8 -> - | K9: =K8 -> 45229 | L9: 8 | M9: =IF('Submit here'!B27>0,'Submit here'!B27,"") -> NKL | N9: =IF('Submit here'!C27>0,'Submit here'!C27,"") -> 45226 | O9: =IF('Submit here'!D27>0,'Submit here'!D27,"") -> CAM2205A | P9: =IF('Submit here'!E27>0,'Submit here'!E27,"") | Q9: =IF('Submit here'!F27>0,'Submit here'!F27,"")
A10: C01 | B10: =B9 -> ARack0459 | C10: =C9 -> LVL600038005 | D10: LV3005887556 | E10: 12 | F10: high | I10: =I9 -> FM | J10: =J9 -> - | K10: =K9 -> 45229 | L10: 9 | M10: =IF('Submit here'!B28>0,'Submit here'!B28,"") -> NKL | N10: =IF('Submit here'!C28>0,'Submit here'!C28,"") -> 45226 | O10: =IF('Submit here'!D28>0,'Submit here'!D28,"") -> CAM2205A | P10: =IF('Submit here'!E28>0,'Submit here'!E28,"") | Q10: =IF('Submit here'!F28>0,'Submit here'!F28,"")
A11: D01 | B11: =B10 -> ARack0459 | C11: =C10 -> LVL600038005 | D11: LV3005887563 | E11: 13.5 | F11: high | I11: =I10 -> FM | J11: =J10 -> - | K11: =K10 -> 45229 | L11: 10 | M11: =IF('Submit here'!B29>0,'Submit here'!B29,"") -> NKL | N11: =IF('Submit here'!C29>0,'Submit here'!C29,"") -> 45226 | O11: =IF('Submit here'!D29>0,'Submit here'!D29,"") -> CAM2205A | P11: =IF('Submit here'!E29>0,'Submit here'!E29,"") | Q11: =IF('Submit here'!F29>0,'Submit here'!F29,"")
A12: A02 | B12: =B11 -> ARack0459 | C12: =C11 -> LVL600038005 | D12: LV3005887543 | E12: 15 | F12: high | I12: =I11 -> FM | J12: =J11 -> - | K12: =K11 -> 45229 | L12: 11 | M12: =IF('Submit here'!B30>0,'Submit here'!B30,"") -> NKL | N12: =IF('Submit here'!C30>0,'Submit here'!C30,"") -> 45226 | O12: =IF('Submit here'!D30>0,'Submit here'!D30,"") -> CAM2205A | P12: =IF('Submit here'!E30>0,'Submit here'!E30,"") | Q12: =IF('Submit here'!F30>0,'Submit here'!F30,"")
A13: B02 | B13: =B12 -> ARack0459 | C13: =C12 -> LVL600038005 | D13: LV3005887549 | E13: 17 | F13: high | I13: =I12 -> FM | J13: =J12 -> - | K13: =K12 -> 45229 | L13: 12 | M13: =IF('Submit here'!B31>0,'Submit here'!B31,"") -> NKL | N13: =IF('Submit here'!C31>0,'Submit here'!C31,"") -> 45226 | O13: =IF('Submit here'!D31>0,'Submit here'!D31,"") -> CAM2205A | P13: =IF('Submit here'!E31>0,'Submit here'!E31,"") | Q13: =IF('Submit here'!F31>0,'Submit here'!F31,"")
A14: C02 | B14: =B13 -> ARack0459 | C14: =C13 -> LVL600038005 | D14: LV3005887555 | E14: 18 | F14: high | I14: =I13 -> FM | J14: =J13 -> - | K14: =K13 -> 45229 | L14: 13 | M14: =IF('Submit here'!B32>0,'Submit here'!B32,"") -> NKL | N14: =IF('Submit here'!C32>0,'Submit here'!C32,"") -> 45226 | O14: =IF('Submit here'!D32>0,'Submit here'!D32,"") -> CAM2205A | P14: =IF('Submit here'!E32>0,'Submit here'!E32,"") | Q14: =IF('Submit here'!F32>0,'Submit here'!F32,"")
A15: D02 | B15: =B14 -> ARack0459 | C15: =C14 -> LVL600038005 | D15: LV3005887562 | E15: 20 | F15: high | I15: =I14 -> FM | J15: =J14 -> - | K15: =K14 -> 45229 | L15: 14 | M15: =IF('Submit here'!B33>0,'Submit here'!B33,"") -> NKL | N15: =IF('Submit here'!C33>0,'Submit here'!C33,"") -> 45226 | O15: =IF('Submit here'!D33>0,'Submit here'!D33,"") -> CAM2205A | P15: =IF('Submit here'!E33>0,'Submit here'!E33,"") | Q15: =IF('Submit here'!F33>0,'Submit here'!F33,"")
A16: A03 | B16: =B15 -> ARack0459 | C16: =C15 -> LVL600038005 | D16: LV3005887561 | E16: 21.5 | F16: high | I16: =I15 -> FM | J16: =J15 -> - | K16: =K15 -> 45229 | L16: 15 | M16: =IF('Submit here'!B34>0,'Submit here'!B34,"") -> NKL | N16: =IF('Submit here'!C34>0,'Submit here'!C34,"") -> 45226 | O16: =IF('Submit here'!D34>0,'Submit here'!D34,"") -> CAM2205A | P16: =IF('Submit here'!E34>0,'Submit here'!E34,"") | Q16: =IF('Submit here'!F34>0,'Submit here'!F34,"")
A17: B03 | B17: =B16 -> ARack0459 | C17: =C16 -> LVL600038005 | D17: LV3005887554 | E17: 23 | F17: high | I17: =I16 -> FM | J17: =J16 -> - | K17: =K16 -> 45229 | L17: 16 | M17: =IF('Submit here'!B35>0,'Submit here'!B35,"") -> NKL | N17: =IF('Submit here'!C35>0,'Submit here'!C35,"") -> 45226 | O17: =IF('Submit here'!D35>0,'Submit here'!D35,"") -> CAM2205A | P17: =IF('Submit here'!E35>0,'Submit here'!E35,"") | Q17: =IF('Submit here'!F35>0,'Submit here'!F35,"")
A18: C03 | B18: =B17 -> ARack0459 | C18: =C17 -> LVL600038005 | D18: LV3005887548 | E18: 24 | F18: high | I18: =I17 -> FM | J18: =J17 -> - | K18: =K17 -> 45229 | L18: 17 | M18: =IF('Submit here'!B36>0,'Submit here'!B36,"") -> NKL | N18: =IF('Submit here'!C36>0,'Submit here'!C36,"") -> 45226 | O18: =IF('Submit here'!D36>0,'Submit here'!D36,"") -> CAM2205A | P18: =IF('Submit here'!E36>0,'Submit here'!E36,"") | Q18: =IF('Submit here'!F36>0,'Submit here'!F36,"")
A19: D03 | B19: =B18 -> ARack0459 | C19: =C18 -> LVL600038005 | D19: LV3005887542 | E19: 25.5 | F19: high | I19: =I18 -> FM | J19: =J18 -> - | K19: =K18 -> 45229 | L19: 18 | M19: =IF('Submit here'!B37>0,'Submit here'!B37,"") -> NKL | N19: =IF('Submit here'!C37>0,'Submit here'!C37,"") -> 45226 | O19: =IF('Submit here'!D37>0,'Submit here'!D37,"") -> CAM2205A | P19: =IF('Submit here'!E37>0,'Submit here'!E37,"") | Q19: =IF('Submit here'!F37>0,'Submit here'!F37,"")
A20: A04 | B20: =B19 -> ARack0459 | C20: =C19 -> LVL600038005 | D20: LV3005887560 | E20: 27 | F20: high | I20: =I19 -> FM | J20: =J19 -> - | K20: =K19 -> 45229 | L20: 19 | M20: =IF('Submit here'!B38>0,'Submit here'!B38,"") -> NKL | N20: =IF('Submit here'!C38>0,'Submit here'!C38,"") -> 45226 | O20: =IF('Submit here'!D38>0,'Submit here'!D38,"") -> CAM2205A | P20: =IF('Submit here'!E38>0,'Submit here'!E38,"") | Q20: =IF('Submit here'!F38>0,'Submit here'!F38,"")
... A31: D06 | B31: =B30 -> ARack0459 | C31: =C30 -> LVL600038005 | D31: LV3005887557 | E31: 44.5 | F31: high | I31: =I30 -> FM | J31: =J30 -> - | K31: =K30 -> 45229 | L31: 30 | M31: =IF('Submit here'!B49>0,'Submit here'!B49,"") -> NKL | N31: =IF('Submit here'!C49>0,'Submit here'!C49,"") -> 45226 | O31: =IF('Submit here'!D49>0,'Submit here'!D49,"") -> CAM2205A | P31: =IF('Submit here'!E49>0,'Submit here'!E49,"") | Q31: =IF('Submit here'!F49>0,'Submit here'!F49,"")
A32: A01 | B32: ARack0460 | C32: LVL600038004 | D32: LV3005887515 | E32: 46 | F32: high | I32: =I31 -> FM | J32: =J31 -> - | K32: =K31 -> 45229 | L32: 31 | M32: =IF('Submit here'!B50>0,'Submit here'!B50,"") -> NKL | N32: =IF('Submit here'!C50>0,'Submit here'!C50,"") -> 45226 | O32: =IF('Submit here'!D50>0,'Submit here'!D50,"") -> CAM2205A | P32: =IF('Submit here'!E50>0,'Submit here'!E50,"") | Q32: =IF('Submit here'!F50>0,'Submit here'!F50,"")
A33: B01 | B33: =B32 -> ARack0460 | C33: =C32 -> LVL600038004 | D33: LV3005887523 | E33: 47.5 | F33: high | I33: =I32 -> FM | J33: =J32 -> - | K33: =K32 -> 45229 | L33: 32 | M33: =IF('Submit here'!B51>0,'Submit here'!B51,"") -> NKL | N33: =IF('Submit here'!C51>0,'Submit here'!C51,"") -> 45226 | O33: =IF('Submit here'!D51>0,'Submit here'!D51,"") -> CAM2205A | P33: =IF('Submit here'!E51>0,'Submit here'!E51,"") | Q33: =IF('Submit here'!F51>0,'Submit here'!F51,"")
A34: C01 | B34: =B33 -> ARack0460 | C34: =C33 -> LVL600038004 | D34: LV3005887529 | E34: 49 | F34: high | I34: =I33 -> FM | J34: =J33 -> - | K34: =K33 -> 45229 | L34: 33 | M34: =IF('Submit here'!B52>0,'Submit here'!B52,"") -> NKL | N34: =IF('Submit here'!C52>0,'Submit here'!C52,"") -> 45226 | O34: =IF('Submit here'!D52>0,'Submit here'!D52,"") -> CAM2205A | P34: =IF('Submit here'!E52>0,'Submit here'!E52,"") | Q34: =IF('Submit here'!F52>0,'Submit here'!F52,"")
A35: D01 | B35: =B34 -> ARack0460 | C35: =C34 -> LVL600038004 | D35: LV3005887535 | E35: 50.5 | F35: high | I35: =I34 -> FM | J35: =J34 -> - | K35: =K34 -> 45229 | L35: 34 | M35: =IF('Submit here'!B53>0,'Submit here'!B53,"") -> NKL | N35: =IF('Submit here'!C53>0,'Submit here'!C53,"") -> 45226 | O35: =IF('Submit here'!D53>0,'Submit here'!D53,"") -> CAM2205A | P35: =IF('Submit here'!E53>0,'Submit here'!E53,"") | Q35: =IF('Submit here'!F53>0,'Submit here'!F53,"")
A36: A02 | B36: =B35 -> ARack0460 | C36: =C35 -> LVL600038004 | D36: LV3005887534 | E36: 52 | F36: high | I36: =I35 -> FM | J36: =J35 -> - | K36: =K35 -> 45229 | L36: 35 | M36: =IF('Submit here'!B54>0,'Submit here'!B54,"") -> NKL | N36: =IF('Submit here'!C54>0,'Submit here'!C54,"") -> 45226 | O36: =IF('Submit here'!D54>0,'Submit here'!D54,"") -> CAM2205A | P36: =IF('Submit here'!E54>0,'Submit here'!E54,"") | Q36: =IF('Submit here'!F54>0,'Submit here'!F54,"")
A37: B02 | B37: =B36 -> ARack0460 | C37: =C36 -> LVL600038004 | D37: LV3005887514 | E37: 53.5 | F37: high | I37: =I36 -> FM | J37: =J36 -> - | K37: =K36 -> 45229 | L37: 36 | M37: =IF('Submit here'!B55>0,'Submit here'!B55,"") -> NKL | N37: =IF('Submit here'!C55>0,'Submit here'!C55,"") -> 45226 | O37: =IF('Submit here'!D55>0,'Submit here'!D55,"") -> CAM2205A | P37: =IF('Submit here'!E55>0,'Submit here'!E55,"") | Q37: =IF('Submit here'!F55>0,'Submit here'!F55,"")
A38: C02 | B38: =B37 -> ARack0460 | C38: =C37 -> LVL600038004 | D38: LV3005887528 | E38: 54.5 | F38: high | I38: =I37 -> FM | J38: =J37 -> - | K38: =K37 -> 45229 | L38: 37 | M38: =IF('Submit here'!B56>0,'Submit here'!B56,"") -> NKL | N38: =IF('Submit here'!C56>0,'Submit here'!C56,"") -> 45226 | O38: =IF('Submit here'!D56>0,'Submit here'!D56,"") -> CAM2205A | P38: =IF('Submit here'!E56>0,'Submit here'!E56,"") | Q38: =IF('Submit here'!F56>0,'Submit here'!F56,"")
A39: D02 | B39: =B38 -> ARack0460 | C39: =C38 -> LVL600038004 | D39: LV3005887522 | E39: 56 | F39: high | I39: =I38 -> FM | J39: =J38 -> - | K39: =K38 -> 45229 | L39: 38 | M39: =IF('Submit here'!B57>0,'Submit here'!B57,"") -> NKL | N39: =IF('Submit here'!C57>0,'Submit here'!C57,"") -> 45226 | O39: =IF('Submit here'!D57>0,'Submit here'!D57,"") -> CAM2205A | P39: =IF('Submit here'!E57>0,'Submit here'!E57,"") | Q39: =IF('Submit here'!F57>0,'Submit here'!F57,"")
A40: A03 | B40: =B39 -> ARack0460 | C40: =C39 -> LVL600038004 | D40: LV3005887513 | E40: 58 | F40: low | I40: =I39 -> FM | J40: =J39 -> - | K40: =K39 -> 45229 | L40: 39 | M40: =IF('Submit here'!B58>0,'Submit here'!B58,"") -> NKL | N40: =IF('Submit here'!C58>0,'Submit here'!C58,"") -> 45226 | O40: =IF('Submit here'!D58>0,'Submit here'!D58,"") -> CAM2205A | P40: =IF('Submit here'!E58>0,'Submit here'!E58,"") | Q40: =IF('Submit here'!F58>0,'Submit here'!F58,"")
A41: B03 | B41: =B40 -> ARack0460 | C41: =C40 -> LVL600038004 | D41: LV3005887521 | E41: 59.5 | F41: low | I41: =I40 -> FM | J41: =J40 -> - | K41: =K40 -> 45229 | L41: 40 | M41: =IF('Submit here'!B59>0,'Submit here'!B59,"") -> NKL | N41: =IF('Submit here'!C59>0,'Submit here'!C59,"") -> 45226 | O41: =IF('Submit here'!D59>0,'Submit here'!D59,"") -> CAM2205A | P41: =IF('Submit here'!E59>0,'Submit here'!E59,"") | Q41: =IF('Submit here'!F59>0,'Submit here'!F59,"")
A42: C03 | B42: =B41 -> ARack0460 | C42: =C41 -> LVL600038004 | D42: LV3005887527 | E42: 61 | F42: low | I42: =I41 -> FM | J42: =J41 -> - | K42: =K41 -> 45229 | L42: 41 | M42: =IF('Submit here'!B60>0,'Submit here'!B60,"") -> NKL | N42: =IF('Submit here'!C60>0,'Submit here'!C60,"") -> 45226 | O42: =IF('Submit here'!D60>0,'Submit here'!D60,"") -> CAM2205A | P42: =IF('Submit here'!E60>0,'Submit here'!E60,"") | Q42: =IF('Submit here'!F60>0,'Submit here'!F60,"")
A43: D03 | B43: =B42 -> ARack0460 | C43: =C42 -> LVL600038004 | D43: LV3005887533 | E43: 62 | F43: low | I43: =I42 -> FM | J43: =J42 -> - | K43: =K42 -> 45229 | L43: 42 | M43: =IF('Submit here'!B61>0,'Submit here'!B61,"") -> NKL | N43: =IF('Submit here'!C61>0,'Submit here'!C61,"") -> 45226 | O43: =IF('Submit here'!D61>0,'Submit here'!D61,"") -> CAM2205A | P43: =IF('Submit here'!E61>0,'Submit here'!E61,"") | Q43: =IF('Submit here'!F61>0,'Submit here'!F61,"")
A44: A04 | B44: =B43 -> ARack0460 | C44: =C43 -> LVL600038004 | D44: LV3005887520 | E44: 63.5 | F44: low | I44: =I43 -> FM | J44: =J43 -> - | K44: =K43 -> 45229 | L44: 43 | M44: =IF('Submit here'!B62>0,'Submit here'!B62,"") -> NKL | N44: =IF('Submit here'!C62>0,'Submit here'!C62,"") -> 45226 | O44: =IF('Submit here'!D62>0,'Submit here'!D62,"") -> CAM2205A | P44: =IF('Submit here'!E62>0,'Submit here'!E62,"") | Q44: =IF('Submit here'!F62>0,'Submit here'!F62,"")
... A55: D06 | B55: =B54 -> ARack0460 | C55: =C54 -> LVL600038004 | D55: LV3005887508 | E55: 80 | F55: low | I55: =I54 -> FM | J55: =J54 -> - | K55: =K54 -> 45229 | L55: 54 | M55: =IF('Submit here'!B73>0,'Submit here'!B73,"") -> NKL | N55: =IF('Submit here'!C73>0,'Submit here'!C73,"") -> 45226 | O55: =IF('Submit here'!D73>0,'Submit here'!D73,"") -> CAM2205A | P55: =IF('Submit here'!E73>0,'Submit here'!E73,"") | Q55: =IF('Submit here'!F73>0,'Submit here'!F73,"")
A56: A01 | B56: ARack0461 | C56: LVL600038029 | D56: LV3005888149 | E56: 81.5 | F56: low | I56: =I55 -> FM | J56: =J55 -> - | K56: =K55 -> 45229 | L56: 55 | M56: =IF('Submit here'!B74>0,'Submit here'!B74,"") -> NKL | N56: =IF('Submit here'!C74>0,'Submit here'!C74,"") -> 45226 | O56: =IF('Submit here'!D74>0,'Submit here'!D74,"") -> CAM2205A | P56: =IF('Submit here'!E74>0,'Submit here'!E74,"") | Q56: =IF('Submit here'!F74>0,'Submit here'!F74,"")
A57: B01 | B57: =B56 -> ARack0461 | C57: =C56 -> LVL600038029 | D57: LV3005888155 | E57: 83 | F57: low | I57: =I56 -> FM | J57: =J56 -> - | K57: =K56 -> 45229 | L57: 56 | M57: =IF('Submit here'!B75>0,'Submit here'!B75,"") -> NKL | N57: =IF('Submit here'!C75>0,'Submit here'!C75,"") -> 45226 | O57: =IF('Submit here'!D75>0,'Submit here'!D75,"") -> CAM2205A | P57: =IF('Submit here'!E75>0,'Submit here'!E75,"") | Q57: =IF('Submit here'!F75>0,'Submit here'!F75,"")
A58: C01 | B58: =B57 -> ARack0461 | C58: =C57 -> LVL600038029 | D58: LV3005888161 | E58: 85 | F58: low | I58: =I57 -> FM | J58: =J57 -> - | K58: =K57 -> 45229 | L58: 57 | M58: =IF('Submit here'!B76>0,'Submit here'!B76,"") -> NKL | N58: =IF('Submit here'!C76>0,'Submit here'!C76,"") -> 45226 | O58: =IF('Submit here'!D76>0,'Submit here'!D76,"") -> CAM2205A | P58: =IF('Submit here'!E76>0,'Submit here'!E76,"") | Q58: =IF('Submit here'!F76>0,'Submit here'!F76,"")
A59: D01 | B59: =B58 -> ARack0461 | C59: =C58 -> LVL600038029 | D59: LV3005888167 | E59: 86.5 | F59: low | I59: =I58 -> FM | J59: =J58 -> - | K59: =K58 -> 45229 | L59: 58 | M59: =IF('Submit here'!B77>0,'Submit here'!B77,"") -> NKL | N59: =IF('Submit here'!C77>0,'Submit here'!C77,"") -> 45226 | O59: =IF('Submit here'!D77>0,'Submit here'!D77,"") -> CAM2205A | P59: =IF('Submit here'!E77>0,'Submit here'!E77,"") | Q59: =IF('Submit here'!F77>0,'Submit here'!F77,"")
A60: A02 | B60: =B59 -> ARack0461 | C60: =C59 -> LVL600038029 | D60: LV3005888166 | E60: 88 | F60: low | I60: =I59 -> FM | J60: =J59 -> - | K60: =K59 -> 45229 | L60: 59 | M60: =IF('Submit here'!B78>0,'Submit here'!B78,"") -> NKL | N60: =IF('Submit here'!C78>0,'Submit here'!C78,"") -> 45226 | O60: =IF('Submit here'!D78>0,'Submit here'!D78,"") -> CAM2205A | P60: =IF('Submit here'!E78>0,'Submit here'!E78,"") | Q60: =IF('Submit here'!F78>0,'Submit here'!F78,"")
...

Sheet OutputForDB
A1: ArchiveSampleID | B1: PositionInRack | C1: RackName | D1: RackID | E1: BulkSampleID | F1: DepthSampledCalTape | G1: DepthOrderedCalTape | H1: OrganicContent | I1: SurfaceExposed | J1: RemarksArchiveSampling | K1: SampledBy1 | L1: SampledBy2 | M1: SamplingDate | N1: Submitter | O1: SubmissionDate | P1: NotesSubmitter
A2: =IF('For lab assistants'!#REF!>0,'For lab assistants'!#REF!,"") -> #REF! | B2: =IF('For lab assistants'!#REF!>0,'For lab assistants'!#REF!,"") -> #REF! | C2: =IF('For lab assistants'!#REF!>0,'For lab assistants'!#REF!,"") -> #REF! | D2: =IF('For lab assistants'!#REF!>0,'For lab assistants'!#REF!,"") -> #REF! | E2: =IF('For lab assistants'!#REF!>0,'For lab assistants'!#REF!,"") -> #REF! | F2: =IF('For lab assistants'!#REF!>0,'For lab assistants'!#REF!,"") -> #REF! | G2: =IF('For lab assistants'!#REF!>0,'For lab assistants'!#REF!,"") -> #REF! | H2: =IF('For lab assistants'!#REF!>0,'For lab assistants'!#REF!,"low") -> #REF! | I2: =IF('For lab assistants'!#REF!>0,'For lab assistants'!#REF!,"no") -> #REF! | J2: =IF('For lab assistants'!#REF!>0,'For lab assistants'!#REF!,"") -> #REF! | K2: =IF('For lab assistants'!#REF!>0,'For lab assistants'!#REF!,"") -> #REF! | L2: =IF('For lab assistants'!#REF!>0,'For lab assistants'!#REF!,"") -> #REF! | M2: =IF('For lab assistants'!#REF!>0,'For lab assistants'!#REF!,"") -> #REF! | N2: =IF('For lab assistants'!#REF!>0,'For lab assistants'!#REF!,"") -> #REF! | O2: =IF('For lab assistants'!#REF!>0,'For lab assistants'!#REF!,"") -> #REF! | P2: =IF(Output4SubSamplingSubmiss.!F2>0,Output4SubSamplingSubmiss.!F2,"") -> #REF!
A3: =IF('For lab assistants'!#REF!>0,'For lab assistants'!#REF!,"") -> #REF! | B3: =IF('For lab assistants'!#REF!>0,'For lab assistants'!#REF!,"") -> #REF! | C3: =IF('For lab assistants'!#REF!>0,'For lab assistants'!#REF!,"") -> #REF! | D3: =IF('For lab assistants'!#REF!>0,'For lab assistants'!#REF!,"") -> #REF! | E3: =IF('For lab assistants'!#REF!>0,'For lab assistants'!#REF!,"") -> #REF! | F3: =IF('For lab assistants'!#REF!>0,'For lab assistants'!#REF!,"") -> #REF! | G3: =IF('For lab assistants'!#REF!>0,'For lab assistants'!#REF!,"") -> #REF! | H3: =IF('For lab assistants'!#REF!>0,'For lab assistants'!#REF!,"low") -> #REF! | I3: =IF('For lab assistants'!#REF!>0,'For lab assistants'!#REF!,"no") -> #REF! | J3: =IF('For lab assistants'!#REF!>0,'For lab assistants'!#REF!,"") -> #REF! | K3: =IF('For lab assistants'!#REF!>0,'For lab assistants'!#REF!,"") -> #REF! | L3: =IF('For lab assistants'!#REF!>0,'For lab assistants'!#REF!,"") -> #REF! | M3: =IF('For lab assistants'!#REF!>0,'For lab assistants'!#REF!,"") -> #REF! | N3: =IF('For lab assistants'!#REF!>0,'For lab assistants'!#REF!,"") -> #REF! | O3: =IF('For lab assistants'!#REF!>0,'For lab assistants'!#REF!,"") -> #REF! | P3: =IF(Output4SubSamplingSubmiss.!F3>0,Output4SubSamplingSubmiss.!F3,"") -> #REF!
A4: =IF('For lab assistants'!#REF!>0,'For lab assistants'!#REF!,"") -> #REF! | B4: =IF('For lab assistants'!#REF!>0,'For lab assistants'!#REF!,"") -> #REF! | C4: =IF('For lab assistants'!#REF!>0,'For lab assistants'!#REF!,"") -> #REF! | D4: =IF('For lab assistants'!#REF!>0,'For lab assistants'!#REF!,"") -> #REF! | E4: =IF('For lab assistants'!#REF!>0,'For lab assistants'!#REF!,"") -> #REF! | F4: =IF('For lab assistants'!#REF!>0,'For lab assistants'!#REF!,"") -> #REF! | G4: =IF('For lab assistants'!#REF!>0,'For lab assistants'!#REF!,"") -> #REF! | H4: =IF('For lab assistants'!#REF!>0,'For lab assistants'!#REF!,"low") -> #REF! | I4: =IF('For lab assistants'!#REF!>0,'For lab assistants'!#REF!,"no") -> #REF! | J4: =IF('For lab assistants'!#REF!>0,'For lab assistants'!#REF!,"") -> #REF! | K4: =IF('For lab assistants'!#REF!>0,'For lab assistants'!#REF!,"") -> #REF! | L4: =IF('For lab assistants'!#REF!>0,'For lab assistants'!#REF!,"") -> #REF! | M4: =IF('For lab assistants'!#REF!>0,'For lab assistants'!#REF!,"") -> #REF! | N4: =IF('For lab assistants'!#REF!>0,'For lab assistants'!#REF!,"") -> #REF! | O4: =IF('For lab assistants'!#REF!>0,'For lab assistants'!#REF!,"") -> #REF! | P4: =IF(Output4SubSamplingSubmiss.!F4>0,Output4SubSamplingSubmiss.!F4,"") -> #REF!
A5: =IF('For lab assistants'!#REF!>0,'For lab assistants'!#REF!,"") -> #REF! | B5: =IF('For lab assistants'!#REF!>0,'For lab assistants'!#REF!,"") -> #REF! | C5: =IF('For lab assistants'!#REF!>0,'For lab assistants'!#REF!,"") -> #REF! | D5: =IF('For lab assistants'!#REF!>0,'For lab assistants'!#REF!,"") -> #REF! | E5: =IF('For lab assistants'!#REF!>0,'For lab assistants'!#REF!,"") -> #REF! | F5: =IF('For lab assistants'!#REF!>0,'For lab assistants'!#REF!,"") -> #REF! | G5: =IF('For lab assistants'!#REF!>0,'For lab assistants'!#REF!,"") -> #REF! | H5: =IF('For lab assistants'!#REF!>0,'For lab assistants'!#REF!,"low") -> #REF! | I5: =IF('For lab assistants'!#REF!>0,'For lab assistants'!#REF!,"no") -> #REF! | J5: =IF('For lab assistants'!#REF!>0,'For lab assistants'!#REF!,"") -> #REF! | K5: =IF('For lab assistants'!#REF!>0,'For lab assistants'!#REF!,"") -> #REF! | L5: =IF('For lab assistants'!#REF!>0,'For lab assistants'!#REF!,"") -> #REF! | M5: =IF('For lab assistants'!#REF!>0,'For lab assistants'!#REF!,"") -> #REF! | N5: =IF('For lab assistants'!#REF!>0,'For lab assistants'!#REF!,"") -> #REF! | O5: =IF('For lab assistants'!#REF!>0,'For lab assistants'!#REF!,"") -> #REF! | P5: =IF(Output4SubSamplingSubmiss.!F5>0,Output4SubSamplingSubmiss.!F5,"") -> #REF!
A6: =IF('For lab assistants'!#REF!>0,'For lab assistants'!#REF!,"") -> #REF! | B6: =IF('For lab assistants'!#REF!>0,'For lab assistants'!#REF!,"") -> #REF! | C6: =IF('For lab assistants'!#REF!>0,'For lab assistants'!#REF!,"") -> #REF! | D6: =IF('For lab assistants'!#REF!>0,'For lab assistants'!#REF!,"") -> #REF! | E6: =IF('For lab assistants'!#REF!>0,'For lab assistants'!#REF!,"") -> #REF! | F6: =IF('For lab assistants'!#REF!>0,'For lab assistants'!#REF!,"") -> #REF! | G6: =IF('For lab assistants'!#REF!>0,'For lab assistants'!#REF!,"") -> #REF! | H6: =IF('For lab assistants'!#REF!>0,'For lab assistants'!#REF!,"low") -> #REF! | I6: =IF('For lab assistants'!#REF!>0,'For lab assistants'!#REF!,"no") -> #REF! | J6: =IF('For lab assistants'!#REF!>0,'For lab assistants'!#REF!,"") -> #REF! | K6: =IF('For lab assistants'!#REF!>0,'For lab assistants'!#REF!,"") -> #REF! | L6: =IF('For lab assistants'!#REF!>0,'For lab assistants'!#REF!,"") -> #REF! | M6: =IF('For lab assistants'!#REF!>0,'For lab assistants'!#REF!,"") -> #REF! | N6: =IF('For lab assistants'!#REF!>0,'For lab assistants'!#REF!,"") -> #REF! | O6: =IF('For lab assistants'!#REF!>0,'For lab assistants'!#REF!,"") -> #REF! | P6: =IF(Output4SubSamplingSubmiss.!F6>0,Output4SubSamplingSubmiss.!F6,"") -> #REF!
A7: =IF('For lab assistants'!#REF!>0,'For lab assistants'!#REF!,"") -> #REF! | B7: =IF('For lab assistants'!#REF!>0,'For lab assistants'!#REF!,"") -> #REF! | C7: =IF('For lab assistants'!#REF!>0,'For lab assistants'!#REF!,"") -> #REF! | D7: =IF('For lab assistants'!#REF!>0,'For lab assistants'!#REF!,"") -> #REF! | E7: =IF('For lab assistants'!#REF!>0,'For lab assistants'!#REF!,"") -> #REF! | F7: =IF('For lab assistants'!#REF!>0,'For lab assistants'!#REF!,"") -> #REF! | G7: =IF('For lab assistants'!#REF!>0,'For lab assistants'!#REF!,"") -> #REF! | H7: =IF('For lab assistants'!#REF!>0,'For lab assistants'!#REF!,"low") -> #REF! | I7: =IF('For lab assistants'!#REF!>0,'For lab assistants'!#REF!,"no") -> #REF! | J7: =IF('For lab assistants'!#REF!>0,'For lab assistants'!#REF!,"") -> #REF! | K7: =IF('For lab assistants'!#REF!>0,'For lab assistants'!#REF!,"") -> #REF! | L7: =IF('For lab assistants'!#REF!>0,'For lab assistants'!#REF!,"") -> #REF! | M7: =IF('For lab assistants'!#REF!>0,'For lab assistants'!#REF!,"") -> #REF! | N7: =IF('For lab assistants'!#REF!>0,'For lab assistants'!#REF!,"") -> #REF! | O7: =IF('For lab assistants'!#REF!>0,'For lab assistants'!#REF!,"") -> #REF! | P7: =IF(Output4SubSamplingSubmiss.!F7>0,Output4SubSamplingSubmiss.!F7,"") -> #REF!
A8: =IF('For lab assistants'!#REF!>0,'For lab assistants'!#REF!,"") -> #REF! | B8: =IF('For lab assistants'!#REF!>0,'For lab assistants'!#REF!,"") -> #REF! | C8: =IF('For lab assistants'!#REF!>0,'For lab assistants'!#REF!,"") -> #REF! | D8: =IF('For lab assistants'!#REF!>0,'For lab assistants'!#REF!,"") -> #REF! | E8: =IF('For lab assistants'!#REF!>0,'For lab assistants'!#REF!,"") -> #REF! | F8: =IF('For lab assistants'!#REF!>0,'For lab assistants'!#REF!,"") -> #REF! | G8: =IF('For lab assistants'!#REF!>0,'For lab assistants'!#REF!,"") -> #REF! | H8: =IF('For lab assistants'!#REF!>0,'For lab assistants'!#REF!,"low") -> #REF! | I8: =IF('For lab assistants'!#REF!>0,'For lab assistants'!#REF!,"no") -> #REF! | J8: =IF('For lab assistants'!#REF!>0,'For lab assistants'!#REF!,"") -> #REF! | K8: =IF('For lab assistants'!#REF!>0,'For lab assistants'!#REF!,"") -> #REF! | L8: =IF('For lab assistants'!#REF!>0,'For lab assistants'!#REF!,"") -> #REF! | M8: =IF('For lab assistants'!#REF!>0,'For lab assistants'!#REF!,"") -> #REF! | N8: =IF('For lab assistants'!#REF!>0,'For lab assistants'!#REF!,"") -> #REF! | O8: =IF('For lab assistants'!#REF!>0,'For lab assistants'!#REF!,"") -> #REF! | P8: =IF(Output4SubSamplingSubmiss.!F8>0,Output4SubSamplingSubmiss.!F8,"") -> #REF!
A9: =IF('For lab assistants'!#REF!>0,'For lab assistants'!#REF!,"") -> #REF! | B9: =IF('For lab assistants'!#REF!>0,'For lab assistants'!#REF!,"") -> #REF! | C9: =IF('For lab assistants'!#REF!>0,'For lab assistants'!#REF!,"") -> #REF! | D9: =IF('For lab assistants'!#REF!>0,'For lab assistants'!#REF!,"") -> #REF! | E9: =IF('For lab assistants'!#REF!>0,'For lab assistants'!#REF!,"") -> #REF! | F9: =IF('For lab assistants'!#REF!>0,'For lab assistants'!#REF!,"") -> #REF! | G9: =IF('For lab assistants'!#REF!>0,'For lab assistants'!#REF!,"") -> #REF! | H9: =IF('For lab assistants'!#REF!>0,'For lab assistants'!#REF!,"low") -> #REF! | I9: =IF('For lab assistants'!#REF!>0,'For lab assistants'!#REF!,"no") -> #REF! | J9: =IF('For lab assistants'!#REF!>0,'For lab assistants'!#REF!,"") -> #REF! | K9: =IF('For lab assistants'!#REF!>0,'For lab assistants'!#REF!,"") -> #REF! | L9: =IF('For lab assistants'!#REF!>0,'For lab assistants'!#REF!,"") -> #REF! | M9: =IF('For lab assistants'!#REF!>0,'For lab assistants'!#REF!,"") -> #REF! | N9: =IF('For lab assistants'!#REF!>0,'For lab assistants'!#REF!,"") -> #REF! | O9: =IF('For lab assistants'!#REF!>0,'For lab assistants'!#REF!,"") -> #REF! | P9: =IF(Output4SubSamplingSubmiss.!F9>0,Output4SubSamplingSubmiss.!F9,"") -> #REF!
A10: =IF('For lab assistants'!#REF!>0,'For lab assistants'!#REF!,"") -> #REF! | B10: =IF('For lab assistants'!#REF!>0,'For lab assistants'!#REF!,"") -> #REF! | C10: =IF('For lab assistants'!#REF!>0,'For lab assistants'!#REF!,"") -> #REF! | D10: =IF('For lab assistants'!#REF!>0,'For lab assistants'!#REF!,"") -> #REF! | E10: =IF('For lab assistants'!#REF!>0,'For lab assistants'!#REF!,"") -> #REF! | F10: =IF('For lab assistants'!#REF!>0,'For lab assistants'!#REF!,"") -> #REF! | G10: =IF('For lab assistants'!#REF!>0,'For lab assistants'!#REF!,"") -> #REF! | H10: =IF('For lab assistants'!#REF!>0,'For lab assistants'!#REF!,"low") -> #REF! | I10: =IF('For lab assistants'!#REF!>0,'For lab assistants'!#REF!,"no") -> #REF! | J10: =IF('For lab assistants'!#REF!>0,'For lab assistants'!#REF!,"") -> #REF! | K10: =IF('For lab assistants'!#REF!>0,'For lab assistants'!#REF!,"") -> #REF! | L10: =IF('For lab assistants'!#REF!>0,'For lab assistants'!#REF!,"") -> #REF! | M10: =IF('For lab assistants'!#REF!>0,'For lab assistants'!#REF!,"") -> #REF! | N10: =IF('For lab assistants'!#REF!>0,'For lab assistants'!#REF!,"") -> #REF! | O10: =IF('For lab assistants'!#REF!>0,'For lab assistants'!#REF!,"") -> #REF! | P10: =IF(Output4SubSamplingSubmiss.!F10>0,Output4SubSamplingSubmiss.!F10,"") -> #REF!
A11: =IF('For lab assistants'!#REF!>0,'For lab assistants'!#REF!,"") -> #REF! | B11: =IF('For lab assistants'!#REF!>0,'For lab assistants'!#REF!,"") -> #REF! | C11: =IF('For lab assistants'!#REF!>0,'For lab assistants'!#REF!,"") -> #REF! | D11: =IF('For lab assistants'!#REF!>0,'For lab assistants'!#REF!,"") -> #REF! | E11: =IF('For lab assistants'!#REF!>0,'For lab assistants'!#REF!,"") -> #REF! | F11: =IF('For lab assistants'!#REF!>0,'For lab assistants'!#REF!,"") -> #REF! | G11: =IF('For lab assistants'!#REF!>0,'For lab assistants'!#REF!,"") -> #REF! | H11: =IF('For lab assistants'!#REF!>0,'For lab assistants'!#REF!,"low") -> #REF! | I11: =IF('For lab assistants'!#REF!>0,'For lab assistants'!#REF!,"no") -> #REF! | J11: =IF('For lab assistants'!#REF!>0,'For lab assistants'!#REF!,"") -> #REF! | K11: =IF('For lab assistants'!#REF!>0,'For lab assistants'!#REF!,"") -> #REF! | L11: =IF('For lab assistants'!#REF!>0,'For lab assistants'!#REF!,"") -> #REF! | M11: =IF('For lab assistants'!#REF!>0,'For lab assistants'!#REF!,"") -> #REF! | N11: =IF('For lab assistants'!#REF!>0,'For lab assistants'!#REF!,"") -> #REF! | O11: =IF('For lab assistants'!#REF!>0,'For lab assistants'!#REF!,"") -> #REF! | P11: =IF(Output4SubSamplingSubmiss.!F11>0,Output4SubSamplingSubmiss.!F11,"") -> #REF!
A12: =IF('For lab assistants'!#REF!>0,'For lab assistants'!#REF!,"") -> #REF! | B12: =IF('For lab assistants'!#REF!>0,'For lab assistants'!#REF!,"") -> #REF! | C12: =IF('For lab assistants'!#REF!>0,'For lab assistants'!#REF!,"") -> #REF! | D12: =IF('For lab assistants'!#REF!>0,'For lab assistants'!#REF!,"") -> #REF! | E12: =IF('For lab assistants'!#REF!>0,'For lab assistants'!#REF!,"") -> #REF! | F12: =IF('For lab assistants'!#REF!>0,'For lab assistants'!#REF!,"") -> #REF! | G12: =IF('For lab assistants'!#REF!>0,'For lab assistants'!#REF!,"") -> #REF! | H12: =IF('For lab assistants'!#REF!>0,'For lab assistants'!#REF!,"low") -> #REF! | I12: =IF('For lab assistants'!#REF!>0,'For lab assistants'!#REF!,"no") -> #REF! | J12: =IF('For lab assistants'!#REF!>0,'For lab assistants'!#REF!,"") -> #REF! | K12: =IF('For lab assistants'!#REF!>0,'For lab assistants'!#REF!,"") -> #REF! | L12: =IF('For lab assistants'!#REF!>0,'For lab assistants'!#REF!,"") -> #REF! | M12: =IF('For lab assistants'!#REF!>0,'For lab assistants'!#REF!,"") -> #REF! | N12: =IF('For lab assistants'!#REF!>0,'For lab assistants'!#REF!,"") -> #REF! | O12: =IF('For lab assistants'!#REF!>0,'For lab assistants'!#REF!,"") -> #REF! | P12: =IF(Output4SubSamplingSubmiss.!F12>0,Output4SubSamplingSubmiss.!F12,"") -> #REF!
A13: =IF('For lab assistants'!#REF!>0,'For lab assistants'!#REF!,"") -> #REF! | B13: =IF('For lab assistants'!#REF!>0,'For lab assistants'!#REF!,"") -> #REF! | C13: =IF('For lab assistants'!#REF!>0,'For lab assistants'!#REF!,"") -> #REF! | D13: =IF('For lab assistants'!#REF!>0,'For lab assistants'!#REF!,"") -> #REF! | E13: =IF('For lab assistants'!#REF!>0,'For lab assistants'!#REF!,"") -> #REF! | F13: =IF('For lab assistants'!#REF!>0,'For lab assistants'!#REF!,"") -> #REF! | G13: =IF('For lab assistants'!#REF!>0,'For lab assistants'!#REF!,"") -> #REF! | H13: =IF('For lab assistants'!#REF!>0,'For lab assistants'!#REF!,"low") -> #REF! | I13: =IF('For lab assistants'!#REF!>0,'For lab assistants'!#REF!,"no") -> #REF! | J13: =IF('For lab assistants'!#REF!>0,'For lab assistants'!#REF!,"") -> #REF! | K13: =IF('For lab assistants'!#REF!>0,'For lab assistants'!#REF!,"") -> #REF! | L13: =IF('For lab assistants'!#REF!>0,'For lab assistants'!#REF!,"") -> #REF! | M13: =IF('For lab assistants'!#REF!>0,'For lab assistants'!#REF!,"") -> #REF! | N13: =IF('For lab assistants'!#REF!>0,'For lab assistants'!#REF!,"") -> #REF! | O13: =IF('For lab assistants'!#REF!>0,'For lab assistants'!#REF!,"") -> #REF! | P13: =IF(Output4SubSamplingSubmiss.!F13>0,Output4SubSamplingSubmiss.!F13,"") -> #REF!
... A19: =IF('For lab assistants'!#REF!>0,'For lab assistants'!#REF!,"") -> #REF! | B19: =IF('For lab assistants'!#REF!>0,'For lab assistants'!#REF!,"") -> #REF! | C19: =IF('For lab assistants'!#REF!>0,'For lab assistants'!#REF!,"") -> #REF! | D19: =IF('For lab assistants'!#REF!>0,'For lab assistants'!#REF!,"") -> #REF! | E19: =IF('For lab assistants'!#REF!>0,'For lab assistants'!#REF!,"") -> #REF! | F19: =IF('For lab assistants'!#REF!>0,'For lab assistants'!#REF!,"") -> #REF! | G19: =IF('For lab assistants'!#REF!>0,'For lab assistants'!#REF!,"") -> #REF! | H19: =IF('For lab assistants'!#REF!>0,'For lab assistants'!#REF!,"low") -> #REF! | I19: =IF('For lab assistants'!#REF!>0,'For lab assistants'!#REF!,"no") -> #REF! | J19: =IF('For lab assistants'!#REF!>0,'For lab assistants'!#REF!,"") -> #REF! | K19: =IF('For lab assistants'!#REF!>0,'For lab assistants'!#REF!,"") -> #REF! | L19: =IF('For lab assistants'!#REF!>0,'For lab assistants'!#REF!,"") -> #REF! | M19: =IF('For lab assistants'!#REF!>0,'For lab assistants'!#REF!,"") -> #REF! | N19: =IF('For lab assistants'!#REF!>0,'For lab assistants'!#REF!,"") -> #REF! | O19: =IF('For lab assistants'!#REF!>0,'For lab assistants'!#REF!,"") -> #REF! | P19: =IF(Output4SubSamplingSubmiss.!F19>0,Output4SubSamplingSubmiss.!F19,"") -> #REF!
A20: =IF('For lab assistants'!D2>0,'For lab assistants'!D2,"") -> LV3005887701 | B20: =IF('For lab assistants'!D2>0,'For lab assistants'!A2,"") -> C05 | C20: =IF('For lab assistants'!B2>0,'For lab assistants'!B2,"") -> ARack0457 | D20: =IF('For lab assistants'!C2>0,'For lab assistants'!C2,"") -> LVL600038007 | E20: =IF('For lab assistants'!O2>0,'For lab assistants'!O2,"") -> CAM2205A | F20: =IF('For lab assistants'!E2>0,'For lab assistants'!E2,"") -> 0.5 | G20: =IF('For lab assistants'!P2>0,'For lab assistants'!P2,"") | H20: =IF('For lab assistants'!F2>0,'For lab assistants'!F2,"low") -> high | I20: =IF('For lab assistants'!G2>0,'For lab assistants'!G2,"no") -> no | J20: =IF('For lab assistants'!H2>0,'For lab assistants'!H2,"") | K20: =IF('For lab assistants'!I2>0,'For lab assistants'!I2,"") -> FM | L20: =IF('For lab assistants'!J2>0,'For lab assistants'!J2,"") -> - | M20: =IF('For lab assistants'!K2>0,'For lab assistants'!K2,"") -> 45229 | N20: =IF('For lab assistants'!D2>0,'For lab assistants'!M2,"") -> NKL | O20: =IF('For lab assistants'!D2>0,'For lab assistants'!N2,"") -> 45226 | P20: =IF(Output4SubSamplingSubmiss.!F20>0,Output4SubSamplingSubmiss.!F20,"")
A21: =IF('For lab assistants'!D3>0,'For lab assistants'!D3,"") -> LV3005887607 | B21: =IF('For lab assistants'!D3>0,'For lab assistants'!A3,"") -> D05 | C21: =IF('For lab assistants'!B3>0,'For lab assistants'!B3,"") -> ARack0457 | D21: =IF('For lab assistants'!C3>0,'For lab assistants'!C3,"") -> LVL600038007 | E21: =IF('For lab assistants'!O3>0,'For lab assistants'!O3,"") -> CAM2205A | F21: =IF('For lab assistants'!E3>0,'For lab assistants'!E3,"") -> 1.5 | G21: =IF('For lab assistants'!P3>0,'For lab assistants'!P3,"") | H21: =IF('For lab assistants'!F3>0,'For lab assistants'!F3,"low") -> high | I21: =IF('For lab assistants'!G3>0,'For lab assistants'!G3,"no") -> no | J21: =IF('For lab assistants'!H3>0,'For lab assistants'!H3,"") | K21: =IF('For lab assistants'!I3>0,'For lab assistants'!I3,"") -> FM | L21: =IF('For lab assistants'!J3>0,'For lab assistants'!J3,"") -> - | M21: =IF('For lab assistants'!K3>0,'For lab assistants'!K3,"") -> 45229 | N21: =IF('For lab assistants'!D3>0,'For lab assistants'!M3,"") -> NKL | O21: =IF('For lab assistants'!D3>0,'For lab assistants'!N3,"") -> 45226 | P21: =IF(Output4SubSamplingSubmiss.!F21>0,Output4SubSamplingSubmiss.!F21,"")
A22: =IF('For lab assistants'!D4>0,'For lab assistants'!D4,"") -> LV3005887608 | B22: =IF('For lab assistants'!D4>0,'For lab assistants'!A4,"") -> A06 | C22: =IF('For lab assistants'!B4>0,'For lab assistants'!B4,"") -> ARack0457 | D22: =IF('For lab assistants'!C4>0,'For lab assistants'!C4,"") -> LVL600038007 | E22: =IF('For lab assistants'!O4>0,'For lab assistants'!O4,"") -> CAM2205A | F22: =IF('For lab assistants'!E4>0,'For lab assistants'!E4,"") -> 3 | G22: =IF('For lab assistants'!P4>0,'For lab assistants'!P4,"") | H22: =IF('For lab assistants'!F4>0,'For lab assistants'!F4,"low") -> high | I22: =IF('For lab assistants'!G4>0,'For lab assistants'!G4,"no") -> no | J22: =IF('For lab assistants'!H4>0,'For lab assistants'!H4,"") | K22: =IF('For lab assistants'!I4>0,'For lab assistants'!I4,"") -> FM | L22: =IF('For lab assistants'!J4>0,'For lab assistants'!J4,"") -> - | M22: =IF('For lab assistants'!K4>0,'For lab assistants'!K4,"") -> 45229 | N22: =IF('For lab assistants'!D4>0,'For lab assistants'!M4,"") -> NKL | O22: =IF('For lab assistants'!D4>0,'For lab assistants'!N4,"") -> 45226 | P22: =IF(Output4SubSamplingSubmiss.!F22>0,Output4SubSamplingSubmiss.!F22,"")
