Workbook
Name piinfo: #REF!

Sheet ReadMe
B1: For submitter (i.e, PI or project leader):
A2: 1: | B2: Download this file and RENAME: | C2: "Ordering_eDNA_Archive_sampling_(YYMMDD_Initials_ProjectID).xlsx"
C3: eg. Ordering_eDNA_Archive_sampling_(230715_LVI_NileValley).xlsx
A4: 2: | B4: Fill out the [Submit here] tab column B,C,D (and optionally E).
A5: 3: | B5: Mail the renamed and completed ordering form (this file) to Jesper Stenderup; eDNA_orders@sund.ku.dk.
A6: 4: | B6: Make sure the core is clearly labelled and easily available for the lab assistants.

Sheet Submit here
A1: No | B1: Submitter (initials) | C1: Submission date (yyyy-mm-dd) | D1: Bulk or Core segment ID (eg. ISL23_019_02A or CGG3_xxxxxx) | E1: Calibration tape depth (cm) | F1: Notes from submitter (optional)
A2: 1 | B2: NKL | C2: 45226 | D2: Frederiksborg_Slotssø_kerne_3 | E2: Continuous
A3: 2 | B3: =B2 -> NKL | C3: =C2 -> 45226 | D3: Frederiksborg_Slotssø_kerne_3
A4: 3 | B4: =B3 -> NKL | C4: =C3 -> 45226 | D4: Frederiksborg_Slotssø_kerne_3
A5: 4 | B5: =B4 -> NKL | C5: =C4 -> 45226 | D5: Frederiksborg_Slotssø_kerne_3
A6: 5 | B6: =B5 -> NKL | C6: =C5 -> 45226 | D6: Frederiksborg_Slotssø_kerne_3
A7: 6 | B7: =B6 -> NKL | C7: =C6 -> 45226 | D7: Frederiksborg_Slotssø_kerne_3
A8: 7 | B8: =B7 -> NKL | C8: =C7 -> 45226 | D8: Frederiksborg_Slotssø_kerne_3
A9: 8 | B9: =B8 -> NKL | C9: =C8 -> 45226 | D9: Frederiksborg_Slotssø_kerne_3
A10: 9 | B10: =B9 -> NKL | C10: =C9 -> 45226 | D10: Frederiksborg_Slotssø_kerne_3
A11: 10 | B11: =B10 -> NKL | C11: =C10 -> 45226 | D11: Frederiksborg_Slotssø_kerne_3
A12: 11 | B12: =B11 -> NKL | C12: =C11 -> 45226 | D12: Frederiksborg_Slotssø_kerne_3
A13: 12 | B13: =B12 -> NKL | C13: =C12 -> 45226 | D13: Frederiksborg_Slotssø_kerne_3
A14: 13 | B14: =B13 -> NKL | C14: =C13 -> 45226 | D14: Frederiksborg_Slotssø_kerne_3
... A105: 104 | B105: =B104 -> NKL | C105: =C104 -> 45226 | D105: Frederiksborg_Slotssø_kerne_3
A106: 105 | B106: =B105 -> NKL | C106: =C105 -> 45226
A107: 106 | B107: =B106 -> NKL | C107: =C106 -> 45226
A108: 107 | B108: =B107 -> NKL | C108: =C107 -> 45226
A109: 108 | B109: =B108 -> NKL | C109: =C108 -> 45226
A110: 109 | B110: =B109 -> NKL | C110: =C109 -> 45226
A111: 110 | B111: =B110 -> NKL | C111: =C110 -> 45226
A112: 111 | B112: =B111 -> NKL | C112: =C111 -> 45226
A113: 112 | B113: =B112 -> NKL | C113: =C112 -> 45226
A114: 113 | B114: =B113 -> NKL | C114: =C113 -> 45226
A115: 114 | B115: =B114 -> NKL | C115: =C114 -> 45226
A116: 115 | B116: =B115 -> NKL | C116: =C115 -> 45226
A117: 116 | B117: =B116 -> NKL | C117: =C116 -> 45226
... A673: 672 | B673: =B672 -> NKL | C673: =C672 -> 45226

Sheet Output4SubSamplingSubmiss.
A1: ='For lab assistants'!O1 -> Core segment ID (fx ISL23_019_02A) | B1: ='For lab assistants'!A1 -> Archive rack position | C1: ='For lab assistants'!B1 -> Archive RACK name (eg. ARack0052) | D1: ='For lab assistants'!C1 -> Archive RACK barcode | E1: ='For lab assistants'!D1 -> Archive TUBE barcode | F1: ='For lab assistants'!Q1 -> Notes from submitter (optional)
A2: =IF('For lab assistants'!O2>0,'For lab assistants'!O2,"") -> Frederiksborg_Slotssø_kerne_3 | B2: =IF('For lab assistants'!D2>0,'For lab assistants'!A2,"") -> B04 | C2: =IF('For lab assistants'!B2>0,'For lab assistants'!B2,"") -> ARack0467 | D2: =IF('For lab assistants'!C2>0,'For lab assistants'!C2,"") -> LVL600038037 | E2: =IF('For lab assistants'!D2>0,'For lab assistants'!D2,"") -> LV3005888353 | F2: =IF('For lab assistants'!Q2>0,'For lab assistants'!Q2,"")
A3: =IF('For lab assistants'!O3>0,'For lab assistants'!O3,"") -> Frederiksborg_Slotssø_kerne_3 | B3: =IF('For lab assistants'!D3>0,'For lab assistants'!A3,"") -> C04 | C3: =IF('For lab assistants'!B3>0,'For lab assistants'!B3,"") -> ARack0467 | D3: =IF('For lab assistants'!C3>0,'For lab assistants'!C3,"") -> LVL600038037 | E3: =IF('For lab assistants'!D3>0,'For lab assistants'!D3,"") -> LV3005888456 | F3: =IF('For lab assistants'!Q3>0,'For lab assistants'!Q3,"")
A4: =IF('For lab assistants'!O4>0,'For lab assistants'!O4,"") -> Frederiksborg_Slotssø_kerne_3 | B4: =IF('For lab assistants'!D4>0,'For lab assistants'!A4,"") -> D04 | C4: =IF('For lab assistants'!B4>0,'For lab assistants'!B4,"") -> ARack0467 | D4: =IF('For lab assistants'!C4>0,'For lab assistants'!C4,"") -> LVL600038037 | E4: =IF('For lab assistants'!D4>0,'For lab assistants'!D4,"") -> LV3005888363 | F4: =IF('For lab assistants'!Q4>0,'For lab assistants'!Q4,"")
A5: =IF('For lab assistants'!O5>0,'For lab assistants'!O5,"") -> Frederiksborg_Slotssø_kerne_3 | B5: =IF('For lab assistants'!D5>0,'For lab assistants'!A5,"") -> A05 | C5: =IF('For lab assistants'!B5>0,'For lab assistants'!B5,"") -> ARack0467 | D5: =IF('For lab assistants'!C5>0,'For lab assistants'!C5,"") -> LVL600038037 | E5: =IF('For lab assistants'!D5>0,'For lab assistants'!D5,"") -> LV3005888369 | F5: =IF('For lab assistants'!Q5>0,'For lab assistants'!Q5,"")
A6: =IF('For lab assistants'!O6>0,'For lab assistants'!O6,"") -> Frederiksborg_Slotssø_kerne_3 | B6: =IF('For lab assistants'!D6>0,'For lab assistants'!A6,"") -> B05 | C6: =IF('For lab assistants'!B6>0,'For lab assistants'!B6,"") -> ARack0467 | D6: =IF('For lab assistants'!C6>0,'For lab assistants'!C6,"") -> LVL600038037 | E6: =IF('For lab assistants'!D6>0,'For lab assistants'!D6,"") -> LV3005888352 | F6: =IF('For lab assistants'!Q6>0,'For lab assistants'!Q6,"")
A7: =IF('For lab assistants'!O7>0,'For lab assistants'!O7,"") -> Frederiksborg_Slotssø_kerne_3 | B7: =IF('For lab assistants'!D7>0,'For lab assistants'!A7,"") -> C05 | C7: =IF('For lab assistants'!B7>0,'For lab assistants'!B7,"") -> ARack0467 | D7: =IF('For lab assistants'!C7>0,'For lab assistants'!C7,"") -> LVL600038037 | E7: =IF('For lab assistants'!D7>0,'For lab assistants'!D7,"") -> LV3005888145 | F7: =IF('For lab assistants'!Q7>0,'For lab assistants'!Q7,"")
A8: =IF('For lab assistants'!O8>0,'For lab assistants'!O8,"") -> Frederiksborg_Slotssø_kerne_3 | B8: =IF('For lab assistants'!D8>0,'For lab assistants'!A8,"") -> D05 | C8: =IF('For lab assistants'!B8>0,'For lab assistants'!B8,"") -> ARack0467 | D8: =IF('For lab assistants'!C8>0,'For lab assistants'!C8,"") -> LVL600038037 | E8: =IF('For lab assistants'!D8>0,'For lab assistants'!D8,"") -> LV3005888038 | F8: =IF('For lab assistants'!Q8>0,'For lab assistants'!Q8,"")
A9: =IF('For lab assistants'!O9>0,'For lab assistants'!O9,"") -> Frederiksborg_Slotssø_kerne_3 | B9: =IF('For lab assistants'!D9>0,'For lab assistants'!A9,"") -> A06 | C9: =IF('For lab assistants'!B9>0,'For lab assistants'!B9,"") -> ARack0467 | D9: =IF('For lab assistants'!C9>0,'For lab assistants'!C9,"") -> LVL600038037 | E9: =IF('For lab assistants'!D9>0,'For lab assistants'!D9,"") -> LV3005888110 | F9: =IF('For lab assistants'!Q9>0,'For lab assistants'!Q9,"")
A10: =IF('For lab assistants'!O10>0,'For lab assistants'!O10,"") -> Frederiksborg_Slotssø_kerne_3 | B10: =IF('For lab assistants'!D10>0,'For lab assistants'!A10,"") -> B06 | C10: =IF('For lab assistants'!B10>0,'For lab assistants'!B10,"") -> ARack0467 | D10: =IF('For lab assistants'!C10>0,'For lab assistants'!C10,"") -> LVL600038037 | E10: =IF('For lab assistants'!D10>0,'For lab assistants'!D10,"") -> LV3005889419 | F10: =IF('For lab assistants'!Q10>0,'For lab assistants'!Q10,"")
A11: =IF('For lab assistants'!O11>0,'For lab assistants'!O11,"") -> Frederiksborg_Slotssø_kerne_3 | B11: =IF('For lab assistants'!D11>0,'For lab assistants'!A11,"") -> C06 | C11: =IF('For lab assistants'!B11>0,'For lab assistants'!B11,"") -> ARack0467 | D11: =IF('For lab assistants'!C11>0,'For lab assistants'!C11,"") -> LVL600038037 | E11: =IF('For lab assistants'!D11>0,'For lab assistants'!D11,"") -> LV3005888162 | F11: =IF('For lab assistants'!Q11>0,'For lab assistants'!Q11,"")
A12: =IF('For lab assistants'!O12>0,'For lab assistants'!O12,"") -> Frederiksborg_Slotssø_kerne_3 | B12: =IF('For lab assistants'!D12>0,'For lab assistants'!A12,"") -> D06 | C12: =IF('For lab assistants'!B12>0,'For lab assistants'!B12,"") -> ARack0467 | D12: =IF('For lab assistants'!C12>0,'For lab assistants'!C12,"") -> LVL600038037 | E12: =IF('For lab assistants'!D12>0,'For lab assistants'!D12,"") -> LV3005887708 | F12: =IF('For lab assistants'!Q12>0,'For lab assistants'!Q12,"")
A13: =IF('For lab assistants'!O13>0,'For lab assistants'!O13,"") -> Frederiksborg_Slotssø_kerne_3 | B13: =IF('For lab assistants'!D13>0,'For lab assistants'!A13,"") -> A01 | C13: =IF('For lab assistants'!B13>0,'For lab assistants'!B13,"") -> ARack0475 | D13: =IF('For lab assistants'!C13>0,'For lab assistants'!C13,"") -> LVL600038051 | E13: =IF('For lab assistants'!D13>0,'For lab assistants'!D13,"") -> LV3005888727 | F13: =IF('For lab assistants'!Q13>0,'For lab assistants'!Q13,"")
... A60: =IF('For lab assistants'!O60>0,'For lab assistants'!O60,"") -> Frederiksborg_Slotssø_kerne_3 | B60: =IF('For lab assistants'!D60>0,'For lab assistants'!A60,"") -> D06 | C60: =IF('For lab assistants'!B60>0,'For lab assistants'!B60,"") -> ARack0476 | D60: =IF('For lab assistants'!C60>0,'For lab assistants'!C60,"") -> LVL600052415 | E60: =IF('For lab assistants'!D60>0,'For lab assistants'!D60,"") -> LV3006009501 | F60: =IF('For lab assistants'!Q60>0,'For lab assistants'!Q60,"")
A61: =IF('For lab assistants'!O61>0,'For lab assistants'!O61,"") -> Frederiksborg_Slotssø_kerne_3 | B61: =IF('For lab assistants'!D61>0,'For lab assistants'!A61,"") -> A01 | C61: =IF('For lab assistants'!B61>0,'For lab assistants'!B61,"") -> ARack0477 | D61: =IF('For lab assistants'!#REF!>0,'For lab assistants'!#REF!,"") -> #REF! | E61: =IF('For lab assistants'!D61>0,'For lab assistants'!D61,"") -> LV3006009476 | F61: =IF('For lab assistants'!Q61>0,'For lab assistants'!Q61,"")
A62: =IF('For lab assistants'!O62>0,'For lab assistants'!O62,"") -> Frederiksborg_Slotssø_kerne_3 | B62: =IF('For lab assistants'!D62>0,'For lab assistants'!A62,"") -> B01 | C62: =IF('For lab assistants'!B62>0,'For lab assistants'!B62,"") -> ARack0477 | D62: =IF('For lab assistants'!C61>0,'For lab assistants'!C61,"") -> LVL600052414 | E62: =IF('For lab assistants'!D62>0,'For lab assistants'!D62,"") -> LV3006009482 | F62: =IF('For lab assistants'!Q62>0,'For lab assistants'!Q62,"")
A63: =IF('For lab assistants'!O63>0,'For lab assistants'!O63,"") -> Frederiksborg_Slotssø_kerne_3 | B63: =IF('For lab assistants'!D63>0,'For lab assistants'!A63,"") -> C01 | C63: =IF('For lab assistants'!B63>0,'For lab assistants'!B63,"") -> ARack0477 | D63: =IF('For lab assistants'!C62>0,'For lab assistants'!C62,"") -> LVL600052414 | E63: =IF('For lab assistants'!D63>0,'For lab assistants'!D63,"") -> LV3006009489 | F63: =IF('For lab assistants'!Q63>0,'For lab assistants'!Q63,"")
A64: =IF('For lab assistants'!O64>0,'For lab assistants'!O64,"") -> Frederiksborg_Slotssø_kerne_3 | B64: =IF('For lab assistants'!D64>0,'For lab assistants'!A64,"") -> D01 | C64: =IF('For lab assistants'!B64>0,'For lab assistants'!B64,"") -> ARack0477 | D64: =IF('For lab assistants'!C64>0,'For lab assistants'!C64,"") -> LVL600052414 | E64: =IF('For lab assistants'!D64>0,'For lab assistants'!D64,"") -> LV3006009496 | F64: =IF('For lab assistants'!Q64>0,'For lab assistants'!Q64,"")
A65: =IF('For lab assistants'!O65>0,'For lab assistants'!O65,"") -> Frederiksborg_Slotssø_kerne_3 | B65: =IF('For lab assistants'!D65>0,'For lab assistants'!A65,"") -> A02 | C65: =IF('For lab assistants'!B65>0,'For lab assistants'!B65,"") -> ARack0477 | D65: =IF('For lab assistants'!C65>0,'For lab assistants'!C65,"") -> LVL600052414 | E65: =IF('For lab assistants'!D65>0,'For lab assistants'!D65,"") -> LV3006009481 | F65: =IF('For lab assistants'!Q65>0,'For lab assistants'!Q65,"")
A66: =IF('For lab assistants'!O66>0,'For lab assistants'!O66,"") -> Frederiksborg_Slotssø_kerne_3 | B66: =IF('For lab assistants'!D66>0,'For lab assistants'!A66,"") -> B02 | C66: =IF('For lab assistants'!B66>0,'For lab assistants'!B66,"") -> ARack0477 | D66: =IF('For lab assistants'!C66>0,'For lab assistants'!C66,"") -> LVL600052414 | E66: =IF('For lab assistants'!D66>0,'For lab assistants'!D66,"") -> LV3006009475 | F66: =IF('For lab assistants'!Q66>0,'For lab assistants'!Q66,"")
A67: =IF('For lab assistants'!O67>0,'For lab assistants'!O67,"") -> Frederiksborg_Slotssø_kerne_3 | B67: =IF('For lab assistants'!D67>0,'For lab assistants'!A67,"") -> C02 | C67: =IF('For lab assistants'!B67>0,'For lab assistants'!B67,"") -> ARack0477 | D67: =IF('For lab assistants'!C67>0,'For lab assistants'!C67,"") -> LVL600052414 | E67: =IF('For lab assistants'!D67>0,'For lab assistants'!D67,"") -> LV3006009488 | F67: =IF('For lab assistants'!Q67>0,'For lab assistants'!Q67,"")
A68: =IF('For lab assistants'!O68>0,'For lab assistants'!O68,"") -> Frederiksborg_Slotssø_kerne_3 | B68: =IF('For lab assistants'!D68>0,'For lab assistants'!A68,"") -> D02 | C68: =IF('For lab assistants'!B68>0,'For lab assistants'!B68,"") -> ARack0477 | D68: =IF('For lab assistants'!C68>0,'For lab assistants'!C68,"") -> LVL600052414 | E68: =IF('For lab assistants'!D68>0,'For lab assistants'!D68,"") -> LV3006009495 | F68: =IF('For lab assistants'!Q68>0,'For lab assistants'!Q68,"")
A69: =IF('For lab assistants'!O69>0,'For lab assistants'!O69,"") -> Frederiksborg_Slotssø_kerne_3 | B69: =IF('For lab assistants'!D69>0,'For lab assistants'!A69,"") -> A03 | C69: =IF('For lab assistants'!B69>0,'For lab assistants'!B69,"") -> ARack0477 | D69: =IF('For lab assistants'!C69>0,'For lab assistants'!C69,"") -> LVL600052414 | E69: =IF('For lab assistants'!D69>0,'For lab assistants'!D69,"") -> LV3006009480 | F69: =IF('For lab assistants'!Q69>0,'For lab assistants'!Q69,"")
A70: =IF('For lab assistants'!O70>0,'For lab assistants'!O70,"") -> Frederiksborg_Slotssø_kerne_3 | B70: =IF('For lab assistants'!D70>0,'For lab assistants'!A70,"") -> B03 | C70: =IF('For lab assistants'!B70>0,'For lab assistants'!B70,"") -> ARack0477 | D70: =IF('For lab assistants'!C70>0,'For lab assistants'!C70,"") -> LVL600052414 | E70: =IF('For lab assistants'!D70>0,'For lab assistants'!D70,"") -> LV3006009487 | F70: =IF('For lab assistants'!Q70>0,'For lab assistants'!Q70,"")
A71: =IF('For lab assistants'!O71>0,'For lab assistants'!O71,"") -> Frederiksborg_Slotssø_kerne_3 | B71: =IF('For lab assistants'!D71>0,'For lab assistants'!A71,"") -> C03 | C71: =IF('For lab assistants'!B71>0,'For lab assistants'!B71,"") -> ARack0477 | D71: =IF('For lab assistants'!C71>0,'For lab assistants'!C71,"") -> LVL600052414 | E71: =IF('For lab assistants'!D71>0,'For lab assistants'!D71,"") -> LV3006009494 | F71: =IF('For lab assistants'!Q71>0,'For lab assistants'!Q71,"")
A72: =IF('For lab assistants'!O72>0,'For lab assistants'!O72,"") -> Frederiksborg_Slotssø_kerne_3 | B72: =IF('For lab assistants'!D72>0,'For lab assistants'!A72,"") -> D03 | C72: =IF('For lab assistants'!B72>0,'For lab assistants'!B72,"") -> ARack0477 | D72: =IF('For lab assistants'!C72>0,'For lab assistants'!C72,"") -> LVL600052414 | E72: =IF('For lab assistants'!D72>0,'For lab assistants'!D72,"") -> LV3006009473 | F72: =IF('For lab assistants'!Q72>0,'For lab assistants'!Q72,"")
A73: =IF('For lab assistants'!O73>0,'For lab assistants'!O73,"") -> Frederiksborg_Slotssø_kerne_3 | B73: =IF('For lab assistants'!D73>0,'For lab assistants'!A73,"") -> A04 | C73: =IF('For lab assistants'!B73>0,'For lab assistants'!B73,"") -> ARack0477 | D73: =IF('For lab assistants'!C73>0,'For lab assistants'!C73,"") -> LVL600052414 | E73: =IF('For lab assistants'!D73>0,'For lab assistants'!D73,"") -> LV3006009479 | F73: =IF('For lab assistants'!Q73>0,'For lab assistants'!Q73,"")
A74: =IF('For lab assistants'!O74>0,'For lab assistants'!O74,"") -> Frederiksborg_Slotssø_kerne_3 | B74: =IF('For lab assistants'!D74>0,'For lab assistants'!A74,"") -> B04 | C74: =IF('For lab assistants'!B74>0,'For lab assistants'!B74,"") -> ARack0477 | D74: =IF('For lab assistants'!C74>0,'For lab assistants'!C74,"") -> LVL600052414 | E74: =IF('For lab assistants'!D74>0,'For lab assistants'!D74,"") -> LV3006009492 | F74: =IF('For lab assistants'!Q74>0,'For lab assistants'!Q74,"")
A75: =IF('For lab assistants'!O75>0,'For lab assistants'!O75,"") -> Frederiksborg_Slotssø_kerne_3 | B75: =IF('For lab assistants'!D75>0,'For lab assistants'!A75,"") -> C04 | C75: =IF('For lab assistants'!B75>0,'For lab assistants'!B75,"") -> ARack0477 | D75: =IF('For lab assistants'!C75>0,'For lab assistants'!C75,"") -> LVL600052414 | E75: =IF('For lab assistants'!D75>0,'For lab assistants'!D75,"") -> LV3006009486 | F75: =IF('For lab assistants'!Q75>0,'For lab assistants'!Q75,"")
... A672: =IF('For lab assistants'!O672>0,'For lab assistants'!O672,"") | B672: =IF('For lab assistants'!D672>0,'For lab assistants'!A672,"") | C672: =IF('For lab assistants'!B672>0,'For lab assistants'!B672,"") | D672: =IF('For lab assistants'!C672>0,'For lab assistants'!C672,"") | E672: =IF('For lab assistants'!D672>0,'For lab assistants'!D672,"") | F672: =IF('For lab assistants'!Q672>0,'For lab assistants'!Q672,"")

Sheet For lab assistants
A1: Archive rack position | B1: Archive RACK name (eg. ARack0052) | C1: Archive RACK barcode | D1: Archive TUBE barcode | E1: Depth sampled (tape, cm) | F1: Organic content (High /Low) | G1: Surface exposed? (ie Back wall hit?) (Yes / No) | H1: Remarks from sampling (optional) | I1: Sampled by 1 (initials) | J1: Sampled by 2 (initials) | K1: Sampled date (yyyy-mm-dd) | L1: No | M1: Submitter (initials) | N1: Submission date (yyyy-mm-dd) | O1: Core segment ID (fx ISL23_019_02A) | P1: Ordered depth (Calibration tape, cm) | Q1: Notes from submitter (optional)
A2: B04 | B2: ARack0467 | C2: LVL600038037 | D2: LV3005888353 | E2: 0.5 | I2: FM | J2: VSS | K2: 45241 | L2: 1 | M2: =IF('Submit here'!B2>0,'Submit here'!B2,"") -> NKL | N2: =IF('Submit here'!C2>0,'Submit here'!C2,"") -> 45226 | O2: =IF('Submit here'!D2>0,'Submit here'!D2,"") -> Frederiksborg_Slotssø_kerne_3 | P2: =IF('Submit here'!E2>0,'Submit here'!E2,"") -> Continuous | Q2: =IF('Submit here'!F2>0,'Submit here'!F2,"")
A3: C04 | B3: ARack0467 | C3: LVL600038037 | D3: LV3005888456 | E3: 2 | I3: =I2 -> FM | J3: =J2 -> VSS | K3: =K2 -> 45241 | L3: 2 | M3: =IF('Submit here'!B3>0,'Submit here'!B3,"") -> NKL | N3: =IF('Submit here'!C3>0,'Submit here'!C3,"") -> 45226 | O3: =IF('Submit here'!D3>0,'Submit here'!D3,"") -> Frederiksborg_Slotssø_kerne_3 | P3: =IF('Submit here'!E3>0,'Submit here'!E3,"") | Q3: =IF('Submit here'!F3>0,'Submit here'!F3,"")
A4: D04 | B4: ARack0467 | C4: LVL600038037 | D4: LV3005888363 | E4: 3.5 | I4: =I3 -> FM | J4: =J3 -> VSS | K4: =K3 -> 45241 | L4: 3 | M4: =IF('Submit here'!B4>0,'Submit here'!B4,"") -> NKL | N4: =IF('Submit here'!C4>0,'Submit here'!C4,"") -> 45226 | O4: =IF('Submit here'!D4>0,'Submit here'!D4,"") -> Frederiksborg_Slotssø_kerne_3 | P4: =IF('Submit here'!E4>0,'Submit here'!E4,"") | Q4: =IF('Submit here'!F4>0,'Submit here'!F4,"")
A5: A05 | B5: ARack0467 | C5: LVL600038037 | D5: LV3005888369 | E5: 5 | I5: =I4 -> FM | J5: =J4 -> VSS | K5: =K4 -> 45241 | L5: 4 | M5: =IF('Submit here'!B5>0,'Submit here'!B5,"") -> NKL | N5: =IF('Submit here'!C5>0,'Submit here'!C5,"") -> 45226 | O5: =IF('Submit here'!D5>0,'Submit here'!D5,"") -> Frederiksborg_Slotssø_kerne_3 | P5: =IF('Submit here'!E5>0,'Submit here'!E5,"") | Q5: =IF('Submit here'!F5>0,'Submit here'!F5,"")
A6: B05 | B6: ARack0467 | C6: LVL600038037 | D6: LV3005888352 | E6: 6.5 | I6: =I5 -> FM | J6: =J5 -> VSS | K6: =K5 -> 45241 | L6: 5 | M6: =IF('Submit here'!B6>0,'Submit here'!B6,"") -> NKL | N6: =IF('Submit here'!C6>0,'Submit here'!C6,"") -> 45226 | O6: =IF('Submit here'!D6>0,'Submit here'!D6,"") -> Frederiksborg_Slotssø_kerne_3 | P6: =IF('Submit here'!E6>0,'Submit here'!E6,"") | Q6: =IF('Submit here'!F6>0,'Submit here'!F6,"")
A7: C05 | B7: ARack0467 | C7: LVL600038037 | D7: LV3005888145 | E7: 8.5 | I7: =I6 -> FM | J7: =J6 -> VSS | K7: =K6 -> 45241 | L7: 6 | M7: =IF('Submit here'!B7>0,'Submit here'!B7,"") -> NKL | N7: =IF('Submit here'!C7>0,'Submit here'!C7,"") -> 45226 | O7: =IF('Submit here'!D7>0,'Submit here'!D7,"") -> Frederiksborg_Slotssø_kerne_3 | P7: =IF('Submit here'!E7>0,'Submit here'!E7,"") | Q7: =IF('Submit here'!F7>0,'Submit here'!F7,"")
A8: D05 | B8: ARack0467 | C8: LVL600038037 | D8: LV3005888038 | E8: 10 | I8: =I7 -> FM | J8: =J7 -> VSS | K8: =K7 -> 45241 | L8: 7 | M8: =IF('Submit here'!B8>0,'Submit here'!B8,"") -> NKL | N8: =IF('Submit here'!C8>0,'Submit here'!C8,"") -> 45226 | O8: =IF('Submit here'!D8>0,'Submit here'!D8,"") -> Frederiksborg_Slotssø_kerne_3 | P8: =IF('Submit here'!E8>0,'Submit here'!E8,"") | Q8: =IF('Submit here'!F8>0,'Submit here'!F8,"")
A9: A06 | B9: ARack0467 | C9: LVL600038037 | D9: LV3005888110 | E9: 11.5 | I9: =I8 -> FM | J9: =J8 -> VSS | K9: =K8 -> 45241 | L9: 8 | M9: =IF('Submit here'!B9>0,'Submit here'!B9,"") -> NKL | N9: =IF('Submit here'!C9>0,'Submit here'!C9,"") -> 45226 | O9: =IF('Submit here'!D9>0,'Submit here'!D9,"") -> Frederiksborg_Slotssø_kerne_3 | P9: =IF('Submit here'!E9>0,'Submit here'!E9,"") | Q9: =IF('Submit here'!F9>0,'Submit here'!F9,"")
A10: B06 | B10: ARack0467 | C10: LVL600038037 | D10: LV3005889419 | E10: 13 | I10: =I9 -> FM | J10: =J9 -> VSS | K10: =K9 -> 45241 | L10: 9 | M10: =IF('Submit here'!B10>0,'Submit here'!B10,"") -> NKL | N10: =IF('Submit here'!C10>0,'Submit here'!C10,"") -> 45226 | O10: =IF('Submit here'!D10>0,'Submit here'!D10,"") -> Frederiksborg_Slotssø_kerne_3 | P10: =IF('Submit here'!E10>0,'Submit here'!E10,"") | Q10: =IF('Submit here'!F10>0,'Submit here'!F10,"")
A11: C06 | B11: ARack0467 | C11: LVL600038037 | D11: LV3005888162 | E11: 14.5 | I11: =I10 -> FM | J11: =J10 -> VSS | K11: =K10 -> 45241 | L11: 10 | M11: =IF('Submit here'!B11>0,'Submit here'!B11,"") -> NKL | N11: =IF('Submit here'!C11>0,'Submit here'!C11,"") -> 45226 | O11: =IF('Submit here'!D11>0,'Submit here'!D11,"") -> Frederiksborg_Slotssø_kerne_3 | P11: =IF('Submit here'!E11>0,'Submit here'!E11,"") | Q11: =IF('Submit here'!F11>0,'Submit here'!F11,"")
A12: D06 | B12: ARack0467 | C12: LVL600038037 | D12: LV3005887708 | E12: 16 | I12: =I11 -> FM | J12: =J11 -> VSS | K12: =K11 -> 45241 | L12: 11 | M12: =IF('Submit here'!B12>0,'Submit here'!B12,"") -> NKL | N12: =IF('Submit here'!C12>0,'Submit here'!C12,"") -> 45226 | O12: =IF('Submit here'!D12>0,'Submit here'!D12,"") -> Frederiksborg_Slotssø_kerne_3 | P12: =IF('Submit here'!E12>0,'Submit here'!E12,"") | Q12: =IF('Submit here'!F12>0,'Submit here'!F12,"")
A13: A01 | B13: ARack0475 | C13: LVL600038051 | D13: LV3005888727 | E13: 18 | I13: =I12 -> FM | J13: =J12 -> VSS | K13: =K12 -> 45241 | L13: 12 | M13: =IF('Submit here'!B13>0,'Submit here'!B13,"") -> NKL | N13: =IF('Submit here'!C13>0,'Submit here'!C13,"") -> 45226 | O13: =IF('Submit here'!D13>0,'Submit here'!D13,"") -> Frederiksborg_Slotssø_kerne_3 | P13: =IF('Submit here'!E13>0,'Submit here'!E13,"") | Q13: =IF('Submit here'!F13>0,'Submit here'!F13,"")
A14: B01 | B14: ARack0475 | C14: LVL600038051 | D14: LV3005888709 | E14: 19.5 | I14: =I13 -> FM | J14: =J13 -> VSS | K14: =K13 -> 45241 | L14: 13 | M14: =IF('Submit here'!B14>0,'Submit here'!B14,"") -> NKL | N14: =IF('Submit here'!C14>0,'Submit here'!C14,"") -> 45226 | O14: =IF('Submit here'!D14>0,'Submit here'!D14,"") -> Frederiksborg_Slotssø_kerne_3 | P14: =IF('Submit here'!E14>0,'Submit here'!E14,"") | Q14: =IF('Submit here'!F14>0,'Submit here'!F14,"")
... A104: D05 | B104: ARack0478 | C104: LVL600052413 | D104: LV3006009446 | E104: 159.5 | I104: =I103 -> FM | J104: =J103 -> VSS | K104: =K103 -> 45241 | L104: 103 | M104: =IF('Submit here'!B104>0,'Submit here'!B104,"") -> NKL | N104: =IF('Submit here'!C104>0,'Submit here'!C104,"") -> 45226 | O104: =IF('Submit here'!D104>0,'Submit here'!D104,"") -> Frederiksborg_Slotssø_kerne_3 | P104: =IF('Submit here'!E104>0,'Submit here'!E104,"") | Q104: =IF('Submit here'!F104>0,'Submit here'!F104,"")
A105: A06 | I105: =I104 -> FM | J105: =J104 -> VSS | K105: =K104 -> 45241 | L105: 104 | M105: =IF('Submit here'!B105>0,'Submit here'!B105,"") -> NKL | N105: =IF('Submit here'!C105>0,'Submit here'!C105,"") -> 45226 | O105: =IF('Submit here'!D105>0,'Submit here'!D105,"") -> Frederiksborg_Slotssø_kerne_3 | P105: =IF('Submit here'!E105>0,'Submit here'!E105,"") | Q105: =IF('Submit here'!F105>0,'Submit here'!F105,"")
A106: B06 | I106: =I105 -> FM | J106: =J105 -> VSS | K106: =K105 -> 45241 | L106: 105 | M106: =IF('Submit here'!B106>0,'Submit here'!B106,"") -> NKL | N106: =IF('Submit here'!C106>0,'Submit here'!C106,"") -> 45226 | O106: =IF('Submit here'!D106>0,'Submit here'!D106,"") | P106: =IF('Submit here'!E106>0,'Submit here'!E106,"") | Q106: =IF('Submit here'!F106>0,'Submit here'!F106,"")
A107: C06 | I107: =I106 -> FM | J107: =J106 -> VSS | K107: =K106 -> 45241 | L107: 106 | M107: =IF('Submit here'!B107>0,'Submit here'!B107,"") -> NKL | N107: =IF('Submit here'!C107>0,'Submit here'!C107,"") -> 45226 | O107: =IF('Submit here'!D107>0,'Submit here'!D107,"") | P107: =IF('Submit here'!E107>0,'Submit here'!E107,"") | Q107: =IF('Submit here'!F107>0,'Submit here'!F107,"")
A108: D06 | I108: =I107 -> FM | J108: =J107 -> VSS | K108: =K107 -> 45241 | L108: 107 | M108: =IF('Submit here'!B108>0,'Submit here'!B108,"") -> NKL | N108: =IF('Submit here'!C108>0,'Submit here'!C108,"") -> 45226 | O108: =IF('Submit here'!D108>0,'Submit here'!D108,"") | P108: =IF('Submit here'!E108>0,'Submit here'!E108,"") | Q108: =IF('Submit here'!F108>0,'Submit here'!F108,"")
A109: A01 | I109: =I108 -> FM | J109: =J108 -> VSS | K109: =K108 -> 45241 | L109: 108 | M109: =IF('Submit here'!B109>0,'Submit here'!B109,"") -> NKL | N109: =IF('Submit here'!C109>0,'Submit here'!C109,"") -> 45226 | O109: =IF('Submit here'!D109>0,'Submit here'!D109,"") | P109: =IF('Submit here'!E109>0,'Submit here'!E109,"") | Q109: =IF('Submit here'!F109>0,'Submit here'!F109,"")
A110: B01 | I110: =I109 -> FM | J110: =J109 -> VSS | K110: =K109 -> 45241 | L110: 109 | M110: =IF('Submit here'!B110>0,'Submit here'!B110,"") -> NKL | N110: =IF('Submit here'!C110>0,'Submit here'!C110,"") -> 45226 | O110: =IF('Submit here'!D110>0,'Submit here'!D110,"") | P110: =IF('Submit here'!E110>0,'Submit here'!E110,"") | Q110: =IF('Submit here'!F110>0,'Submit here'!F110,"")
A111: C01 | I111: =I110 -> FM | J111: =J110 -> VSS | K111: =K110 -> 45241 | L111: 110 | M111: =IF('Submit here'!B111>0,'Submit here'!B111,"") -> NKL | N111: =IF('Submit here'!C111>0,'Submit here'!C111,"") -> 45226 | O111: =IF('Submit here'!D111>0,'Submit here'!D111,"") | P111: =IF('Submit here'!E111>0,'Submit here'!E111,"") | Q111: =IF('Submit here'!F111>0,'Submit here'!F111,"")
A112: D01 | I112: =I111 -> FM | J112: =J111 -> VSS | K112: =K111 -> 45241 | L112: 111 | M112: =IF('Submit here'!B112>0,'Submit here'!B112,"") -> NKL | N112: =IF('Submit here'!C112>0,'Submit here'!C112,"") -> 45226 | O112: =IF('Submit here'!D112>0,'Submit here'!D112,"") | P112: =IF('Submit here'!E112>0,'Submit here'!E112,"") | Q112: =IF('Submit here'!F112>0,'Submit here'!F112,"")
A113: A02 | I113: =I112 -> FM | J113: =J112 -> VSS | K113: =K112 -> 45241 | L113: 112 | M113: =IF('Submit here'!B113>0,'Submit here'!B113,"") -> NKL | N113: =IF('Submit here'!C113>0,'Submit here'!C113,"") -> 45226 | O113: =IF('Submit here'!D113>0,'Submit here'!D113,"") | P113: =IF('Submit here'!E113>0,'Submit here'!E113,"") | Q113: =IF('Submit here'!F113>0,'Submit here'!F113,"")
A114: B02 | I114: =I113 -> FM | J114: =J113 -> VSS | K114: =K113 -> 45241 | L114: 113 | M114: =IF('Submit here'!B114>0,'Submit here'!B114,"") -> NKL | N114: =IF('Submit here'!C114>0,'Submit here'!C114,"") -> 45226 | O114: =IF('Submit here'!D114>0,'Submit here'!D114,"") | P114: =IF('Submit here'!E114>0,'Submit here'!E114,"") | Q114: =IF('Submit here'!F114>0,'Submit here'!F114,"")
A115: C02 | I115: =I114 -> FM | J115: =J114 -> VSS | K115: =K114 -> 45241 | L115: 114 | M115: =IF('Submit here'!B115>0,'Submit here'!B115,"") -> NKL | N115: =IF('Submit here'!C115>0,'Submit here'!C115,"") -> 45226 | O115: =IF('Submit here'!D115>0,'Submit here'!D115,"") | P115: =IF('Submit here'!E115>0,'Submit here'!E115,"") | Q115: =IF('Submit here'!F115>0,'Submit here'!F115,"")
A116: D02 | I116: =I115 -> FM | J116: =J115 -> VSS | K116: =K115 -> 45241 | L116: 115 | M116: =IF('Submit here'!B116>0,'Submit here'!B116,"") -> NKL | N116: =IF('Submit here'!C116>0,'Submit here'!C116,"") -> 45226 | O116: =IF('Submit here'!D116>0,'Submit here'!D116,"") | P116: =IF('Submit here'!E116>0,'Submit here'!E116,"") | Q116: =IF('Submit here'!F116>0,'Submit here'!F116,"")
... A146: A01 | I146: =I145 -> FM | J146: =J145 -> VSS | K146: =K145 -> 45241 | L146: 145 | M146: =IF('Submit here'!B146>0,'Submit here'!B146,"") -> NKL | N146: =IF('Submit here'!C146>0,'Submit here'!C146,"") -> 45226 | O146: =IF('Submit here'!D146>0,'Submit here'!D146,"") | P146: =IF('Submit here'!E146>0,'Submit here'!E146,"") | Q146: =IF('Submit here'!F146>0,'Submit here'!F146,"")
A147: B01 | B147: =B146 -> 0 | C147: =C146 -> 0 | I147: =I146 -> FM | J147: =J146 -> VSS | K147: =K146 -> 45241 | L147: 146 | M147: =IF('Submit here'!B147>0,'Submit here'!B147,"") -> NKL | N147: =IF('Submit here'!C147>0,'Submit here'!C147,"") -> 45226 | O147: =IF('Submit here'!D147>0,'Submit here'!D147,"") | P147: =IF('Submit here'!E147>0,'Submit here'!E147,"") | Q147: =IF('Submit here'!F147>0,'Submit here'!F147,"")
A148: C01 | B148: =B147 -> 0 | C148: =C147 -> 0 | I148: =I147 -> FM | J148: =J147 -> VSS | K148: =K147 -> 45241 | L148: 147 | M148: =IF('Submit here'!B148>0,'Submit here'!B148,"") -> NKL | N148: =IF('Submit here'!C148>0,'Submit here'!C148,"") -> 45226 | O148: =IF('Submit here'!D148>0,'Submit here'!D148,"") | P148: =IF('Submit here'!E148>0,'Submit here'!E148,"") | Q148: =IF('Submit here'!F148>0,'Submit here'!F148,"")
A149: D01 | B149: =B148 -> 0 | C149: =C148 -> 0 | I149: =I148 -> FM | J149: =J148 -> VSS | K149: =K148 -> 45241 | L149: 148 | M149: =IF('Submit here'!B149>0,'Submit here'!B149,"") -> NKL | N149: =IF('Submit here'!C149>0,'Submit here'!C149,"") -> 45226 | O149: =IF('Submit here'!D149>0,'Submit here'!D149,"") | P149: =IF('Submit here'!E149>0,'Submit here'!E149,"") | Q149: =IF('Submit here'!F149>0,'Submit here'!F149,"")
A150: A02 | B150: =B149 -> 0 | C150: =C149 -> 0 | I150: =I149 -> FM | J150: =J149 -> VSS | K150: =K149 -> 45241 | L150: 149 | M150: =IF('Submit here'!B150>0,'Submit here'!B150,"") -> NKL | N150: =IF('Submit here'!C150>0,'Submit here'!C150,"") -> 45226 | O150: =IF('Submit here'!D150>0,'Submit here'!D150,"") | P150: =IF('Submit here'!E150>0,'Submit here'!E150,"") | Q150: =IF('Submit here'!F150>0,'Submit here'!F150,"")
A151: B02 | B151: =B150 -> 0 | C151: =C150 -> 0 | I151: =I150 -> FM | J151: =J150 -> VSS | K151: =K150 -> 45241 | L151: 150 | M151: =IF('Submit here'!B151>0,'Submit here'!B151,"") -> NKL | N151: =IF('Submit here'!C151>0,'Submit here'!C151,"") -> 45226 | O151: =IF('Submit here'!D151>0,'Submit here'!D151,"") | P151: =IF('Submit here'!E151>0,'Submit here'!E151,"") | Q151: =IF('Submit here'!F151>0,'Submit here'!F151,"")
A152: C02 | B152: =B151 -> 0 | C152: =C151 -> 0 | I152: =I151 -> FM | J152: =J151 -> VSS | K152: =K151 -> 45241 | L152: 151 | M152: =IF('Submit here'!B152>0,'Submit here'!B152,"") -> NKL | N152: =IF('Submit here'!C152>0,'Submit here'!C152,"") -> 45226 | O152: =IF('Submit here'!D152>0,'Submit here'!D152,"") | P152: =IF('Submit here'!E152>0,'Submit here'!E152,"") | Q152: =IF('Submit here'!F152>0,'Submit here'!F152,"")
A153: D02 | B153: =B152 -> 0 | C153: =C152 -> 0 | I153: =I152 -> FM | J153: =J152 -> VSS | K153: =K152 -> 45241 | L153: 152 | M153: =IF('Submit here'!B153>0,'Submit here'!B153,"") -> NKL | N153: =IF('Submit here'!C153>0,'Submit here'!C153,"") -> 45226 | O153: =IF('Submit here'!D153>0,'Submit here'!D153,"") | P153: =IF('Submit here'!E153>0,'Submit here'!E153,"") | Q153: =IF('Submit here'!F153>0,'Submit here'!F153,"")
A154: A03 | B154: =B153 -> 0 | C154: =C153 -> 0 | I154: =I153 -> FM | J154: =J153 -> VSS | K154: =K153 -> 45241 | L154: 153 | M154: =IF('Submit here'!B154>0,'Submit here'!B154,"") -> NKL | N154: =IF('Submit here'!C154>0,'Submit here'!C154,"") -> 45226 | O154: =IF('Submit here'!D154>0,'Submit here'!D154,"") | P154: =IF('Submit here'!E154>0,'Submit here'!E154,"") | Q154: =IF('Submit here'!F154>0,'Submit here'!F154,"")
A155: B03 | B155: =B154 -> 0 | C155: =C154 -> 0 | I155: =I154 -> FM | J155: =J154 -> VSS | K155: =K154 -> 45241 | L155: 154 | M155: =IF('Submit here'!B155>0,'Submit here'!B155,"") -> NKL | N155: =IF('Submit here'!C155>0,'Submit here'!C155,"") -> 45226 | O155: =IF('Submit here'!D155>0,'Submit here'!D155,"") | P155: =IF('Submit here'!E155>0,'Submit here'!E155,"") | Q155: =IF('Submit here'!F155>0,'Submit here'!F155,"")
A156: C03 | B156: =B155 -> 0 | C156: =C155 -> 0 | I156: =I155 -> FM | J156: =J155 -> VSS | K156: =K155 -> 45241 | L156: 155 | M156: =IF('Submit here'!B156>0,'Submit here'!B156,"") -> NKL | N156: =IF('Submit here'!C156>0,'Submit here'!C156,"") -> 45226 | O156: =IF('Submit here'!D156>0,'Submit here'!D156,"") | P156: =IF('Submit here'!E156>0,'Submit here'!E156,"") | Q156: =IF('Submit here'!F156>0,'Submit here'!F156,"")
A157: D03 | B157: =B156 -> 0 | C157: =C156 -> 0 | I157: =I156 -> FM | J157: =J156 -> VSS | K157: =K156 -> 45241 | L157: 156 | M157: =IF('Submit here'!B157>0,'Submit here'!B157,"") -> NKL | N157: =IF('Submit here'!C157>0,'Submit here'!C157,"") -> 45226 | O157: =IF('Submit here'!D157>0,'Submit here'!D157,"") | P157: =IF('Submit here'!E157>0,'Submit here'!E157,"") | Q157: =IF('Submit here'!F157>0,'Submit here'!F157,"")
A158: A04 | B158: =B157 -> 0 | C158: =C157 -> 0 | I158: =I157 -> FM | J158: =J157 -> VSS | K158: =K157 -> 45241 | L158: 157 | M158: =IF('Submit here'!B158>0,'Submit here'!B158,"") -> NKL | N158: =IF('Submit here'!C158>0,'Submit here'!C158,"") -> 45226 | O158: =IF('Submit here'!D158>0,'Submit here'!D158,"") | P158: =IF('Submit here'!E158>0,'Submit here'!E158,"") | Q158: =IF('Submit here'!F158>0,'Submit here'!F158,"")
...

Sheet OutputForDB
A1: ArchiveSampleID | B1: PositionInRack | C1: RackName | D1: RackID | E1: BulkSampleID | F1: DepthSampledCalTape | G1: DepthOrderedCalTape | H1: OrganicContent | I1: SurfaceExposed | J1: RemarksArchiveSampling | K1: SampledBy1 | L1: SampledBy2 | M1: SamplingDate | N1: Submitter | O1: SubmissionDate | P1: NotesSubmitter
A2: =IF('For lab assistants'!D2>0,'For lab assistants'!D2,"") -> LV3005888353 | B2: =IF('For lab assistants'!D2>0,'For lab assistants'!A2,"") -> B04 | C2: =IF('For lab assistants'!B2>0,'For lab assistants'!B2,"") -> ARack0467 | D2: =IF('For lab assistants'!C2>0,'For lab assistants'!C2,"") -> LVL600038037 | E2: =IF('For lab assistants'!O2>0,'For lab assistants'!O2,"") -> Frederiksborg_Slotssø_kerne_3 | F2: =IF('For lab assistants'!E2>0,'For lab assistants'!E2,"") -> 0.5 | G2: =IF('For lab assistants'!P2>0,'For lab assistants'!P2,"") -> Continuous | H2: =IF('For lab assistants'!F2>0,'For lab assistants'!F2,"low") -> low | I2: =IF('For lab assistants'!G2>0,'For lab assistants'!G2,"no") -> no | J2: =IF('For lab assistants'!H2>0,'For lab assistants'!H2,"") | K2: =IF('For lab assistants'!I2>0,'For lab assistants'!I2,"") -> FM | L2: =IF('For lab assistants'!J2>0,'For lab assistants'!J2,"") -> VSS | M2: =IF('For lab assistants'!K2>0,'For lab assistants'!K2,"") -> 45241 | N2: =IF('For lab assistants'!D2>0,'For lab assistants'!M2,"") -> NKL | O2: =IF('For lab assistants'!D2>0,'For lab assistants'!N2,"") -> 45226 | P2: =IF(Output4SubSamplingSubmiss.!F2>0,Output4SubSamplingSubmiss.!F2,"")
A3: =IF('For lab assistants'!D3>0,'For lab assistants'!D3,"") -> LV3005888456 | B3: =IF('For lab assistants'!D3>0,'For lab assistants'!A3,"") -> C04 | C3: =IF('For lab assistants'!B3>0,'For lab assistants'!B3,"") -> ARack0467 | D3: =IF('For lab assistants'!C3>0,'For lab assistants'!C3,"") -> LVL600038037 | E3: =IF('For lab assistants'!O3>0,'For lab assistants'!O3,"") -> Frederiksborg_Slotssø_kerne_3 | F3: =IF('For lab assistants'!E3>0,'For lab assistants'!E3,"") -> 2 | G3: =IF('For lab assistants'!P3>0,'For lab assistants'!P3,"") | H3: =IF('For lab assistants'!F3>0,'For lab assistants'!F3,"low") -> low | I3: =IF('For lab assistants'!G3>0,'For lab assistants'!G3,"no") -> no | J3: =IF('For lab assistants'!H3>0,'For lab assistants'!H3,"") | K3: =IF('For lab assistants'!I3>0,'For lab assistants'!I3,"") -> FM | L3: =IF('For lab assistants'!J3>0,'For lab assistants'!J3,"") -> VSS | M3: =IF('For lab assistants'!K3>0,'For lab assistants'!K3,"") -> 45241 | N3: =IF('For lab assistants'!D3>0,'For lab assistants'!M3,"") -> NKL | O3: =IF('For lab assistants'!D3>0,'For lab assistants'!N3,"") -> 45226 | P3: =IF(Output4SubSamplingSubmiss.!F3>0,Output4SubSamplingSubmiss.!F3,"")
A4: =IF('For lab assistants'!D4>0,'For lab assistants'!D4,"") -> LV3005888363 | B4: =IF('For lab assistants'!D4>0,'For lab assistants'!A4,"") -> D04 | C4: =IF('For lab assistants'!B4>0,'For lab assistants'!B4,"") -> ARack0467 | D4: =IF('For lab assistants'!C4>0,'For lab assistants'!C4,"") -> LVL600038037 | E4: =IF('For lab assistants'!O4>0,'For lab assistants'!O4,"") -> Frederiksborg_Slotssø_kerne_3 | F4: =IF('For lab assistants'!E4>0,'For lab assistants'!E4,"") -> 3.5 | G4: =IF('For lab assistants'!P4>0,'For lab assistants'!P4,"") | H4: =IF('For lab assistants'!F4>0,'For lab assistants'!F4,"low") -> low | I4: =IF('For lab assistants'!G4>0,'For lab assistants'!G4,"no") -> no | J4: =IF('For lab assistants'!H4>0,'For lab assistants'!H4,"") | K4: =IF('For lab assistants'!I4>0,'For lab assistants'!I4,"") -> FM | L4: =IF('For lab assistants'!J4>0,'For lab assistants'!J4,"") -> VSS | M4: =IF('For lab assistants'!K4>0,'For lab assistants'!K4,"") -> 45241 | N4: =IF('For lab assistants'!D4>0,'For lab assistants'!M4,"") -> NKL | O4: =IF('For lab assistants'!D4>0,'For lab assistants'!N4,"") -> 45226 | P4: =IF(Output4SubSamplingSubmiss.!F4>0,Output4SubSamplingSubmiss.!F4,"")
A5: =IF('For lab assistants'!D5>0,'For lab assistants'!D5,"") -> LV3005888369 | B5: =IF('For lab assistants'!D5>0,'For lab assistants'!A5,"") -> A05 | C5: =IF('For lab assistants'!B5>0,'For lab assistants'!B5,"") -> ARack0467 | D5: =IF('For lab assistants'!C5>0,'For lab assistants'!C5,"") -> LVL600038037 | E5: =IF('For lab assistants'!O5>0,'For lab assistants'!O5,"") -> Frederiksborg_Slotssø_kerne_3 | F5: =IF('For lab assistants'!E5>0,'For lab assistants'!E5,"") -> 5 | G5: =IF('For lab assistants'!P5>0,'For lab assistants'!P5,"") | H5: =IF('For lab assistants'!F5>0,'For lab assistants'!F5,"low") -> low | I5: =IF('For lab assistants'!G5>0,'For lab assistants'!G5,"no") -> no | J5: =IF('For lab assistants'!H5>0,'For lab assistants'!H5,"") | K5: =IF('For lab assistants'!I5>0,'For lab assistants'!I5,"") -> FM | L5: =IF('For lab assistants'!J5>0,'For lab assistants'!J5,"") -> VSS | M5: =IF('For lab assistants'!K5>0,'For lab assistants'!K5,"") -> 45241 | N5: =IF('For lab assistants'!D5>0,'For lab assistants'!M5,"") -> NKL | O5: =IF('For lab assistants'!D5>0,'For lab assistants'!N5,"") -> 45226 | P5: =IF(Output4SubSamplingSubmiss.!F5>0,Output4SubSamplingSubmiss.!F5,"")
A6: =IF('For lab assistants'!D6>0,'For lab assistants'!D6,"") -> LV3005888352 | B6: =IF('For lab assistants'!D6>0,'For lab assistants'!A6,"") -> B05 | C6: =IF('For lab assistants'!B6>0,'For lab assistants'!B6,"") -> ARack0467 | D6: =IF('For lab assistants'!C6>0,'For lab assistants'!C6,"") -> LVL600038037 | E6: =IF('For lab assistants'!O6>0,'For lab assistants'!O6,"") -> Frederiksborg_Slotssø_kerne_3 | F6: =IF('For lab assistants'!E6>0,'For lab assistants'!E6,"") -> 6.5 | G6: =IF('For lab assistants'!P6>0,'For lab assistants'!P6,"") | H6: =IF('For lab assistants'!F6>0,'For lab assistants'!F6,"low") -> low | I6: =IF('For lab assistants'!G6>0,'For lab assistants'!G6,"no") -> no | J6: =IF('For lab assistants'!H6>0,'For lab assistants'!H6,"") | K6: =IF('For lab assistants'!I6>0,'For lab assistants'!I6,"") -> FM | L6: =IF('For lab assistants'!J6>0,'For lab assistants'!J6,"") -> VSS | M6: =IF('For lab assistants'!K6>0,'For lab assistants'!K6,"") -> 45241 | N6: =IF('For lab assistants'!D6>0,'For lab assistants'!M6,"") -> NKL | O6: =IF('For lab assistants'!D6>0,'For lab assistants'!N6,"") -> 45226 | P6: =IF(Output4SubSamplingSubmiss.!F6>0,Output4SubSamplingSubmiss.!F6,"")
A7: =IF('For lab assistants'!D7>0,'For lab assistants'!D7,"") -> LV3005888145 | B7: =IF('For lab assistants'!D7>0,'For lab assistants'!A7,"") -> C05 | C7: =IF('For lab assistants'!B7>0,'For lab assistants'!B7,"") -> ARack0467 | D7: =IF('For lab assistants'!C7>0,'For lab assistants'!C7,"") -> LVL600038037 | E7: =IF('For lab assistants'!O7>0,'For lab assistants'!O7,"") -> Frederiksborg_Slotssø_kerne_3 | F7: =IF('For lab assistants'!E7>0,'For lab assistants'!E7,"") -> 8.5 | G7: =IF('For lab assistants'!P7>0,'For lab assistants'!P7,"") | H7: =IF('For lab assistants'!F7>0,'For lab assistants'!F7,"low") -> low | I7: =IF('For lab assistants'!G7>0,'For lab assistants'!G7,"no") -> no | J7: =IF('For lab assistants'!H7>0,'For lab assistants'!H7,"") | K7: =IF('For lab assistants'!I7>0,'For lab assistants'!I7,"") -> FM | L7: =IF('For lab assistants'!J7>0,'For lab assistants'!J7,"") -> VSS | M7: =IF('For lab assistants'!K7>0,'For lab assistants'!K7,"") -> 45241 | N7: =IF('For lab assistants'!D7>0,'For lab assistants'!M7,"") -> NKL | O7: =IF('For lab assistants'!D7>0,'For lab assistants'!N7,"") -> 45226 | P7: =IF(Output4SubSamplingSubmiss.!F7>0,Output4SubSamplingSubmiss.!F7,"")
A8: =IF('For lab assistants'!D8>0,'For lab assistants'!D8,"") -> LV3005888038 | B8: =IF('For lab assistants'!D8>0,'For lab assistants'!A8,"") -> D05 | C8: =IF('For lab assistants'!B8>0,'For lab assistants'!B8,"") -> ARack0467 | D8: =IF('For lab assistants'!C8>0,'For lab assistants'!C8,"") -> LVL600038037 | E8: =IF('For lab assistants'!O8>0,'For lab assistants'!O8,"") -> Frederiksborg_Slotssø_kerne_3 | F8: =IF('For lab assistants'!E8>0,'For lab assistants'!E8,"") -> 10 | G8: =IF('For lab assistants'!P8>0,'For lab assistants'!P8,"") | H8: =IF('For lab assistants'!F8>0,'For lab assistants'!F8,"low") -> low | I8: =IF('For lab assistants'!G8>0,'For lab assistants'!G8,"no") -> no | J8: =IF('For lab assistants'!H8>0,'For lab assistants'!H8,"") | K8: =IF('For lab assistants'!I8>0,'For lab assistants'!I8,"") -> FM | L8: =IF('For lab assistants'!J8>0,'For lab assistants'!J8,"") -> VSS | M8: =IF('For lab assistants'!K8>0,'For lab assistants'!K8,"") -> 45241 | N8: =IF('For lab assistants'!D8>0,'For lab assistants'!M8,"") -> NKL | O8: =IF('For lab assistants'!D8>0,'For lab assistants'!N8,"") -> 45226 | P8: =IF(Output4SubSamplingSubmiss.!F8>0,Output4SubSamplingSubmiss.!F8,"")
A9: =IF('For lab assistants'!D9>0,'For lab assistants'!D9,"") -> LV3005888110 | B9: =IF('For lab assistants'!D9>0,'For lab assistants'!A9,"") -> A06 | C9: =IF('For lab assistants'!B9>0,'For lab assistants'!B9,"") -> ARack0467 | D9: =IF('For lab assistants'!C9>0,'For lab assistants'!C9,"") -> LVL600038037 | E9: =IF('For lab assistants'!O9>0,'For lab assistants'!O9,"") -> Frederiksborg_Slotssø_kerne_3 | F9: =IF('For lab assistants'!E9>0,'For lab assistants'!E9,"") -> 11.5 | G9: =IF('For lab assistants'!P9>0,'For lab assistants'!P9,"") | H9: =IF('For lab assistants'!F9>0,'For lab assistants'!F9,"low") -> low | I9: =IF('For lab assistants'!G9>0,'For lab assistants'!G9,"no") -> no | J9: =IF('For lab assistants'!H9>0,'For lab assistants'!H9,"") | K9: =IF('For lab assistants'!I9>0,'For lab assistants'!I9,"") -> FM | L9: =IF('For lab assistants'!J9>0,'For lab assistants'!J9,"") -> VSS | M9: =IF('For lab assistants'!K9>0,'For lab assistants'!K9,"") -> 45241 | N9: =IF('For lab assistants'!D9>0,'For lab assistants'!M9,"") -> NKL | O9: =IF('For lab assistants'!D9>0,'For lab assistants'!N9,"") -> 45226 | P9: =IF(Output4SubSamplingSubmiss.!F9>0,Output4SubSamplingSubmiss.!F9,"")
A10: =IF('For lab assistants'!D10>0,'For lab assistants'!D10,"") -> LV3005889419 | B10: =IF('For lab assistants'!D10>0,'For lab assistants'!A10,"") -> B06 | C10: =IF('For lab assistants'!B10>0,'For lab assistants'!B10,"") -> ARack0467 | D10: =IF('For lab assistants'!C10>0,'For lab assistants'!C10,"") -> LVL600038037 | E10: =IF('For lab assistants'!O10>0,'For lab assistants'!O10,"") -> Frederiksborg_Slotssø_kerne_3 | F10: =IF('For lab assistants'!E10>0,'For lab assistants'!E10,"") -> 13 | G10: =IF('For lab assistants'!P10>0,'For lab assistants'!P10,"") | H10: =IF('For lab assistants'!F10>0,'For lab assistants'!F10,"low") -> low | I10: =IF('For lab assistants'!G10>0,'For lab assistants'!G10,"no") -> no | J10: =IF('For lab assistants'!H10>0,'For lab assistants'!H10,"") | K10: =IF('For lab assistants'!I10>0,'For lab assistants'!I10,"") -> FM | L10: =IF('For lab assistants'!J10>0,'For lab assistants'!J10,"") -> VSS | M10: =IF('For lab assistants'!K10>0,'For lab assistants'!K10,"") -> 45241 | N10: =IF('For lab assistants'!D10>0,'For lab assistants'!M10,"") -> NKL | O10: =IF('For lab assistants'!D10>0,'For lab assistants'!N10,"") -> 45226 | P10: =IF(Output4SubSamplingSubmiss.!F10>0,Output4SubSamplingSubmiss.!F10,"")
A11: =IF('For lab assistants'!D11>0,'For lab assistants'!D11,"") -> LV3005888162 | B11: =IF('For lab assistants'!D11>0,'For lab assistants'!A11,"") -> C06 | C11: =IF('For lab assistants'!B11>0,'For lab assistants'!B11,"") -> ARack0467 | D11: =IF('For lab assistants'!C11>0,'For lab assistants'!C11,"") -> LVL600038037 | E11: =IF('For lab assistants'!O11>0,'For lab assistants'!O11,"") -> Frederiksborg_Slotssø_kerne_3 | F11: =IF('For lab assistants'!E11>0,'For lab assistants'!E11,"") -> 14.5 | G11: =IF('For lab assistants'!P11>0,'For lab assistants'!P11,"") | H11: =IF('For lab assistants'!F11>0,'For lab assistants'!F11,"low") -> low | I11: =IF('For lab assistants'!G11>0,'For lab assistants'!G11,"no") -> no | J11: =IF('For lab assistants'!H11>0,'For lab assistants'!H11,"") | K11: =IF('For lab assistants'!I11>0,'For lab assistants'!I11,"") -> FM | L11: =IF('For lab assistants'!J11>0,'For lab assistants'!J11,"") -> VSS | M11: =IF('For lab assistants'!K11>0,'For lab assistants'!K11,"") -> 45241 | N11: =IF('For lab assistants'!D11>0,'For lab assistants'!M11,"") -> NKL | O11: =IF('For lab assistants'!D11>0,'For lab assistants'!N11,"") -> 45226 | P11: =IF(Output4SubSamplingSubmiss.!F11>0,Output4SubSamplingSubmiss.!F11,"")
A12: =IF('For lab assistants'!D12>0,'For lab assistants'!D12,"") -> LV3005887708 | B12: =IF('For lab assistants'!D12>0,'For lab assistants'!A12,"") -> D06 | C12: =IF('For lab assistants'!B12>0,'For lab assistants'!B12,"") -> ARack0467 | D12: =IF('For lab assistants'!C12>0,'For lab assistants'!C12,"") -> LVL600038037 | E12: =IF('For lab assistants'!O12>0,'For lab assistants'!O12,"") -> Frederiksborg_Slotssø_kerne_3 | F12: =IF('For lab assistants'!E12>0,'For lab assistants'!E12,"") -> 16 | G12: =IF('For lab assistants'!P12>0,'For lab assistants'!P12,"") | H12: =IF('For lab assistants'!F12>0,'For lab assistants'!F12,"low") -> low | I12: =IF('For lab assistants'!G12>0,'For lab assistants'!G12,"no") -> no | J12: =IF('For lab assistants'!H12>0,'For lab assistants'!H12,"") | K12: =IF('For lab assistants'!I12>0,'For lab assistants'!I12,"") -> FM | L12: =IF('For lab assistants'!J12>0,'For lab assistants'!J12,"") -> VSS | M12: =IF('For lab assistants'!K12>0,'For lab assistants'!K12,"") -> 45241 | N12: =IF('For lab assistants'!D12>0,'For lab assistants'!M12,"") -> NKL | O12: =IF('For lab assistants'!D12>0,'For lab assistants'!N12,"") -> 45226 | P12: =IF(Output4SubSamplingSubmiss.!F12>0,Output4SubSamplingSubmiss.!F12,"")
A13: =IF('For lab assistants'!D13>0,'For lab assistants'!D13,"") -> LV3005888727 | B13: =IF('For lab assistants'!D13>0,'For lab assistants'!A13,"") -> A01 | C13: =IF('For lab assistants'!B13>0,'For lab assistants'!B13,"") -> ARack0475 | D13: =IF('For lab assistants'!C13>0,'For lab assistants'!C13,"") -> LVL600038051 | E13: =IF('For lab assistants'!O13>0,'For lab assistants'!O13,"") -> Frederiksborg_Slotssø_kerne_3 | F13: =IF('For lab assistants'!E13>0,'For lab assistants'!E13,"") -> 18 | G13: =IF('For lab assistants'!P13>0,'For lab assistants'!P13,"") | H13: =IF('For lab assistants'!F13>0,'For lab assistants'!F13,"low") -> low | I13: =IF('For lab assistants'!G13>0,'For lab assistants'!G13,"no") -> no | J13: =IF('For lab assistants'!H13>0,'For lab assistants'!H13,"") | K13: =IF('For lab assistants'!I13>0,'For lab assistants'!I13,"") -> FM | L13: =IF('For lab assistants'!J13>0,'For lab assistants'!J13,"") -> VSS | M13: =IF('For lab assistants'!K13>0,'For lab assistants'!K13,"") -> 45241 | N13: =IF('For lab assistants'!D13>0,'For lab assistants'!M13,"") -> NKL | O13: =IF('For lab assistants'!D13>0,'For lab assistants'!N13,"") -> 45226 | P13: =IF(Output4SubSamplingSubmiss.!F13>0,Output4SubSamplingSubmiss.!F13,"")
... A60: =IF('For lab assistants'!D60>0,'For lab assistants'!D60,"") -> LV3006009501 | B60: =IF('For lab assistants'!D60>0,'For lab assistants'!A60,"") -> D06 | C60: =IF('For lab assistants'!B60>0,'For lab assistants'!B60,"") -> ARack0476 | D60: =IF('For lab assistants'!C60>0,'For lab assistants'!C60,"") -> LVL600052415 | E60: =IF('For lab assistants'!O60>0,'For lab assistants'!O60,"") -> Frederiksborg_Slotssø_kerne_3 | F60: =IF('For lab assistants'!E60>0,'For lab assistants'!E60,"") -> 91.5 | G60: =IF('For lab assistants'!P60>0,'For lab assistants'!P60,"") | H60: =IF('For lab assistants'!F60>0,'For lab assistants'!F60,"low") -> low | I60: =IF('For lab assistants'!G60>0,'For lab assistants'!G60,"no") -> no | J60: =IF('For lab assistants'!H60>0,'For lab assistants'!H60,"") | K60: =IF('For lab assistants'!I60>0,'For lab assistants'!I60,"") -> FM | L60: =IF('For lab assistants'!J60>0,'For lab assistants'!J60,"") -> VSS | M60: =IF('For lab assistants'!K60>0,'For lab assistants'!K60,"") -> 45241 | N60: =IF('For lab assistants'!D60>0,'For lab assistants'!M60,"") -> NKL | O60: =IF('For lab assistants'!D60>0,'For lab assistants'!N60,"") -> 45226 | P60: =IF(Output4SubSamplingSubmiss.!F60>0,Output4SubSamplingSubmiss.!F60,"")
A61: =IF('For lab assistants'!D61>0,'For lab assistants'!D61,"") -> LV3006009476 | B61: =IF('For lab assistants'!D61>0,'For lab assistants'!A61,"") -> A01 | C61: =IF('For lab assistants'!B61>0,'For lab assistants'!B61,"") -> ARack0477 | D61: =IF('For lab assistants'!#REF!>0,'For lab assistants'!#REF!,"") -> #REF! | E61: =IF('For lab assistants'!O61>0,'For lab assistants'!O61,"") -> Frederiksborg_Slotssø_kerne_3 | F61: =IF('For lab assistants'!E61>0,'For lab assistants'!E61,"") -> 93 | G61: =IF('For lab assistants'!P61>0,'For lab assistants'!P61,"") | H61: =IF('For lab assistants'!F61>0,'For lab assistants'!F61,"low") -> low | I61: =IF('For lab assistants'!G61>0,'For lab assistants'!G61,"no") -> no | J61: =IF('For lab assistants'!H61>0,'For lab assistants'!H61,"") | K61: =IF('For lab assistants'!I61>0,'For lab assistants'!I61,"") -> FM | L61: =IF('For lab assistants'!J61>0,'For lab assistants'!J61,"") -> VSS | M61: =IF('For lab assistants'!K61>0,'For lab assistants'!K61,"") -> 45241 | N61: =IF('For lab assistants'!D61>0,'For lab assistants'!M61,"") -> NKL | O61: =IF('For lab assistants'!D61>0,'For lab assistants'!N61,"") -> 45226 | P61: =IF(Output4SubSamplingSubmiss.!F61>0,Output4SubSamplingSubmiss.!F61,"")
A62: =IF('For lab assistants'!D62>0,'For lab assistants'!D62,"") -> LV3006009482 | B62: =IF('For lab assistants'!D62>0,'For lab assistants'!A62,"") -> B01 | C62: =IF('For lab assistants'!B62>0,'For lab assistants'!B62,"") -> ARack0477 | D62: =IF('For lab assistants'!C61>0,'For lab assistants'!C61,"") -> LVL600052414 | E62: =IF('For lab assistants'!O62>0,'For lab assistants'!O62,"") -> Frederiksborg_Slotssø_kerne_3 | F62: =IF('For lab assistants'!E62>0,'For lab assistants'!E62,"") -> 94.5 | G62: =IF('For lab assistants'!P62>0,'For lab assistants'!P62,"") | H62: =IF('For lab assistants'!F62>0,'For lab assistants'!F62,"low") -> low | I62: =IF('For lab assistants'!G62>0,'For lab assistants'!G62,"no") -> no | J62: =IF('For lab assistants'!H62>0,'For lab assistants'!H62,"") | K62: =IF('For lab assistants'!I62>0,'For lab assistants'!I62,"") -> FM | L62: =IF('For lab assistants'!J62>0,'For lab assistants'!J62,"") -> VSS | M62: =IF('For lab assistants'!K62>0,'For lab assistants'!K62,"") -> 45241 | N62: =IF('For lab assistants'!D62>0,'For lab assistants'!M62,"") -> NKL | O62: =IF('For lab assistants'!D62>0,'For lab assistants'!N62,"") -> 45226 | P62: =IF(Output4SubSamplingSubmiss.!F62>0,Output4SubSamplingSubmiss.!F62,"")
A63: =IF('For lab assistants'!D63>0,'For lab assistants'!D63,"") -> LV3006009489 | B63: =IF('For lab assistants'!D63>0,'For lab assistants'!A63,"") -> C01 | C63: =IF('For lab assistants'!B63>0,'For lab assistants'!B63,"") -> ARack0477 | D63: =IF('For lab assistants'!C62>0,'For lab assistants'!C62,"") -> LVL600052414 | E63: =IF('For lab assistants'!O63>0,'For lab assistants'!O63,"") -> Frederiksborg_Slotssø_kerne_3 | F63: =IF('For lab assistants'!E63>0,'For lab assistants'!E63,"") -> 96 | G63: =IF('For lab assistants'!P63>0,'For lab assistants'!P63,"") | H63: =IF('For lab assistants'!F63>0,'For lab assistants'!F63,"low") -> low | I63: =IF('For lab assistants'!G63>0,'For lab assistants'!G63,"no") -> no | J63: =IF('For lab assistants'!H63>0,'For lab assistants'!H63,"") | K63: =IF('For lab assistants'!I63>0,'For lab assistants'!I63,"") -> FM | L63: =IF('For lab assistants'!J63>0,'For lab assistants'!J63,"") -> VSS | M63: =IF('For lab assistants'!K63>0,'For lab assistants'!K63,"") -> 45241 | N63: =IF('For lab assistants'!D63>0,'For lab assistants'!M63,"") -> NKL | O63: =IF('For lab assistants'!D63>0,'For lab assistants'!N63,"") -> 45226 | P63: =IF(Output4SubSamplingSubmiss.!F63>0,Output4SubSamplingSubmiss.!F63,"")
A64: =IF('For lab assistants'!D64>0,'For lab assistants'!D64,"") -> LV3006009496 | B64: =IF('For lab assistants'!D64>0,'For lab assistants'!A64,"") -> D01 | C64: =IF('For lab assistants'!B64>0,'For lab assistants'!B64,"") -> ARack0477 | D64: =IF('For lab assistants'!C64>0,'For lab assistants'!C64,"") -> LVL600052414 | E64: =IF('For lab assistants'!O64>0,'For lab assistants'!O64,"") -> Frederiksborg_Slotssø_kerne_3 | F64: =IF('For lab assistants'!E64>0,'For lab assistants'!E64,"") -> 97.5 | G64: =IF('For lab assistants'!P64>0,'For lab assistants'!P64,"") | H64: =IF('For lab assistants'!F64>0,'For lab assistants'!F64,"low") -> low | I64: =IF('For lab assistants'!G64>0,'For lab assistants'!G64,"no") -> no | J64: =IF('For lab assistants'!H64>0,'For lab assistants'!H64,"") | K64: =IF('For lab assistants'!I64>0,'For lab assistants'!I64,"") -> FM | L64: =IF('For lab assistants'!J64>0,'For lab assistants'!J64,"") -> VSS | M64: =IF('For lab assistants'!K64>0,'For lab assistants'!K64,"") -> 45241 | N64: =IF('For lab assistants'!D64>0,'For lab assistants'!M64,"") -> NKL | O64: =IF('For lab assistants'!D64>0,'For lab assistants'!N64,"") -> 45226 | P64: =IF(Output4SubSamplingSubmiss.!F64>0,Output4SubSamplingSubmiss.!F64,"")
A65: =IF('For lab assistants'!D65>0,'For lab assistants'!D65,"") -> LV3006009481 | B65: =IF('For lab assistants'!D65>0,'For lab assistants'!A65,"") -> A02 | C65: =IF('For lab assistants'!B65>0,'For lab assistants'!B65,"") -> ARack0477 | D65: =IF('For lab assistants'!C65>0,'For lab assistants'!C65,"") -> LVL600052414 | E65: =IF('For lab assistants'!O65>0,'For lab assistants'!O65,"") -> Frederiksborg_Slotssø_kerne_3 | F65: =IF('For lab assistants'!E65>0,'For lab assistants'!E65,"") -> 99.5 | G65: =IF('For lab assistants'!P65>0,'For lab assistants'!P65,"") | H65: =IF('For lab assistants'!F65>0,'For lab assistants'!F65,"low") -> low | I65: =IF('For lab assistants'!G65>0,'For lab assistants'!G65,"no") -> no | J65: =IF('For lab assistants'!H65>0,'For lab assistants'!H65,"") | K65: =IF('For lab assistants'!I65>0,'For lab assistants'!I65,"") -> FM | L65: =IF('For lab assistants'!J65>0,'For lab assistants'!J65,"") -> VSS | M65: =IF('For lab assistants'!K65>0,'For lab assistants'!K65,"") -> 45241 | N65: =IF('For lab assistants'!D65>0,'For lab assistants'!M65,"") -> NKL | O65: =IF('For lab assistants'!D65>0,'For lab assistants'!N65,"") -> 45226 | P65: =IF(Output4SubSamplingSubmiss.!F65>0,Output4SubSamplingSubmiss.!F65,"")
A66: =IF('For lab assistants'!D66>0,'For lab assistants'!D66,"") -> LV3006009475 | B66: =IF('For lab assistants'!D66>0,'For lab assistants'!A66,"") -> B02 | C66: =IF('For lab assistants'!B66>0,'For lab assistants'!B66,"") -> ARack0477 | D66: =IF('For lab assistants'!C66>0,'For lab assistants'!C66,"") -> LVL600052414 | E66: =IF('For lab assistants'!O66>0,'For lab assistants'!O66,"") -> Frederiksborg_Slotssø_kerne_3 | F66: =IF('For lab assistants'!E66>0,'For lab assistants'!E66,"") -> 101 | G66: =IF('For lab assistants'!P66>0,'For lab assistants'!P66,"") | H66: =IF('For lab assistants'!F66>0,'For lab assistants'!F66,"low") -> low | I66: =IF('For lab assistants'!G66>0,'For lab assistants'!G66,"no") -> no | J66: =IF('For lab assistants'!H66>0,'For lab assistants'!H66,"") | K66: =IF('For lab assistants'!I66>0,'For lab assistants'!I66,"") -> FM | L66: =IF('For lab assistants'!J66>0,'For lab assistants'!J66,"") -> VSS | M66: =IF('For lab assistants'!K66>0,'For lab assistants'!K66,"") -> 45241 | N66: =IF('For lab assistants'!D66>0,'For lab assistants'!M66,"") -> NKL | O66: =IF('For lab assistants'!D66>0,'For lab assistants'!N66,"") -> 45226 | P66: =IF(Output4SubSamplingSubmiss.!F66>0,Output4SubSamplingSubmiss.!F66,"")
A67: =IF('For lab assistants'!D67>0,'For lab assistants'!D67,"") -> LV3006009488 | B67: =IF('For lab assistants'!D67>0,'For lab assistants'!A67,"") -> C02 | C67: =IF('For lab assistants'!B67>0,'For lab assistants'!B67,"") -> ARack0477 | D67: =IF('For lab assistants'!C67>0,'For lab assistants'!C67,"") -> LVL600052414 | E67: =IF('For lab assistants'!O67>0,'For lab assistants'!O67,"") -> Frederiksborg_Slotssø_kerne_3 | F67: =IF('For lab assistants'!E67>0,'For lab assistants'!E67,"") -> 102.5 | G67: =IF('For lab assistants'!P67>0,'For lab assistants'!P67,"") | H67: =IF('For lab assistants'!F67>0,'For lab assistants'!F67,"low") -> low | I67: =IF('For lab assistants'!G67>0,'For lab assistants'!G67,"no") -> no | J67: =IF('For lab assistants'!H67>0,'For lab assistants'!H67,"") | K67: =IF('For lab assistants'!I67>0,'For lab assistants'!I67,"") -> FM | L67: =IF('For lab assistants'!J67>0,'For lab assistants'!J67,"") -> VSS | M67: =IF('For lab assistants'!K67>0,'For lab assistants'!K67,"") -> 45241 | N67: =IF('For lab assistants'!D67>0,'For lab assistants'!M67,"") -> NKL | O67: =IF('For lab assistants'!D67>0,'For lab assistants'!N67,"") -> 45226 | P67: =IF(Output4SubSamplingSubmiss.!F67>0,Output4SubSamplingSubmiss.!F67,"")
A68: =IF('For lab assistants'!D68>0,'For lab assistants'!D68,"") -> LV3006009495 | B68: =IF('For lab assistants'!D68>0,'For lab assistants'!A68,"") -> D02 | C68: =IF('For lab assistants'!B68>0,'For lab assistants'!B68,"") -> ARack0477 | D68: =IF('For lab assistants'!C68>0,'For lab assistants'!C68,"") -> LVL600052414 | E68: =IF('For lab assistants'!O68>0,'For lab assistants'!O68,"") -> Frederiksborg_Slotssø_kerne_3 | F68: =IF('For lab assistants'!E68>0,'For lab assistants'!E68,"") -> 104 | G68: =IF('For lab assistants'!P68>0,'For lab assistants'!P68,"") | H68: =IF('For lab assistants'!F68>0,'For lab assistants'!F68,"low") -> low | I68: =IF('For lab assistants'!G68>0,'For lab assistants'!G68,"no") -> no | J68: =IF('For lab assistants'!H68>0,'For lab assistants'!H68,"") | K68: =IF('For lab assistants'!I68>0,'For lab assistants'!I68,"") -> FM | L68: =IF('For lab assistants'!J68>0,'For lab assistants'!J68,"") -> VSS | M68: =IF('For lab assistants'!K68>0,'For lab assistants'!K68,"") -> 45241 | N68: =IF('For lab assistants'!D68>0,'For lab assistants'!M68,"") -> NKL | O68: =IF('For lab assistants'!D68>0,'For lab assistants'!N68,"") -> 45226 | P68: =IF(Output4SubSamplingSubmiss.!F68>0,Output4SubSamplingSubmiss.!F68,"")
