Workbook
Name piinfo: #REF!
Name piinfo: #REF!

Sheet ReadMe
B2: For Submitter (PI or project leader):
A3: 1: | B3: Download and rename file: | C3: "Ordering_eDNA_Subsampling_for_robot_pipeline(YYMMDD_Initials_ProjectID).xlsx"
C4: e.g. Ordering_eDNA_subsampling_for_robot_pipeline(230715_LVI_Langeland02).xlsx
A5: 2: | B5: Fill out the [Submit here] tab column B,C,D,E,F,G,H (and I).
B6: Info for column D, E, F, G can be copied from the relevant "Archive sampling sheet(s)".
B7: Consider the number of negative controls (default is 1 NTC per 24 samples).
B8: Leave the last two postions per rack empty for production controls.
A9: 3: | B9: Mail the renamed and completed ordering form (this file) to Jesper Stenderup; eDNA_orders@sund.ku.dk.
A10: 4: | B10: Make sure the samples are clearly labelled and easily available for the lab assistants.

Sheet For submitter
A1: No | B1: Submitter (initials) | C1: Submission Date (yyyy-mm-dd) | D1: Core- or Bulk sample ID (Optional) | E1: Archive rack position | F1: Archive RACK no. (eg. ARack0052) | G1: Archive RACK barcode | H1: Archive TUBE barcode | I1: Remarks (eg. personal project ID)
A2: 1 | B2: BdS_YW | C2: 45009 | D2: GOR22SS | E2: A01 | F2: ARack0431 | G2: LVL600038023 | H2: LV3005888014 | I2: A01
A3: 2 | B3: =B2 -> BdS_YW | C3: =C2 -> 45009 | D3: GOR22SS | E3: B01 | F3: ARack0431 | G3: LVL600038023 | H3: LV3005888008 | I3: B01
A4: 3 | B4: =B3 -> BdS_YW | C4: =C3 -> 45009 | D4: GOR22SS | E4: C01 | F4: ARack0431 | G4: LVL600038023 | H4: LV3005888020 | I4: C01
A5: 4 | B5: =B4 -> BdS_YW | C5: =C4 -> 45009 | D5: GOR22SS | E5: D01 | F5: ARack0431 | G5: LVL600038023 | H5: LV3005888019 | I5: D01
A6: 5 | B6: =B5 -> BdS_YW | C6: =C5 -> 45009 | D6: GOR22SS | E6: A02 | F6: ARack0431 | G6: LVL600038023 | H6: LV3005888013 | I6: E01
A7: 6 | B7: =B6 -> BdS_YW | C7: =C6 -> 45009 | D7: GOR22SS | E7: B02 | F7: ARack0431 | G7: LVL600038023 | H7: LV3005888007 | I7: F01
A8: 7 | B8: =B7 -> BdS_YW | C8: =C7 -> 45009 | D8: GOR22SS | E8: C02 | F8: ARack0431 | G8: LVL600038023 | H8: LV3005888001 | I8: A02
A9: 8 | B9: =B8 -> BdS_YW | C9: =C8 -> 45009 | D9: GOR22SS | E9: D02 | F9: ARack0431 | G9: LVL600038023 | H9: LV3005888018 | I9: B02
A10: 9 | B10: =B9 -> BdS_YW | C10: =C9 -> 45009 | D10: GOR22SS | E10: A03 | F10: ARack0431 | G10: LVL600038023 | H10: LV3005888016 | I10: C02
A11: 10 | B11: =B10 -> BdS_YW | C11: =C10 -> 45009 | D11: GOR22SS | E11: B03 | F11: ARack0431 | G11: LVL600038023 | H11: LV3005888012 | I11: D02
A12: 11 | B12: =B11 -> BdS_YW | C12: =C11 -> 45009 | D12: GOR22SS | E12: C03 | F12: ARack0431 | G12: LVL600038023 | H12: LV3005888006 | I12: E02
A13: 12 | B13: =B12 -> BdS_YW | C13: =C12 -> 45009 | D13: GOR22SS | E13: D03 | F13: ARack0431 | G13: LVL600038023 | H13: LV3005888000 | I13: F02
A14: 13 | B14: =B13 -> BdS_YW | C14: =C13 -> 45009 | D14: GOR22SS | E14: A04 | F14: ARack0431 | G14: LVL600038023 | H14: LV3005888017 | I14: A03
A15: 14 | B15: =B14 -> BdS_YW | C15: =C14 -> 45009 | D15: GOR22A_1 | E15: B04 | F15: ARack0431 | G15: LVL600038023 | H15: LV3005888015 | I15: B03
A16: 15 | B16: =B15 -> BdS_YW | C16: =C15 -> 45009 | I16: C03
A17: 16 | B17: =B16 -> BdS_YW | C17: =C16 -> 45009 | D17: GOR22A_1 | E17: C04 | F17: ARack0431 | G17: LVL600038023 | H17: LV3005888009 | I17: D03
A18: 17 | B18: =B17 -> BdS_YW | C18: =C17 -> 45009 | D18: GOR22A_1 | E18: D04 | F18: ARack0431 | G18: LVL600038023 | H18: LV3005888010 | I18: E03
A19: 18 | B19: =B18 -> BdS_YW | C19: =C18 -> 45009 | D19: GOR22A_1 | E19: A05 | F19: ARack0431 | G19: LVL600038023 | H19: LV3005888011 | I19: F03
A20: 19 | B20: =B19 -> BdS_YW | C20: =C19 -> 45009 | D20: GOR22A_1 | E20: B05 | F20: ARack0431 | G20: LVL600038023 | H20: LV3005888003 | I20: A04
A21: 20 | B21: =B20 -> BdS_YW | C21: =C20 -> 45009 | D21: GOR22A_1 | E21: C05 | F21: ARack0431 | G21: LVL600038023 | H21: LV3005888004 | I21: B04
A22: 21 | B22: =B21 -> BdS_YW | C22: =C21 -> 45009 | D22: GOR22A_1 | E22: D05 | F22: ARack0431 | G22: LVL600038023 | H22: LV3005888005 | I22: C04
A23: 22 | B23: =B22 -> BdS_YW | C23: =C22 -> 45009 | D23: GOR22A_1 | E23: A06 | F23: ARack0431 | G23: LVL600038023 | H23: LV3005887997 | I23: D04
A24: 23 | B24: =B23 -> BdS_YW | C24: =C23 -> 45009 | D24: GOR22A_1 | E24: B06 | F24: ARack0431 | G24: LVL600038023 | H24: LV3005887998 | I24: E04
A25: 24 | B25: =B24 -> BdS_YW | C25: =C24 -> 45009 | D25: GOR22A_1 | E25: C06 | F25: ARack0431 | G25: LVL600038023 | H25: LV3005887773 | I25: F04
A26: 25 | B26: =B25 -> BdS_YW | C26: =C25 -> 45009 | D26: GOR22A_1 | E26: D06 | F26: ARack0431 | G26: LVL600038023 | H26: LV3005887999 | I26: A05
A27: 26 | B27: =B26 -> BdS_YW | C27: =C26 -> 45009 | D27: GOR22A_1 | E27: A01 | F27: ARack0432 | G27: LVL600038022 | H27: LV3005887991 | I27: B05
A28: 27 | B28: =B27 -> BdS_YW | C28: =C27 -> 45009 | D28: GOR22A_1 | E28: B01 | F28: ARack0432 | G28: LVL600038022 | H28: LV3005887985 | I28: C05
... A34: 33 | B34: =B33 -> BdS_YW | C34: =C33 -> 45009 | D34: GOR22A_1 | E34: D02 | F34: ARack0432 | G34: LVL600038022 | H34: LV3005887996 | I34: C06
A35: 34 | B35: =B34 -> BdS_YW | C35: =C34 -> 45009 | I35: D06
A36: 35 | B36: =B35 -> BdS_YW | C36: =C35 -> 45009 | D36: GOR22A_1 | E36: A03 | F36: ARack0432 | G36: LVL600038022 | H36: LV3005887989 | I36: E06
A37: 36 | B37: =B36 -> BdS_YW | C37: =C36 -> 45009 | D37: GOR22A_1 | E37: B03 | F37: ARack0432 | G37: LVL600038022 | H37: LV3005887987 | I37: F06
A38: 37 | B38: =B37 -> BdS_YW | C38: =C37 -> 45009 | D38: GOR22A_1 | E38: C03 | F38: ARack0432 | G38: LVL600038022 | H38: LV3005887978 | I38: A07
A39: 38 | B39: =B38 -> BdS_YW | C39: =C38 -> 45009 | D39: GOR22A_1 | E39: D03 | F39: ARack0432 | G39: LVL600038022 | H39: LV3005887979 | I39: B07
A40: 39 | B40: =B39 -> BdS_YW | C40: =C39 -> 45009 | D40: GOR22A_1 | E40: A04 | F40: ARack0432 | G40: LVL600038022 | H40: LV3005887988 | I40: C07
A41: 40 | B41: =B40 -> BdS_YW | C41: =C40 -> 45009 | D41: GOR22A_1 | E41: B04 | F41: ARack0432 | G41: LVL600038022 | H41: LV3005887990 | I41: D07
A42: 41 | B42: =B41 -> BdS_YW | C42: =C41 -> 45009 | D42: GOR22A_1 | E42: C04 | F42: ARack0432 | G42: LVL600038022 | H42: LV3005887980 | I42: E07
A43: 42 | B43: =B42 -> BdS_YW | C43: =C42 -> 45009 | D43: GOR22A_1 | E43: D04 | F43: ARack0432 | G43: LVL600038022 | H43: LV3005887983 | I43: F07
A44: 43 | B44: =B43 -> BdS_YW | C44: =C43 -> 45009 | D44: GOR22A_2 | E44: A05 | F44: ARack0432 | G44: LVL600038022 | H44: LV3005887982 | I44: A08
A45: 44 | B45: =B44 -> BdS_YW | C45: =C44 -> 45009 | D45: GOR22A_2 | E45: B05 | F45: ARack0432 | G45: LVL600038022 | H45: LV3005887984 | I45: B08
...

Sheet Output4LibrarySubmiss.
A1: No | B1: Position in Rack | C1: Robot RACK name | D1: Robot RACK barcode | E1: Robot TUBE barcode | F1: Core(bulk)SampleID | G1: ='For Lab assistants ONLY'!F1 -> Sample mass (mg) | H1: RemarksSubmission
A2: 1 | B2: =IF('For Lab assistants ONLY'!B2>0,'For Lab assistants ONLY'!A2,"") -> A01 | C2: =IF('For Lab assistants ONLY'!B2>0,'For Lab assistants ONLY'!B2,"") -> Rack52 | D2: =IF('For Lab assistants ONLY'!C2>0,'For Lab assistants ONLY'!C2,"") -> LVL900114395 | E2: =IF('For Lab assistants ONLY'!E2>0,'For Lab assistants ONLY'!E2,"") -> LV7005367348 | F2: =IF('For Lab assistants ONLY'!M2>0,'For Lab assistants ONLY'!M2,"") -> GOR22SS | G2: =IF('For Lab assistants ONLY'!F2>0,'For Lab assistants ONLY'!F2,"") -> 192 | H2: =IF('For Lab assistants ONLY'!R2>0,'For Lab assistants ONLY'!R2,"") -> A01
A3: 2 | B3: =IF('For Lab assistants ONLY'!B3>0,'For Lab assistants ONLY'!A3,"") -> B01 | C3: =IF('For Lab assistants ONLY'!B3>0,'For Lab assistants ONLY'!B3,"") -> Rack52 | D3: =IF('For Lab assistants ONLY'!C3>0,'For Lab assistants ONLY'!C3,"") -> LVL900114395 | E3: =IF('For Lab assistants ONLY'!E3>0,'For Lab assistants ONLY'!E3,"") -> LV7005227800 | F3: =IF('For Lab assistants ONLY'!M3>0,'For Lab assistants ONLY'!M3,"") -> GOR22SS | G3: =IF('For Lab assistants ONLY'!F3>0,'For Lab assistants ONLY'!F3,"") -> 140 | H3: =IF('For Lab assistants ONLY'!R3>0,'For Lab assistants ONLY'!R3,"") -> B01
A4: 3 | B4: =IF('For Lab assistants ONLY'!B4>0,'For Lab assistants ONLY'!A4,"") -> C01 | C4: =IF('For Lab assistants ONLY'!B4>0,'For Lab assistants ONLY'!B4,"") -> Rack52 | D4: =IF('For Lab assistants ONLY'!C4>0,'For Lab assistants ONLY'!C4,"") -> LVL900114395 | E4: =IF('For Lab assistants ONLY'!E4>0,'For Lab assistants ONLY'!E4,"") -> LV7005224976 | F4: =IF('For Lab assistants ONLY'!M4>0,'For Lab assistants ONLY'!M4,"") -> GOR22SS | G4: =IF('For Lab assistants ONLY'!F4>0,'For Lab assistants ONLY'!F4,"") -> 172 | H4: =IF('For Lab assistants ONLY'!R4>0,'For Lab assistants ONLY'!R4,"") -> C01
A5: 4 | B5: =IF('For Lab assistants ONLY'!B5>0,'For Lab assistants ONLY'!A5,"") -> D01 | C5: =IF('For Lab assistants ONLY'!B5>0,'For Lab assistants ONLY'!B5,"") -> Rack52 | D5: =IF('For Lab assistants ONLY'!C5>0,'For Lab assistants ONLY'!C5,"") -> LVL900114395 | E5: =IF('For Lab assistants ONLY'!E5>0,'For Lab assistants ONLY'!E5,"") -> LV7005224920 | F5: =IF('For Lab assistants ONLY'!M5>0,'For Lab assistants ONLY'!M5,"") -> GOR22SS | G5: =IF('For Lab assistants ONLY'!F5>0,'For Lab assistants ONLY'!F5,"") -> 181 | H5: =IF('For Lab assistants ONLY'!R5>0,'For Lab assistants ONLY'!R5,"") -> D01
A6: 5 | B6: =IF('For Lab assistants ONLY'!B6>0,'For Lab assistants ONLY'!A6,"") -> E01 | C6: =IF('For Lab assistants ONLY'!B6>0,'For Lab assistants ONLY'!B6,"") -> Rack52 | D6: =IF('For Lab assistants ONLY'!C6>0,'For Lab assistants ONLY'!C6,"") -> LVL900114395 | E6: =IF('For Lab assistants ONLY'!E6>0,'For Lab assistants ONLY'!E6,"") -> LV7005225024 | F6: =IF('For Lab assistants ONLY'!M6>0,'For Lab assistants ONLY'!M6,"") -> GOR22SS | G6: =IF('For Lab assistants ONLY'!F6>0,'For Lab assistants ONLY'!F6,"") -> 162 | H6: =IF('For Lab assistants ONLY'!R6>0,'For Lab assistants ONLY'!R6,"") -> E01
A7: 6 | B7: =IF('For Lab assistants ONLY'!B7>0,'For Lab assistants ONLY'!A7,"") -> F01 | C7: =IF('For Lab assistants ONLY'!B7>0,'For Lab assistants ONLY'!B7,"") -> Rack52 | D7: =IF('For Lab assistants ONLY'!C7>0,'For Lab assistants ONLY'!C7,"") -> LVL900114395 | E7: =IF('For Lab assistants ONLY'!E7>0,'For Lab assistants ONLY'!E7,"") -> LV7005225032 | F7: =IF('For Lab assistants ONLY'!M7>0,'For Lab assistants ONLY'!M7,"") -> GOR22SS | G7: =IF('For Lab assistants ONLY'!F7>0,'For Lab assistants ONLY'!F7,"") -> 163 | H7: =IF('For Lab assistants ONLY'!R7>0,'For Lab assistants ONLY'!R7,"") -> F01
A8: 7 | B8: =IF('For Lab assistants ONLY'!B8>0,'For Lab assistants ONLY'!A8,"") -> A02 | C8: =IF('For Lab assistants ONLY'!B8>0,'For Lab assistants ONLY'!B8,"") -> Rack52 | D8: =IF('For Lab assistants ONLY'!C8>0,'For Lab assistants ONLY'!C8,"") -> LVL900114395 | E8: =IF('For Lab assistants ONLY'!E8>0,'For Lab assistants ONLY'!E8,"") -> LV7005225594 | F8: =IF('For Lab assistants ONLY'!M8>0,'For Lab assistants ONLY'!M8,"") -> GOR22SS | G8: =IF('For Lab assistants ONLY'!F8>0,'For Lab assistants ONLY'!F8,"") -> 179 | H8: =IF('For Lab assistants ONLY'!R8>0,'For Lab assistants ONLY'!R8,"") -> A02
A9: 8 | B9: =IF('For Lab assistants ONLY'!B9>0,'For Lab assistants ONLY'!A9,"") -> B02 | C9: =IF('For Lab assistants ONLY'!B9>0,'For Lab assistants ONLY'!B9,"") -> Rack52 | D9: =IF('For Lab assistants ONLY'!C9>0,'For Lab assistants ONLY'!C9,"") -> LVL900114395 | E9: =IF('For Lab assistants ONLY'!E9>0,'For Lab assistants ONLY'!E9,"") -> LV7005225602 | F9: =IF('For Lab assistants ONLY'!M9>0,'For Lab assistants ONLY'!M9,"") -> GOR22SS | G9: =IF('For Lab assistants ONLY'!F9>0,'For Lab assistants ONLY'!F9,"") -> 168 | H9: =IF('For Lab assistants ONLY'!R9>0,'For Lab assistants ONLY'!R9,"") -> B02
A10: 9 | B10: =IF('For Lab assistants ONLY'!B10>0,'For Lab assistants ONLY'!A10,"") -> C02 | C10: =IF('For Lab assistants ONLY'!B10>0,'For Lab assistants ONLY'!B10,"") -> Rack52 | D10: =IF('For Lab assistants ONLY'!C10>0,'For Lab assistants ONLY'!C10,"") -> LVL900114395 | E10: =IF('For Lab assistants ONLY'!E10>0,'For Lab assistants ONLY'!E10,"") -> LV7005225610 | F10: =IF('For Lab assistants ONLY'!M10>0,'For Lab assistants ONLY'!M10,"") -> GOR22SS | G10: =IF('For Lab assistants ONLY'!F10>0,'For Lab assistants ONLY'!F10,"") -> 171 | H10: =IF('For Lab assistants ONLY'!R10>0,'For Lab assistants ONLY'!R10,"") -> C02
A11: 10 | B11: =IF('For Lab assistants ONLY'!B11>0,'For Lab assistants ONLY'!A11,"") -> D02 | C11: =IF('For Lab assistants ONLY'!B11>0,'For Lab assistants ONLY'!B11,"") -> Rack52 | D11: =IF('For Lab assistants ONLY'!C11>0,'For Lab assistants ONLY'!C11,"") -> LVL900114395 | E11: =IF('For Lab assistants ONLY'!E11>0,'For Lab assistants ONLY'!E11,"") -> LV7005225618 | F11: =IF('For Lab assistants ONLY'!M11>0,'For Lab assistants ONLY'!M11,"") -> GOR22SS | G11: =IF('For Lab assistants ONLY'!F11>0,'For Lab assistants ONLY'!F11,"") -> 163 | H11: =IF('For Lab assistants ONLY'!R11>0,'For Lab assistants ONLY'!R11,"") -> D02
A12: 11 | B12: =IF('For Lab assistants ONLY'!B12>0,'For Lab assistants ONLY'!A12,"") -> E02 | C12: =IF('For Lab assistants ONLY'!B12>0,'For Lab assistants ONLY'!B12,"") -> Rack52 | D12: =IF('For Lab assistants ONLY'!C12>0,'For Lab assistants ONLY'!C12,"") -> LVL900114395 | E12: =IF('For Lab assistants ONLY'!E12>0,'For Lab assistants ONLY'!E12,"") -> LV7005225626 | F12: =IF('For Lab assistants ONLY'!M12>0,'For Lab assistants ONLY'!M12,"") -> GOR22SS | G12: =IF('For Lab assistants ONLY'!F12>0,'For Lab assistants ONLY'!F12,"") -> 167 | H12: =IF('For Lab assistants ONLY'!R12>0,'For Lab assistants ONLY'!R12,"") -> E02
A13: 12 | B13: =IF('For Lab assistants ONLY'!B13>0,'For Lab assistants ONLY'!A13,"") -> F02 | C13: =IF('For Lab assistants ONLY'!B13>0,'For Lab assistants ONLY'!B13,"") -> Rack52 | D13: =IF('For Lab assistants ONLY'!C13>0,'For Lab assistants ONLY'!C13,"") -> LVL900114395 | E13: =IF('For Lab assistants ONLY'!E13>0,'For Lab assistants ONLY'!E13,"") -> LV7005224363 | F13: =IF('For Lab assistants ONLY'!M13>0,'For Lab assistants ONLY'!M13,"") -> GOR22SS | G13: =IF('For Lab assistants ONLY'!F13>0,'For Lab assistants ONLY'!F13,"") -> 189 | H13: =IF('For Lab assistants ONLY'!R13>0,'For Lab assistants ONLY'!R13,"") -> F02
... A264: 263 | B264: =IF('For Lab assistants ONLY'!B264>0,'For Lab assistants ONLY'!A264,"") | C264: =IF('For Lab assistants ONLY'!B264>0,'For Lab assistants ONLY'!B264,"") | D264: =IF('For Lab assistants ONLY'!C264>0,'For Lab assistants ONLY'!C264,"") | E264: =IF('For Lab assistants ONLY'!E264>0,'For Lab assistants ONLY'!E264,"") | F264: =IF('For Lab assistants ONLY'!M264>0,'For Lab assistants ONLY'!M264,"") | G264: =IF('For Lab assistants ONLY'!F264>0,'For Lab assistants ONLY'!F264,"") | H264: =IF('For Lab assistants ONLY'!R264>0,'For Lab assistants ONLY'!R264,"")

Sheet For Lab assistants ONLY
A1: Robot RACK position | B1: Robot RACK name (e.g. Rack10) | C1: Robot RACK barcode | D1: Archive TUBE barcode (check) | E1: Robot TUBE barcode | F1: Sample mass (mg) | G1: SubSampling remarks | H1: Lab assistant (initials) | I1: Subsampling date (yyyy-mm-dd) | J1: No | K1: Submitter (initials) | L1: Submission Date (yyyy-mm-dd) | M1: Core- or Bulk sample ID (Optional) | N1: Archive rack position | O1: Archive RACK no. (eg. ARack0052) | P1: Archive RACK barcode | Q1: Archive TUBE barcode | R1: Remarks (eg. personal project ID)
A2: A01 | B2: Rack52 | C2: LVL900114395 | D2: LV3005888014 | E2: LV7005367348 | F2: 192 | H2: MH_FM_VSS | I2: 45203 | J2: 1 | K2: =IF('For submitter'!B2>0,'For submitter'!B2,"") -> BdS_YW | L2: =IF('For submitter'!C2>0,'For submitter'!C2,"") -> 45009 | M2: =IF('For submitter'!D2>0,'For submitter'!D2,"") -> GOR22SS | N2: =IF('For submitter'!E2>0,'For submitter'!E2,"") -> A01 | O2: =IF('For submitter'!F2>0,'For submitter'!F2,"") -> ARack0431 | P2: =IF('For submitter'!G2>0,'For submitter'!G2,"") -> LVL600038023 | Q2: =IF('For submitter'!H2>0,'For submitter'!H2,"") -> LV3005888014 | R2: =IF('For submitter'!I2>0,'For submitter'!I2,"") -> A01
A3: B01 | B3: Rack52 | C3: LVL900114395 | D3: LV3005888008 | E3: LV7005227800 | F3: 140 | H3: =H2 -> MH_FM_VSS | I3: =I2 -> 45203 | J3: 2 | K3: =IF('For submitter'!B3>0,'For submitter'!B3,"") -> BdS_YW | L3: =IF('For submitter'!C3>0,'For submitter'!C3,"") -> 45009 | M3: =IF('For submitter'!D3>0,'For submitter'!D3,"") -> GOR22SS | N3: =IF('For submitter'!E3>0,'For submitter'!E3,"") -> B01 | O3: =IF('For submitter'!F3>0,'For submitter'!F3,"") -> ARack0431 | P3: =IF('For submitter'!G3>0,'For submitter'!G3,"") -> LVL600038023 | Q3: =IF('For submitter'!H3>0,'For submitter'!H3,"") -> LV3005888008 | R3: =IF('For submitter'!I3>0,'For submitter'!I3,"") -> B01
A4: C01 | B4: Rack52 | C4: LVL900114395 | D4: LV3005888020 | E4: LV7005224976 | F4: 172 | H4: =H3 -> MH_FM_VSS | I4: =I3 -> 45203 | J4: 3 | K4: =IF('For submitter'!B4>0,'For submitter'!B4,"") -> BdS_YW | L4: =IF('For submitter'!C4>0,'For submitter'!C4,"") -> 45009 | M4: =IF('For submitter'!D4>0,'For submitter'!D4,"") -> GOR22SS | N4: =IF('For submitter'!E4>0,'For submitter'!E4,"") -> C01 | O4: =IF('For submitter'!F4>0,'For submitter'!F4,"") -> ARack0431 | P4: =IF('For submitter'!G4>0,'For submitter'!G4,"") -> LVL600038023 | Q4: =IF('For submitter'!H4>0,'For submitter'!H4,"") -> LV3005888020 | R4: =IF('For submitter'!I4>0,'For submitter'!I4,"") -> C01
A5: D01 | B5: Rack52 | C5: LVL900114395 | D5: LV3005888019 | E5: LV7005224920 | F5: 181 | H5: =H4 -> MH_FM_VSS | I5: =I4 -> 45203 | J5: 4 | K5: =IF('For submitter'!B5>0,'For submitter'!B5,"") -> BdS_YW | L5: =IF('For submitter'!C5>0,'For submitter'!C5,"") -> 45009 | M5: =IF('For submitter'!D5>0,'For submitter'!D5,"") -> GOR22SS | N5: =IF('For submitter'!E5>0,'For submitter'!E5,"") -> D01 | O5: =IF('For submitter'!F5>0,'For submitter'!F5,"") -> ARack0431 | P5: =IF('For submitter'!G5>0,'For submitter'!G5,"") -> LVL600038023 | Q5: =IF('For submitter'!H5>0,'For submitter'!H5,"") -> LV3005888019 | R5: =IF('For submitter'!I5>0,'For submitter'!I5,"") -> D01
A6: E01 | B6: Rack52 | C6: LVL900114395 | D6: LV3005888013 | E6: LV7005225024 | F6: 162 | H6: =H5 -> MH_FM_VSS | I6: =I5 -> 45203 | J6: 5 | K6: =IF('For submitter'!B6>0,'For submitter'!B6,"") -> BdS_YW | L6: =IF('For submitter'!C6>0,'For submitter'!C6,"") -> 45009 | M6: =IF('For submitter'!D6>0,'For submitter'!D6,"") -> GOR22SS | N6: =IF('For submitter'!E6>0,'For submitter'!E6,"") -> A02 | O6: =IF('For submitter'!F6>0,'For submitter'!F6,"") -> ARack0431 | P6: =IF('For submitter'!G6>0,'For submitter'!G6,"") -> LVL600038023 | Q6: =IF('For submitter'!H6>0,'For submitter'!H6,"") -> LV3005888013 | R6: =IF('For submitter'!I6>0,'For submitter'!I6,"") -> E01
A7: F01 | B7: Rack52 | C7: LVL900114395 | D7: LV3005888007 | E7: LV7005225032 | F7: 163 | H7: =H6 -> MH_FM_VSS | I7: =I6 -> 45203 | J7: 6 | K7: =IF('For submitter'!B7>0,'For submitter'!B7,"") -> BdS_YW | L7: =IF('For submitter'!C7>0,'For submitter'!C7,"") -> 45009 | M7: =IF('For submitter'!D7>0,'For submitter'!D7,"") -> GOR22SS | N7: =IF('For submitter'!E7>0,'For submitter'!E7,"") -> B02 | O7: =IF('For submitter'!F7>0,'For submitter'!F7,"") -> ARack0431 | P7: =IF('For submitter'!G7>0,'For submitter'!G7,"") -> LVL600038023 | Q7: =IF('For submitter'!H7>0,'For submitter'!H7,"") -> LV3005888007 | R7: =IF('For submitter'!I7>0,'For submitter'!I7,"") -> F01
A8: A02 | B8: Rack52 | C8: LVL900114395 | D8: LV3005888001 | E8: LV7005225594 | F8: 179 | H8: =H7 -> MH_FM_VSS | I8: =I7 -> 45203 | J8: 7 | K8: =IF('For submitter'!B8>0,'For submitter'!B8,"") -> BdS_YW | L8: =IF('For submitter'!C8>0,'For submitter'!C8,"") -> 45009 | M8: =IF('For submitter'!D8>0,'For submitter'!D8,"") -> GOR22SS | N8: =IF('For submitter'!E8>0,'For submitter'!E8,"") -> C02 | O8: =IF('For submitter'!F8>0,'For submitter'!F8,"") -> ARack0431 | P8: =IF('For submitter'!G8>0,'For submitter'!G8,"") -> LVL600038023 | Q8: =IF('For submitter'!H8>0,'For submitter'!H8,"") -> LV3005888001 | R8: =IF('For submitter'!I8>0,'For submitter'!I8,"") -> A02
A9: B02 | B9: Rack52 | C9: LVL900114395 | D9: LV3005888018 | E9: LV7005225602 | F9: 168 | H9: =H8 -> MH_FM_VSS | I9: =I8 -> 45203 | J9: 8 | K9: =IF('For submitter'!B9>0,'For submitter'!B9,"") -> BdS_YW | L9: =IF('For submitter'!C9>0,'For submitter'!C9,"") -> 45009 | M9: =IF('For submitter'!D9>0,'For submitter'!D9,"") -> GOR22SS | N9: =IF('For submitter'!E9>0,'For submitter'!E9,"") -> D02 | O9: =IF('For submitter'!F9>0,'For submitter'!F9,"") -> ARack0431 | P9: =IF('For submitter'!G9>0,'For submitter'!G9,"") -> LVL600038023 | Q9: =IF('For submitter'!H9>0,'For submitter'!H9,"") -> LV3005888018 | R9: =IF('For submitter'!I9>0,'For submitter'!I9,"") -> B02
A10: C02 | B10: Rack52 | C10: LVL900114395 | D10: LV3005888016 | E10: LV7005225610 | F10: 171 | H10: =H9 -> MH_FM_VSS | I10: =I9 -> 45203 | J10: 9 | K10: =IF('For submitter'!B10>0,'For submitter'!B10,"") -> BdS_YW | L10: =IF('For submitter'!C10>0,'For submitter'!C10,"") -> 45009 | M10: =IF('For submitter'!D10>0,'For submitter'!D10,"") -> GOR22SS | N10: =IF('For submitter'!E10>0,'For submitter'!E10,"") -> A03 | O10: =IF('For submitter'!F10>0,'For submitter'!F10,"") -> ARack0431 | P10: =IF('For submitter'!G10>0,'For submitter'!G10,"") -> LVL600038023 | Q10: =IF('For submitter'!H10>0,'For submitter'!H10,"") -> LV3005888016 | R10: =IF('For submitter'!I10>0,'For submitter'!I10,"") -> C02
A11: D02 | B11: Rack52 | C11: LVL900114395 | D11: LV3005888012 | E11: LV7005225618 | F11: 163 | H11: =H10 -> MH_FM_VSS | I11: =I10 -> 45203 | J11: 10 | K11: =IF('For submitter'!B11>0,'For submitter'!B11,"") -> BdS_YW | L11: =IF('For submitter'!C11>0,'For submitter'!C11,"") -> 45009 | M11: =IF('For submitter'!D11>0,'For submitter'!D11,"") -> GOR22SS | N11: =IF('For submitter'!E11>0,'For submitter'!E11,"") -> B03 | O11: =IF('For submitter'!F11>0,'For submitter'!F11,"") -> ARack0431 | P11: =IF('For submitter'!G11>0,'For submitter'!G11,"") -> LVL600038023 | Q11: =IF('For submitter'!H11>0,'For submitter'!H11,"") -> LV3005888012 | R11: =IF('For submitter'!I11>0,'For submitter'!I11,"") -> D02
A12: E02 | B12: Rack52 | C12: LVL900114395 | D12: LV3005888006 | E12: LV7005225626 | F12: 167 | H12: =H11 -> MH_FM_VSS | I12: =I11 -> 45203 | J12: 11 | K12: =IF('For submitter'!B12>0,'For submitter'!B12,"") -> BdS_YW | L12: =IF('For submitter'!C12>0,'For submitter'!C12,"") -> 45009 | M12: =IF('For submitter'!D12>0,'For submitter'!D12,"") -> GOR22SS | N12: =IF('For submitter'!E12>0,'For submitter'!E12,"") -> C03 | O12: =IF('For submitter'!F12>0,'For submitter'!F12,"") -> ARack0431 | P12: =IF('For submitter'!G12>0,'For submitter'!G12,"") -> LVL600038023 | Q12: =IF('For submitter'!H12>0,'For submitter'!H12,"") -> LV3005888006 | R12: =IF('For submitter'!I12>0,'For submitter'!I12,"") -> E02
A13: F02 | B13: Rack52 | C13: LVL900114395 | D13: LV3005888000 | E13: LV7005224363 | F13: 189 | H13: =H12 -> MH_FM_VSS | I13: =I12 -> 45203 | J13: 12 | K13: =IF('For submitter'!B13>0,'For submitter'!B13,"") -> BdS_YW | L13: =IF('For submitter'!C13>0,'For submitter'!C13,"") -> 45009 | M13: =IF('For submitter'!D13>0,'For submitter'!D13,"") -> GOR22SS | N13: =IF('For submitter'!E13>0,'For submitter'!E13,"") -> D03 | O13: =IF('For submitter'!F13>0,'For submitter'!F13,"") -> ARack0431 | P13: =IF('For submitter'!G13>0,'For submitter'!G13,"") -> LVL600038023 | Q13: =IF('For submitter'!H13>0,'For submitter'!H13,"") -> LV3005888000 | R13: =IF('For submitter'!I13>0,'For submitter'!I13,"") -> F02
A14: A03 | B14: Rack52 | C14: LVL900114395 | D14: LV3005888017 | E14: LV7005225595 | F14: 179 | H14: =H13 -> MH_FM_VSS | I14: =I13 -> 45203 | J14: 13 | K14: =IF('For submitter'!B14>0,'For submitter'!B14,"") -> BdS_YW | L14: =IF('For submitter'!C14>0,'For submitter'!C14,"") -> 45009 | M14: =IF('For submitter'!D14>0,'For submitter'!D14,"") -> GOR22SS | N14: =IF('For submitter'!E14>0,'For submitter'!E14,"") -> A04 | O14: =IF('For submitter'!F14>0,'For submitter'!F14,"") -> ARack0431 | P14: =IF('For submitter'!G14>0,'For submitter'!G14,"") -> LVL600038023 | Q14: =IF('For submitter'!H14>0,'For submitter'!H14,"") -> LV3005888017 | R14: =IF('For submitter'!I14>0,'For submitter'!I14,"") -> A03
A15: B03 | B15: Rack52 | C15: LVL900114395 | D15: LV3005888015 | E15: LV7005225603 | F15: 168 | H15: =H14 -> MH_FM_VSS | I15: =I14 -> 45203 | J15: 14 | K15: =IF('For submitter'!B15>0,'For submitter'!B15,"") -> BdS_YW | L15: =IF('For submitter'!C15>0,'For submitter'!C15,"") -> 45009 | M15: =IF('For submitter'!D15>0,'For submitter'!D15,"") -> GOR22A_1 | N15: =IF('For submitter'!E15>0,'For submitter'!E15,"") -> B04 | O15: =IF('For submitter'!F15>0,'For submitter'!F15,"") -> ARack0431 | P15: =IF('For submitter'!G15>0,'For submitter'!G15,"") -> LVL600038023 | Q15: =IF('For submitter'!H15>0,'For submitter'!H15,"") -> LV3005888015 | R15: =IF('For submitter'!I15>0,'For submitter'!I15,"") -> B03
A16: C03 | B16: Rack52 | C16: LVL900114395 | E16: LV7005225611 | H16: =H15 -> MH_FM_VSS | I16: =I15 -> 45203 | J16: 15 | K16: =IF('For submitter'!B16>0,'For submitter'!B16,"") -> BdS_YW | L16: =IF('For submitter'!C16>0,'For submitter'!C16,"") -> 45009 | M16: =IF('For submitter'!D16>0,'For submitter'!D16,"") | N16: =IF('For submitter'!E16>0,'For submitter'!E16,"") | O16: =IF('For submitter'!F16>0,'For submitter'!F16,"") | P16: =IF('For submitter'!G16>0,'For submitter'!G16,"") | Q16: =IF('For submitter'!H16>0,'For submitter'!H16,"") | R16: =IF('For submitter'!I16>0,'For submitter'!I16,"") -> C03
A17: D03 | B17: Rack52 | C17: LVL900114395 | D17: LV3005888009 | E17: LV7005225619 | F17: 180 | H17: =H16 -> MH_FM_VSS | I17: =I16 -> 45203 | J17: 16 | K17: =IF('For submitter'!B17>0,'For submitter'!B17,"") -> BdS_YW | L17: =IF('For submitter'!C17>0,'For submitter'!C17,"") -> 45009 | M17: =IF('For submitter'!D17>0,'For submitter'!D17,"") -> GOR22A_1 | N17: =IF('For submitter'!E17>0,'For submitter'!E17,"") -> C04 | O17: =IF('For submitter'!F17>0,'For submitter'!F17,"") -> ARack0431 | P17: =IF('For submitter'!G17>0,'For submitter'!G17,"") -> LVL600038023 | Q17: =IF('For submitter'!H17>0,'For submitter'!H17,"") -> LV3005888009 | R17: =IF('For submitter'!I17>0,'For submitter'!I17,"") -> D03
A18: E03 | B18: Rack52 | C18: LVL900114395 | D18: LV3005888010 | E18: LV7005225627 | F18: 178 | H18: =H17 -> MH_FM_VSS | I18: =I17 -> 45203 | J18: 17 | K18: =IF('For submitter'!B18>0,'For submitter'!B18,"") -> BdS_YW | L18: =IF('For submitter'!C18>0,'For submitter'!C18,"") -> 45009 | M18: =IF('For submitter'!D18>0,'For submitter'!D18,"") -> GOR22A_1 | N18: =IF('For submitter'!E18>0,'For submitter'!E18,"") -> D04 | O18: =IF('For submitter'!F18>0,'For submitter'!F18,"") -> ARack0431 | P18: =IF('For submitter'!G18>0,'For submitter'!G18,"") -> LVL600038023 | Q18: =IF('For submitter'!H18>0,'For submitter'!H18,"") -> LV3005888010 | R18: =IF('For submitter'!I18>0,'For submitter'!I18,"") -> E03
A19: F03 | B19: Rack52 | C19: LVL900114395 | D19: LV3005888011 | E19: LV7005225635 | F19: 178 | H19: =H18 -> MH_FM_VSS | I19: =I18 -> 45203 | J19: 18 | K19: =IF('For submitter'!B19>0,'For submitter'!B19,"") -> BdS_YW | L19: =IF('For submitter'!C19>0,'For submitter'!C19,"") -> 45009 | M19: =IF('For submitter'!D19>0,'For submitter'!D19,"") -> GOR22A_1 | N19: =IF('For submitter'!E19>0,'For submitter'!E19,"") -> A05 | O19: =IF('For submitter'!F19>0,'For submitter'!F19,"") -> ARack0431 | P19: =IF('For submitter'!G19>0,'For submitter'!G19,"") -> LVL600038023 | Q19: =IF('For submitter'!H19>0,'For submitter'!H19,"") -> LV3005888011 | R19: =IF('For submitter'!I19>0,'For submitter'!I19,"") -> F03
A20: A04 | B20: Rack52 | C20: LVL900114395 | D20: LV3005888003 | E20: LV7005225596 | F20: 183 | H20: =H19 -> MH_FM_VSS | I20: =I19 -> 45203 | J20: 19 | K20: =IF('For submitter'!B20>0,'For submitter'!B20,"") -> BdS_YW | L20: =IF('For submitter'!C20>0,'For submitter'!C20,"") -> 45009 | M20: =IF('For submitter'!D20>0,'For submitter'!D20,"") -> GOR22A_1 | N20: =IF('For submitter'!E20>0,'For submitter'!E20,"") -> B05 | O20: =IF('For submitter'!F20>0,'For submitter'!F20,"") -> ARack0431 | P20: =IF('For submitter'!G20>0,'For submitter'!G20,"") -> LVL600038023 | Q20: =IF('For submitter'!H20>0,'For submitter'!H20,"") -> LV3005888003 | R20: =IF('For submitter'!I20>0,'For submitter'!I20,"") -> A04
A21: B04 | B21: Rack52 | C21: LVL900114395 | D21: LV3005888004 | E21: LV7005225604 | F21: 165 | H21: =H20 -> MH_FM_VSS | I21: =I20 -> 45203 | J21: 20 | K21: =IF('For submitter'!B21>0,'For submitter'!B21,"") -> BdS_YW | L21: =IF('For submitter'!C21>0,'For submitter'!C21,"") -> 45009 | M21: =IF('For submitter'!D21>0,'For submitter'!D21,"") -> GOR22A_1 | N21: =IF('For submitter'!E21>0,'For submitter'!E21,"") -> C05 | O21: =IF('For submitter'!F21>0,'For submitter'!F21,"") -> ARack0431 | P21: =IF('For submitter'!G21>0,'For submitter'!G21,"") -> LVL600038023 | Q21: =IF('For submitter'!H21>0,'For submitter'!H21,"") -> LV3005888004 | R21: =IF('For submitter'!I21>0,'For submitter'!I21,"") -> B04
A22: C04 | B22: Rack52 | C22: LVL900114395 | D22: LV3005888005 | E22: LV7005225612 | F22: 164 | H22: =H21 -> MH_FM_VSS | I22: =I21 -> 45203 | J22: 21 | K22: =IF('For submitter'!B22>0,'For submitter'!B22,"") -> BdS_YW | L22: =IF('For submitter'!C22>0,'For submitter'!C22,"") -> 45009 | M22: =IF('For submitter'!D22>0,'For submitter'!D22,"") -> GOR22A_1 | N22: =IF('For submitter'!E22>0,'For submitter'!E22,"") -> D05 | O22: =IF('For submitter'!F22>0,'For submitter'!F22,"") -> ARack0431 | P22: =IF('For submitter'!G22>0,'For submitter'!G22,"") -> LVL600038023 | Q22: =IF('For submitter'!H22>0,'For submitter'!H22,"") -> LV3005888005 | R22: =IF('For submitter'!I22>0,'For submitter'!I22,"") -> C04
A23: D04 | B23: Rack52 | C23: LVL900114395 | D23: LV3005887997 | E23: LV7005224365 | F23: 167 | H23: =H22 -> MH_FM_VSS | I23: =I22 -> 45203 | J23: 22 | K23: =IF('For submitter'!B23>0,'For submitter'!B23,"") -> BdS_YW | L23: =IF('For submitter'!C23>0,'For submitter'!C23,"") -> 45009 | M23: =IF('For submitter'!D23>0,'For submitter'!D23,"") -> GOR22A_1 | N23: =IF('For submitter'!E23>0,'For submitter'!E23,"") -> A06 | O23: =IF('For submitter'!F23>0,'For submitter'!F23,"") -> ARack0431 | P23: =IF('For submitter'!G23>0,'For submitter'!G23,"") -> LVL600038023 | Q23: =IF('For submitter'!H23>0,'For submitter'!H23,"") -> LV3005887997 | R23: =IF('For submitter'!I23>0,'For submitter'!I23,"") -> D04
A24: E04 | B24: Rack52 | C24: LVL900114395 | D24: LV3005887998 | E24: LV7005225628 | F24: 166 | H24: =H23 -> MH_FM_VSS | I24: =I23 -> 45203 | J24: 23 | K24: =IF('For submitter'!B24>0,'For submitter'!B24,"") -> BdS_YW | L24: =IF('For submitter'!C24>0,'For submitter'!C24,"") -> 45009 | M24: =IF('For submitter'!D24>0,'For submitter'!D24,"") -> GOR22A_1 | N24: =IF('For submitter'!E24>0,'For submitter'!E24,"") -> B06 | O24: =IF('For submitter'!F24>0,'For submitter'!F24,"") -> ARack0431 | P24: =IF('For submitter'!G24>0,'For submitter'!G24,"") -> LVL600038023 | Q24: =IF('For submitter'!H24>0,'For submitter'!H24,"") -> LV3005887998 | R24: =IF('For submitter'!I24>0,'For submitter'!I24,"") -> E04
A25: F04 | B25: Rack52 | C25: LVL900114395 | D25: LV3005887773 | E25: LV7005225636 | F25: 170 | H25: =H24 -> MH_FM_VSS | I25: =I24 -> 45203 | J25: 24 | K25: =IF('For submitter'!B25>0,'For submitter'!B25,"") -> BdS_YW | L25: =IF('For submitter'!C25>0,'For submitter'!C25,"") -> 45009 | M25: =IF('For submitter'!D25>0,'For submitter'!D25,"") -> GOR22A_1 | N25: =IF('For submitter'!E25>0,'For submitter'!E25,"") -> C06 | O25: =IF('For submitter'!F25>0,'For submitter'!F25,"") -> ARack0431 | P25: =IF('For submitter'!G25>0,'For submitter'!G25,"") -> LVL600038023 | Q25: =IF('For submitter'!H25>0,'For submitter'!H25,"") -> LV3005887773 | R25: =IF('For submitter'!I25>0,'For submitter'!I25,"") -> F04
A26: A05 | B26: Rack52 | C26: LVL900114395 | D26: LV3005887999 | E26: LV7005225597 | F26: 158 | H26: =H25 -> MH_FM_VSS | I26: =I25 -> 45203 | J26: 25 | K26: =IF('For submitter'!B26>0,'For submitter'!B26,"") -> BdS_YW | L26: =IF('For submitter'!C26>0,'For submitter'!C26,"") -> 45009 | M26: =IF('For submitter'!D26>0,'For submitter'!D26,"") -> GOR22A_1 | N26: =IF('For submitter'!E26>0,'For submitter'!E26,"") -> D06 | O26: =IF('For submitter'!F26>0,'For submitter'!F26,"") -> ARack0431 | P26: =IF('For submitter'!G26>0,'For submitter'!G26,"") -> LVL600038023 | Q26: =IF('For submitter'!H26>0,'For submitter'!H26,"") -> LV3005887999 | R26: =IF('For submitter'!I26>0,'For submitter'!I26,"") -> A05
A27: B05 | B27: Rack52 | C27: LVL900114395 | D27: LV3005887991 | E27: LV7005225605 | F27: 161 | H27: =H26 -> MH_FM_VSS | I27: =I26 -> 45203 | J27: 26 | K27: =IF('For submitter'!B27>0,'For submitter'!B27,"") -> BdS_YW | L27: =IF('For submitter'!C27>0,'For submitter'!C27,"") -> 45009 | M27: =IF('For submitter'!D27>0,'For submitter'!D27,"") -> GOR22A_1 | N27: =IF('For submitter'!E27>0,'For submitter'!E27,"") -> A01 | O27: =IF('For submitter'!F27>0,'For submitter'!F27,"") -> ARack0432 | P27: =IF('For submitter'!G27>0,'For submitter'!G27,"") -> LVL600038022 | Q27: =IF('For submitter'!H27>0,'For submitter'!H27,"") -> LV3005887991 | R27: =IF('For submitter'!I27>0,'For submitter'!I27,"") -> B05
A28: C05 | B28: Rack52 | C28: LVL900114395 | D28: LV3005887985 | E28: LV7005225613 | F28: 177 | H28: =H27 -> MH_FM_VSS | I28: =I27 -> 45203 | J28: 27 | K28: =IF('For submitter'!B28>0,'For submitter'!B28,"") -> BdS_YW | L28: =IF('For submitter'!C28>0,'For submitter'!C28,"") -> 45009 | M28: =IF('For submitter'!D28>0,'For submitter'!D28,"") -> GOR22A_1 | N28: =IF('For submitter'!E28>0,'For submitter'!E28,"") -> B01 | O28: =IF('For submitter'!F28>0,'For submitter'!F28,"") -> ARack0432 | P28: =IF('For submitter'!G28>0,'For submitter'!G28,"") -> LVL600038022 | Q28: =IF('For submitter'!H28>0,'For submitter'!H28,"") -> LV3005887985 | R28: =IF('For submitter'!I28>0,'For submitter'!I28,"") -> C05
... A34: C06 | B34: Rack52 | C34: LVL900114395 | D34: LV3005887996 | E34: LV7005225614 | F34: 178 | H34: =H33 -> MH_FM_VSS | I34: =I33 -> 45203 | J34: 33 | K34: =IF('For submitter'!B34>0,'For submitter'!B34,"") -> BdS_YW | L34: =IF('For submitter'!C34>0,'For submitter'!C34,"") -> 45009 | M34: =IF('For submitter'!D34>0,'For submitter'!D34,"") -> GOR22A_1 | N34: =IF('For submitter'!E34>0,'For submitter'!E34,"") -> D02 | O34: =IF('For submitter'!F34>0,'For submitter'!F34,"") -> ARack0432 | P34: =IF('For submitter'!G34>0,'For submitter'!G34,"") -> LVL600038022 | Q34: =IF('For submitter'!H34>0,'For submitter'!H34,"") -> LV3005887996 | R34: =IF('For submitter'!I34>0,'For submitter'!I34,"") -> C06
A35: D06 | B35: Rack52 | C35: LVL900114395 | E35: LV7005225622 | H35: =H34 -> MH_FM_VSS | I35: =I34 -> 45203 | J35: 34 | K35: =IF('For submitter'!B35>0,'For submitter'!B35,"") -> BdS_YW | L35: =IF('For submitter'!C35>0,'For submitter'!C35,"") -> 45009 | M35: =IF('For submitter'!D35>0,'For submitter'!D35,"") | N35: =IF('For submitter'!E35>0,'For submitter'!E35,"") | O35: =IF('For submitter'!F35>0,'For submitter'!F35,"") | P35: =IF('For submitter'!G35>0,'For submitter'!G35,"") | Q35: =IF('For submitter'!H35>0,'For submitter'!H35,"") | R35: =IF('For submitter'!I35>0,'For submitter'!I35,"") -> D06
A36: E06 | B36: Rack52 | C36: LVL900114395 | D36: LV3005887989 | E36: LV7005225630 | F36: 180 | H36: =H35 -> MH_FM_VSS | I36: =I35 -> 45203 | J36: 35 | K36: =IF('For submitter'!B36>0,'For submitter'!B36,"") -> BdS_YW | L36: =IF('For submitter'!C36>0,'For submitter'!C36,"") -> 45009 | M36: =IF('For submitter'!D36>0,'For submitter'!D36,"") -> GOR22A_1 | N36: =IF('For submitter'!E36>0,'For submitter'!E36,"") -> A03 | O36: =IF('For submitter'!F36>0,'For submitter'!F36,"") -> ARack0432 | P36: =IF('For submitter'!G36>0,'For submitter'!G36,"") -> LVL600038022 | Q36: =IF('For submitter'!H36>0,'For submitter'!H36,"") -> LV3005887989 | R36: =IF('For submitter'!I36>0,'For submitter'!I36,"") -> E06
A37: F06 | B37: Rack52 | C37: LVL900114395 | D37: LV3005887987 | E37: LV7005225638 | F37: 160 | H37: =H36 -> MH_FM_VSS | I37: =I36 -> 45203 | J37: 36 | K37: =IF('For submitter'!B37>0,'For submitter'!B37,"") -> BdS_YW | L37: =IF('For submitter'!C37>0,'For submitter'!C37,"") -> 45009 | M37: =IF('For submitter'!D37>0,'For submitter'!D37,"") -> GOR22A_1 | N37: =IF('For submitter'!E37>0,'For submitter'!E37,"") -> B03 | O37: =IF('For submitter'!F37>0,'For submitter'!F37,"") -> ARack0432 | P37: =IF('For submitter'!G37>0,'For submitter'!G37,"") -> LVL600038022 | Q37: =IF('For submitter'!H37>0,'For submitter'!H37,"") -> LV3005887987 | R37: =IF('For submitter'!I37>0,'For submitter'!I37,"") -> F06
A38: A07 | B38: Rack52 | C38: LVL900114395 | D38: LV3005887978 | E38: LV7005224166 | F38: 167 | H38: =H37 -> MH_FM_VSS | I38: =I37 -> 45203 | J38: 37 | K38: =IF('For submitter'!B38>0,'For submitter'!B38,"") -> BdS_YW | L38: =IF('For submitter'!C38>0,'For submitter'!C38,"") -> 45009 | M38: =IF('For submitter'!D38>0,'For submitter'!D38,"") -> GOR22A_1 | N38: =IF('For submitter'!E38>0,'For submitter'!E38,"") -> C03 | O38: =IF('For submitter'!F38>0,'For submitter'!F38,"") -> ARack0432 | P38: =IF('For submitter'!G38>0,'For submitter'!G38,"") -> LVL600038022 | Q38: =IF('For submitter'!H38>0,'For submitter'!H38,"") -> LV3005887978 | R38: =IF('For submitter'!I38>0,'For submitter'!I38,"") -> A07
A39: B07 | B39: Rack52 | C39: LVL900114395 | D39: LV3005887979 | E39: LV7005225607 | F39: 172 | H39: =H38 -> MH_FM_VSS | I39: =I38 -> 45203 | J39: 38 | K39: =IF('For submitter'!B39>0,'For submitter'!B39,"") -> BdS_YW | L39: =IF('For submitter'!C39>0,'For submitter'!C39,"") -> 45009 | M39: =IF('For submitter'!D39>0,'For submitter'!D39,"") -> GOR22A_1 | N39: =IF('For submitter'!E39>0,'For submitter'!E39,"") -> D03 | O39: =IF('For submitter'!F39>0,'For submitter'!F39,"") -> ARack0432 | P39: =IF('For submitter'!G39>0,'For submitter'!G39,"") -> LVL600038022 | Q39: =IF('For submitter'!H39>0,'For submitter'!H39,"") -> LV3005887979 | R39: =IF('For submitter'!I39>0,'For submitter'!I39,"") -> B07
A40: C07 | B40: Rack52 | C40: LVL900114395 | D40: LV3005887988 | E40: LV7005225615 | F40: 161 | H40: =H39 -> MH_FM_VSS | I40: =I39 -> 45203 | J40: 39 | K40: =IF('For submitter'!B40>0,'For submitter'!B40,"") -> BdS_YW | L40: =IF('For submitter'!C40>0,'For submitter'!C40,"") -> 45009 | M40: =IF('For submitter'!D40>0,'For submitter'!D40,"") -> GOR22A_1 | N40: =IF('For submitter'!E40>0,'For submitter'!E40,"") -> A04 | O40: =IF('For submitter'!F40>0,'For submitter'!F40,"") -> ARack0432 | P40: =IF('For submitter'!G40>0,'For submitter'!G40,"") -> LVL600038022 | Q40: =IF('For submitter'!H40>0,'For submitter'!H40,"") -> LV3005887988 | R40: =IF('For submitter'!I40>0,'For submitter'!I40,"") -> C07
A41: D07 | B41: Rack52 | C41: LVL900114395 | D41: LV3005887990 | E41: LV7005225623 | F41: 168 | H41: =H40 -> MH_FM_VSS | I41: =I40 -> 45203 | J41: 40 | K41: =IF('For submitter'!B41>0,'For submitter'!B41,"") -> BdS_YW | L41: =IF('For submitter'!C41>0,'For submitter'!C41,"") -> 45009 | M41: =IF('For submitter'!D41>0,'For submitter'!D41,"") -> GOR22A_1 | N41: =IF('For submitter'!E41>0,'For submitter'!E41,"") -> B04 | O41: =IF('For submitter'!F41>0,'For submitter'!F41,"") -> ARack0432 | P41: =IF('For submitter'!G41>0,'For submitter'!G41,"") -> LVL600038022 | Q41: =IF('For submitter'!H41>0,'For submitter'!H41,"") -> LV3005887990 | R41: =IF('For submitter'!I41>0,'For submitter'!I41,"") -> D07
A42: E07 | B42: Rack52 | C42: LVL900114395 | D42: LV3005887980 | E42: LV7005225631 | F42: 160 | H42: =H41 -> MH_FM_VSS | I42: =I41 -> 45203 | J42: 41 | K42: =IF('For submitter'!B42>0,'For submitter'!B42,"") -> BdS_YW | L42: =IF('For submitter'!C42>0,'For submitter'!C42,"") -> 45009 | M42: =IF('For submitter'!D42>0,'For submitter'!D42,"") -> GOR22A_1 | N42: =IF('For submitter'!E42>0,'For submitter'!E42,"") -> C04 | O42: =IF('For submitter'!F42>0,'For submitter'!F42,"") -> ARack0432 | P42: =IF('For submitter'!G42>0,'For submitter'!G42,"") -> LVL600038022 | Q42: =IF('For submitter'!H42>0,'For submitter'!H42,"") -> LV3005887980 | R42: =IF('For submitter'!I42>0,'For submitter'!I42,"") -> E07
A43: F07 | B43: Rack52 | C43: LVL900114395 | D43: LV3005887983 | E43: LV7005225639 | F43: 162 | H43: =H42 -> MH_FM_VSS | I43: =I42 -> 45203 | J43: 42 | K43: =IF('For submitter'!B43>0,'For submitter'!B43,"") -> BdS_YW | L43: =IF('For submitter'!C43>0,'For submitter'!C43,"") -> 45009 | M43: =IF('For submitter'!D43>0,'For submitter'!D43,"") -> GOR22A_1 | N43: =IF('For submitter'!E43>0,'For submitter'!E43,"") -> D04 | O43: =IF('For submitter'!F43>0,'For submitter'!F43,"") -> ARack0432 | P43: =IF('For submitter'!G43>0,'For submitter'!G43,"") -> LVL600038022 | Q43: =IF('For submitter'!H43>0,'For submitter'!H43,"") -> LV3005887983 | R43: =IF('For submitter'!I43>0,'For submitter'!I43,"") -> F07
A44: A08 | B44: Rack52 | C44: LVL900114395 | D44: LV3005887982 | E44: LV7005225600 | F44: 165 | H44: =H43 -> MH_FM_VSS | I44: =I43 -> 45203 | J44: 43 | K44: =IF('For submitter'!B44>0,'For submitter'!B44,"") -> BdS_YW | L44: =IF('For submitter'!C44>0,'For submitter'!C44,"") -> 45009 | M44: =IF('For submitter'!D44>0,'For submitter'!D44,"") -> GOR22A_2 | N44: =IF('For submitter'!E44>0,'For submitter'!E44,"") -> A05 | O44: =IF('For submitter'!F44>0,'For submitter'!F44,"") -> ARack0432 | P44: =IF('For submitter'!G44>0,'For submitter'!G44,"") -> LVL600038022 | Q44: =IF('For submitter'!H44>0,'For submitter'!H44,"") -> LV3005887982 | R44: =IF('For submitter'!I44>0,'For submitter'!I44,"") -> A08
A45: B08 | B45: Rack52 | C45: LVL900114395 | D45: LV3005887984 | E45: LV7005224161 | F45: 176 | H45: =H44 -> MH_FM_VSS | I45: =I44 -> 45203 | J45: 44 | K45: =IF('For submitter'!B45>0,'For submitter'!B45,"") -> BdS_YW | L45: =IF('For submitter'!C45>0,'For submitter'!C45,"") -> 45009 | M45: =IF('For submitter'!D45>0,'For submitter'!D45,"") -> GOR22A_2 | N45: =IF('For submitter'!E45>0,'For submitter'!E45,"") -> B05 | O45: =IF('For submitter'!F45>0,'For submitter'!F45,"") -> ARack0432 | P45: =IF('For submitter'!G45>0,'For submitter'!G45,"") -> LVL600038022 | Q45: =IF('For submitter'!H45>0,'For submitter'!H45,"") -> LV3005887984 | R45: =IF('For submitter'!I45>0,'For submitter'!I45,"") -> B08
...

Sheet DontTouch! DB_input
A1: SubSampleID | B1: RackName | C1: RackID | D1: PositionInRack | E1: Mass | F1: SampledBy | G1: SamplingDate | H1: RemarksSubSampling | I1: ArchiveSampleID | J1: Submitter | K1: SubmissionDate | L1: RemarksSubmission
A2: =IF('For Lab assistants ONLY'!E2>0,'For Lab assistants ONLY'!E2,"") -> LV7005367348 | B2: =IF('For Lab assistants ONLY'!B2>0,'For Lab assistants ONLY'!B2,"") -> Rack52 | C2: =IF('For Lab assistants ONLY'!C2>0,'For Lab assistants ONLY'!C2,"") -> LVL900114395 | D2: =IF('For Lab assistants ONLY'!A2>0,'For Lab assistants ONLY'!A2,"") -> A01 | E2: =IF('For Lab assistants ONLY'!F2>0,'For Lab assistants ONLY'!F2,"") -> 192 | F2: =IF('For Lab assistants ONLY'!H2>0,'For Lab assistants ONLY'!H2,"") -> MH_FM_VSS | G2: =IF('For Lab assistants ONLY'!I2>0,'For Lab assistants ONLY'!I2,"") -> 45203 | H2: =IF('For Lab assistants ONLY'!G2>0,'For Lab assistants ONLY'!G2,"") | I2: =IF('For Lab assistants ONLY'!D2>0,'For Lab assistants ONLY'!D2,"") -> LV3005888014 | J2: =IF('For Lab assistants ONLY'!K2>0,'For Lab assistants ONLY'!K2,"") -> BdS_YW | K2: =IF('For Lab assistants ONLY'!L2>0,'For Lab assistants ONLY'!L2,"") -> 45009 | L2: =IF('For Lab assistants ONLY'!R2>0,'For Lab assistants ONLY'!R2,"") -> A01
A3: =IF('For Lab assistants ONLY'!E3>0,'For Lab assistants ONLY'!E3,"") -> LV7005227800 | B3: =IF('For Lab assistants ONLY'!B3>0,'For Lab assistants ONLY'!B3,"") -> Rack52 | C3: =IF('For Lab assistants ONLY'!C3>0,'For Lab assistants ONLY'!C3,"") -> LVL900114395 | D3: =IF('For Lab assistants ONLY'!A3>0,'For Lab assistants ONLY'!A3,"") -> B01 | E3: =IF('For Lab assistants ONLY'!F3>0,'For Lab assistants ONLY'!F3,"") -> 140 | F3: =IF('For Lab assistants ONLY'!H3>0,'For Lab assistants ONLY'!H3,"") -> MH_FM_VSS | G3: =IF('For Lab assistants ONLY'!I3>0,'For Lab assistants ONLY'!I3,"") -> 45203 | H3: =IF('For Lab assistants ONLY'!G3>0,'For Lab assistants ONLY'!G3,"") | I3: =IF('For Lab assistants ONLY'!D3>0,'For Lab assistants ONLY'!D3,"") -> LV3005888008 | J3: =IF('For Lab assistants ONLY'!K3>0,'For Lab assistants ONLY'!K3,"") -> BdS_YW | K3: =IF('For Lab assistants ONLY'!L3>0,'For Lab assistants ONLY'!L3,"") -> 45009 | L3: =IF('For Lab assistants ONLY'!R3>0,'For Lab assistants ONLY'!R3,"") -> B01
A4: =IF('For Lab assistants ONLY'!E4>0,'For Lab assistants ONLY'!E4,"") -> LV7005224976 | B4: =IF('For Lab assistants ONLY'!B4>0,'For Lab assistants ONLY'!B4,"") -> Rack52 | C4: =IF('For Lab assistants ONLY'!C4>0,'For Lab assistants ONLY'!C4,"") -> LVL900114395 | D4: =IF('For Lab assistants ONLY'!A4>0,'For Lab assistants ONLY'!A4,"") -> C01 | E4: =IF('For Lab assistants ONLY'!F4>0,'For Lab assistants ONLY'!F4,"") -> 172 | F4: =IF('For Lab assistants ONLY'!H4>0,'For Lab assistants ONLY'!H4,"") -> MH_FM_VSS | G4: =IF('For Lab assistants ONLY'!I4>0,'For Lab assistants ONLY'!I4,"") -> 45203 | H4: =IF('For Lab assistants ONLY'!G4>0,'For Lab assistants ONLY'!G4,"") | I4: =IF('For Lab assistants ONLY'!D4>0,'For Lab assistants ONLY'!D4,"") -> LV3005888020 | J4: =IF('For Lab assistants ONLY'!K4>0,'For Lab assistants ONLY'!K4,"") -> BdS_YW | K4: =IF('For Lab assistants ONLY'!L4>0,'For Lab assistants ONLY'!L4,"") -> 45009 | L4: =IF('For Lab assistants ONLY'!R4>0,'For Lab assistants ONLY'!R4,"") -> C01
A5: =IF('For Lab assistants ONLY'!E5>0,'For Lab assistants ONLY'!E5,"") -> LV7005224920 | B5: =IF('For Lab assistants ONLY'!B5>0,'For Lab assistants ONLY'!B5,"") -> Rack52 | C5: =IF('For Lab assistants ONLY'!C5>0,'For Lab assistants ONLY'!C5,"") -> LVL900114395 | D5: =IF('For Lab assistants ONLY'!A5>0,'For Lab assistants ONLY'!A5,"") -> D01 | E5: =IF('For Lab assistants ONLY'!F5>0,'For Lab assistants ONLY'!F5,"") -> 181 | F5: =IF('For Lab assistants ONLY'!H5>0,'For Lab assistants ONLY'!H5,"") -> MH_FM_VSS | G5: =IF('For Lab assistants ONLY'!I5>0,'For Lab assistants ONLY'!I5,"") -> 45203 | H5: =IF('For Lab assistants ONLY'!G5>0,'For Lab assistants ONLY'!G5,"") | I5: =IF('For Lab assistants ONLY'!D5>0,'For Lab assistants ONLY'!D5,"") -> LV3005888019 | J5: =IF('For Lab assistants ONLY'!K5>0,'For Lab assistants ONLY'!K5,"") -> BdS_YW | K5: =IF('For Lab assistants ONLY'!L5>0,'For Lab assistants ONLY'!L5,"") -> 45009 | L5: =IF('For Lab assistants ONLY'!R5>0,'For Lab assistants ONLY'!R5,"") -> D01
A6: =IF('For Lab assistants ONLY'!E6>0,'For Lab assistants ONLY'!E6,"") -> LV7005225024 | B6: =IF('For Lab assistants ONLY'!B6>0,'For Lab assistants ONLY'!B6,"") -> Rack52 | C6: =IF('For Lab assistants ONLY'!C6>0,'For Lab assistants ONLY'!C6,"") -> LVL900114395 | D6: =IF('For Lab assistants ONLY'!A6>0,'For Lab assistants ONLY'!A6,"") -> E01 | E6: =IF('For Lab assistants ONLY'!F6>0,'For Lab assistants ONLY'!F6,"") -> 162 | F6: =IF('For Lab assistants ONLY'!H6>0,'For Lab assistants ONLY'!H6,"") -> MH_FM_VSS | G6: =IF('For Lab assistants ONLY'!I6>0,'For Lab assistants ONLY'!I6,"") -> 45203 | H6: =IF('For Lab assistants ONLY'!G6>0,'For Lab assistants ONLY'!G6,"") | I6: =IF('For Lab assistants ONLY'!D6>0,'For Lab assistants ONLY'!D6,"") -> LV3005888013 | J6: =IF('For Lab assistants ONLY'!K6>0,'For Lab assistants ONLY'!K6,"") -> BdS_YW | K6: =IF('For Lab assistants ONLY'!L6>0,'For Lab assistants ONLY'!L6,"") -> 45009 | L6: =IF('For Lab assistants ONLY'!R6>0,'For Lab assistants ONLY'!R6,"") -> E01
A7: =IF('For Lab assistants ONLY'!E7>0,'For Lab assistants ONLY'!E7,"") -> LV7005225032 | B7: =IF('For Lab assistants ONLY'!B7>0,'For Lab assistants ONLY'!B7,"") -> Rack52 | C7: =IF('For Lab assistants ONLY'!C7>0,'For Lab assistants ONLY'!C7,"") -> LVL900114395 | D7: =IF('For Lab assistants ONLY'!A7>0,'For Lab assistants ONLY'!A7,"") -> F01 | E7: =IF('For Lab assistants ONLY'!F7>0,'For Lab assistants ONLY'!F7,"") -> 163 | F7: =IF('For Lab assistants ONLY'!H7>0,'For Lab assistants ONLY'!H7,"") -> MH_FM_VSS | G7: =IF('For Lab assistants ONLY'!I7>0,'For Lab assistants ONLY'!I7,"") -> 45203 | H7: =IF('For Lab assistants ONLY'!G7>0,'For Lab assistants ONLY'!G7,"") | I7: =IF('For Lab assistants ONLY'!D7>0,'For Lab assistants ONLY'!D7,"") -> LV3005888007 | J7: =IF('For Lab assistants ONLY'!K7>0,'For Lab assistants ONLY'!K7,"") -> BdS_YW | K7: =IF('For Lab assistants ONLY'!L7>0,'For Lab assistants ONLY'!L7,"") -> 45009 | L7: =IF('For Lab assistants ONLY'!R7>0,'For Lab assistants ONLY'!R7,"") -> F01
A8: =IF('For Lab assistants ONLY'!E8>0,'For Lab assistants ONLY'!E8,"") -> LV7005225594 | B8: =IF('For Lab assistants ONLY'!B8>0,'For Lab assistants ONLY'!B8,"") -> Rack52 | C8: =IF('For Lab assistants ONLY'!C8>0,'For Lab assistants ONLY'!C8,"") -> LVL900114395 | D8: =IF('For Lab assistants ONLY'!A8>0,'For Lab assistants ONLY'!A8,"") -> A02 | E8: =IF('For Lab assistants ONLY'!F8>0,'For Lab assistants ONLY'!F8,"") -> 179 | F8: =IF('For Lab assistants ONLY'!H8>0,'For Lab assistants ONLY'!H8,"") -> MH_FM_VSS | G8: =IF('For Lab assistants ONLY'!I8>0,'For Lab assistants ONLY'!I8,"") -> 45203 | H8: =IF('For Lab assistants ONLY'!G8>0,'For Lab assistants ONLY'!G8,"") | I8: =IF('For Lab assistants ONLY'!D8>0,'For Lab assistants ONLY'!D8,"") -> LV3005888001 | J8: =IF('For Lab assistants ONLY'!K8>0,'For Lab assistants ONLY'!K8,"") -> BdS_YW | K8: =IF('For Lab assistants ONLY'!L8>0,'For Lab assistants ONLY'!L8,"") -> 45009 | L8: =IF('For Lab assistants ONLY'!R8>0,'For Lab assistants ONLY'!R8,"") -> A02
A9: =IF('For Lab assistants ONLY'!E9>0,'For Lab assistants ONLY'!E9,"") -> LV7005225602 | B9: =IF('For Lab assistants ONLY'!B9>0,'For Lab assistants ONLY'!B9,"") -> Rack52 | C9: =IF('For Lab assistants ONLY'!C9>0,'For Lab assistants ONLY'!C9,"") -> LVL900114395 | D9: =IF('For Lab assistants ONLY'!A9>0,'For Lab assistants ONLY'!A9,"") -> B02 | E9: =IF('For Lab assistants ONLY'!F9>0,'For Lab assistants ONLY'!F9,"") -> 168 | F9: =IF('For Lab assistants ONLY'!H9>0,'For Lab assistants ONLY'!H9,"") -> MH_FM_VSS | G9: =IF('For Lab assistants ONLY'!I9>0,'For Lab assistants ONLY'!I9,"") -> 45203 | H9: =IF('For Lab assistants ONLY'!G9>0,'For Lab assistants ONLY'!G9,"") | I9: =IF('For Lab assistants ONLY'!D9>0,'For Lab assistants ONLY'!D9,"") -> LV3005888018 | J9: =IF('For Lab assistants ONLY'!K9>0,'For Lab assistants ONLY'!K9,"") -> BdS_YW | K9: =IF('For Lab assistants ONLY'!L9>0,'For Lab assistants ONLY'!L9,"") -> 45009 | L9: =IF('For Lab assistants ONLY'!R9>0,'For Lab assistants ONLY'!R9,"") -> B02
A10: =IF('For Lab assistants ONLY'!E10>0,'For Lab assistants ONLY'!E10,"") -> LV7005225610 | B10: =IF('For Lab assistants ONLY'!B10>0,'For Lab assistants ONLY'!B10,"") -> Rack52 | C10: =IF('For Lab assistants ONLY'!C10>0,'For Lab assistants ONLY'!C10,"") -> LVL900114395 | D10: =IF('For Lab assistants ONLY'!A10>0,'For Lab assistants ONLY'!A10,"") -> C02 | E10: =IF('For Lab assistants ONLY'!F10>0,'For Lab assistants ONLY'!F10,"") -> 171 | F10: =IF('For Lab assistants ONLY'!H10>0,'For Lab assistants ONLY'!H10,"") -> MH_FM_VSS | G10: =IF('For Lab assistants ONLY'!I10>0,'For Lab assistants ONLY'!I10,"") -> 45203 | H10: =IF('For Lab assistants ONLY'!G10>0,'For Lab assistants ONLY'!G10,"") | I10: =IF('For Lab assistants ONLY'!D10>0,'For Lab assistants ONLY'!D10,"") -> LV3005888016 | J10: =IF('For Lab assistants ONLY'!K10>0,'For Lab assistants ONLY'!K10,"") -> BdS_YW | K10: =IF('For Lab assistants ONLY'!L10>0,'For Lab assistants ONLY'!L10,"") -> 45009 | L10: =IF('For Lab assistants ONLY'!R10>0,'For Lab assistants ONLY'!R10,"") -> C02
A11: =IF('For Lab assistants ONLY'!E11>0,'For Lab assistants ONLY'!E11,"") -> LV7005225618 | B11: =IF('For Lab assistants ONLY'!B11>0,'For Lab assistants ONLY'!B11,"") -> Rack52 | C11: =IF('For Lab assistants ONLY'!C11>0,'For Lab assistants ONLY'!C11,"") -> LVL900114395 | D11: =IF('For Lab assistants ONLY'!A11>0,'For Lab assistants ONLY'!A11,"") -> D02 | E11: =IF('For Lab assistants ONLY'!F11>0,'For Lab assistants ONLY'!F11,"") -> 163 | F11: =IF('For Lab assistants ONLY'!H11>0,'For Lab assistants ONLY'!H11,"") -> MH_FM_VSS | G11: =IF('For Lab assistants ONLY'!I11>0,'For Lab assistants ONLY'!I11,"") -> 45203 | H11: =IF('For Lab assistants ONLY'!G11>0,'For Lab assistants ONLY'!G11,"") | I11: =IF('For Lab assistants ONLY'!D11>0,'For Lab assistants ONLY'!D11,"") -> LV3005888012 | J11: =IF('For Lab assistants ONLY'!K11>0,'For Lab assistants ONLY'!K11,"") -> BdS_YW | K11: =IF('For Lab assistants ONLY'!L11>0,'For Lab assistants ONLY'!L11,"") -> 45009 | L11: =IF('For Lab assistants ONLY'!R11>0,'For Lab assistants ONLY'!R11,"") -> D02
A12: =IF('For Lab assistants ONLY'!E12>0,'For Lab assistants ONLY'!E12,"") -> LV7005225626 | B12: =IF('For Lab assistants ONLY'!B12>0,'For Lab assistants ONLY'!B12,"") -> Rack52 | C12: =IF('For Lab assistants ONLY'!C12>0,'For Lab assistants ONLY'!C12,"") -> LVL900114395 | D12: =IF('For Lab assistants ONLY'!A12>0,'For Lab assistants ONLY'!A12,"") -> E02 | E12: =IF('For Lab assistants ONLY'!F12>0,'For Lab assistants ONLY'!F12,"") -> 167 | F12: =IF('For Lab assistants ONLY'!H12>0,'For Lab assistants ONLY'!H12,"") -> MH_FM_VSS | G12: =IF('For Lab assistants ONLY'!I12>0,'For Lab assistants ONLY'!I12,"") -> 45203 | H12: =IF('For Lab assistants ONLY'!G12>0,'For Lab assistants ONLY'!G12,"") | I12: =IF('For Lab assistants ONLY'!D12>0,'For Lab assistants ONLY'!D12,"") -> LV3005888006 | J12: =IF('For Lab assistants ONLY'!K12>0,'For Lab assistants ONLY'!K12,"") -> BdS_YW | K12: =IF('For Lab assistants ONLY'!L12>0,'For Lab assistants ONLY'!L12,"") -> 45009 | L12: =IF('For Lab assistants ONLY'!R12>0,'For Lab assistants ONLY'!R12,"") -> E02
A13: =IF('For Lab assistants ONLY'!E13>0,'For Lab assistants ONLY'!E13,"") -> LV7005224363 | B13: =IF('For Lab assistants ONLY'!B13>0,'For Lab assistants ONLY'!B13,"") -> Rack52 | C13: =IF('For Lab assistants ONLY'!C13>0,'For Lab assistants ONLY'!C13,"") -> LVL900114395 | D13: =IF('For Lab assistants ONLY'!A13>0,'For Lab assistants ONLY'!A13,"") -> F02 | E13: =IF('For Lab assistants ONLY'!F13>0,'For Lab assistants ONLY'!F13,"") -> 189 | F13: =IF('For Lab assistants ONLY'!H13>0,'For Lab assistants ONLY'!H13,"") -> MH_FM_VSS | G13: =IF('For Lab assistants ONLY'!I13>0,'For Lab assistants ONLY'!I13,"") -> 45203 | H13: =IF('For Lab assistants ONLY'!G13>0,'For Lab assistants ONLY'!G13,"") | I13: =IF('For Lab assistants ONLY'!D13>0,'For Lab assistants ONLY'!D13,"") -> LV3005888000 | J13: =IF('For Lab assistants ONLY'!K13>0,'For Lab assistants ONLY'!K13,"") -> BdS_YW | K13: =IF('For Lab assistants ONLY'!L13>0,'For Lab assistants ONLY'!L13,"") -> 45009 | L13: =IF('For Lab assistants ONLY'!R13>0,'For Lab assistants ONLY'!R13,"") -> F02
... A673: =IF('For Lab assistants ONLY'!E673>0,'For Lab assistants ONLY'!E673,"") | B673: =IF('For Lab assistants ONLY'!B673>0,'For Lab assistants ONLY'!B673,"") | C673: =IF('For Lab assistants ONLY'!C673>0,'For Lab assistants ONLY'!C673,"") | D673: =IF('For Lab assistants ONLY'!A673>0,'For Lab assistants ONLY'!A673,"") -> F08 | E673: =IF('For Lab assistants ONLY'!F673>0,'For Lab assistants ONLY'!F673,"") | F673: =IF('For Lab assistants ONLY'!H673>0,'For Lab assistants ONLY'!H673,"") | G673: =IF('For Lab assistants ONLY'!I673>0,'For Lab assistants ONLY'!I673,"") | H673: =IF('For Lab assistants ONLY'!G673>0,'For Lab assistants ONLY'!G673,"") | I673: =IF('For Lab assistants ONLY'!D673>0,'For Lab assistants ONLY'!D673,"") | J673: =IF('For Lab assistants ONLY'!K673>0,'For Lab assistants ONLY'!K673,"") -> BdS_YW | K673: =IF('For Lab assistants ONLY'!L673>0,'For Lab assistants ONLY'!L673,"") -> 45009 | L673: =IF('For Lab assistants ONLY'!R673>0,'For Lab assistants ONLY'!R673,"") -> Control
